Workbook

Sheet TAM_DOLU İĞNELİ_DÜZ_RİB_GRAMAJ
B1: DÜZ RİBANA; 100 MAYDAKİ İPLİK UZUNLUKLARINA GÖRE ORTALAMA MAMÜL GRAMAJLARI
A2: 18 | B2: İPLİK NUMARALARI
A3: FAYN | B3: 100 | C3: 80 | D3: 60 | E3: 50 | F3: 40 | G3: 39 | H3: 38 | I3: 37 | J3: 36 | K3: 35 | L3: 34 | M3: 33 | N3: 32 | O3: 31 | P3: 30 | Q3: 29 | R3: 28 | S3: 27 | T3: 26 | U3: 25 | V3: 24 | W3: 23 | X3: 22 | Y3: 21 | Z3: 20 | AA3: 19 | AB3: 18 | AC3: 17 | AD3: 16 | AE3: 15 | AF3: 14 | AG3: 13 | AH3: 12 | AI3: 11 | AJ3: 10
A4: 45 cm | B4: =(C3*C4)/(B3) -> 34.5 | C4: =(D3*D4)/(C3) -> 43.125 | D4: =(E3*E4)/(D3) -> 57.5 | E4: =(F3*F4)/(E3) -> 69 | F4: =(G3*G4)/(F3) -> 86.25 | G4: =(H3*H4)/(G3) -> 88.461538 | H4: =(I3*I4)/(H3) -> 90.789474 | I4: =(J3*J4)/(I3) -> 93.243243 | ... O4: =(P3*P4)/(O3) -> 111.29032 | P4: 115 | Q4: =(P3*P4)/(Q3) -> 118.96552 | R4: =(Q3*Q4)/(R3) -> 123.21429 | S4: =(R3*R4)/(S3) -> 127.77778 | T4: =(S3*S4)/(T3) -> 132.69231 | U4: =(T3*T4)/(U3) -> 138 | V4: =(U3*U4)/(V3) -> 143.75 | W4: =(V3*V4)/(W3) -> 150 | X4: =(W3*W4)/(X3) -> 156.81818 | ... AJ4: =(AI3*AI4)/(AJ3) -> 345
A5: 44 cm | B5: =(C3*C5)/(B3) -> 36 | C5: =(D3*D5)/(C3) -> 45 | D5: =(E3*E5)/(D3) -> 60 | E5: =(F3*F5)/(E3) -> 72 | F5: =(G3*G5)/(F3) -> 90 | G5: =(H3*H5)/(G3) -> 92.307692 | H5: =(I3*I5)/(H3) -> 94.736842 | I5: =(J3*J5)/(I3) -> 97.297297 | ... O5: =(P3*P5)/(O3) -> 116.12903 | P5: 120 | Q5: =(P3*P5)/(Q3) -> 124.13793 | R5: =(Q3*Q5)/(R3) -> 128.57143 | S5: =(R3*R5)/(S3) -> 133.33333 | T5: =(S3*S5)/(T3) -> 138.46154 | U5: =(T3*T5)/(U3) -> 144 | V5: =(U3*U5)/(V3) -> 150 | W5: =(V3*V5)/(W3) -> 156.52174 | X5: =(W3*W5)/(X3) -> 163.63636 | ... AJ5: =(AI3*AI5)/(AJ3) -> 360
A6: 43 cm | B6: =(C3*C6)/(B3) -> 37.5 | C6: =(D3*D6)/(C3) -> 46.875 | D6: =(E3*E6)/(D3) -> 62.5 | E6: =(F3*F6)/(E3) -> 75 | F6: =(G3*G6)/(F3) -> 93.75 | G6: =(H3*H6)/(G3) -> 96.153846 | H6: =(I3*I6)/(H3) -> 98.684211 | I6: =(J3*J6)/(I3) -> 101.35135 | ... O6: =(P3*P6)/(O3) -> 120.96774 | P6: 125 | Q6: =(P3*P6)/(Q3) -> 129.31034 | R6: =(Q3*Q6)/(R3) -> 133.92857 | S6: =(R3*R6)/(S3) -> 138.88889 | T6: =(S3*S6)/(T3) -> 144.23077 | U6: =(T3*T6)/(U3) -> 150 | V6: =(U3*U6)/(V3) -> 156.25 | W6: =(V3*V6)/(W3) -> 163.04348 | X6: =(W3*W6)/(X3) -> 170.45455 | ... AJ6: =(AI3*AI6)/(AJ3) -> 375
A7: 42 cm | B7: =(C3*C7)/(B3) -> 39 | C7: =(D3*D7)/(C3) -> 48.75 | D7: =(E3*E7)/(D3) -> 65 | E7: =(F3*F7)/(E3) -> 78 | F7: =(G3*G7)/(F3) -> 97.5 | G7: =(H3*H7)/(G3) -> 100 | H7: =(I3*I7)/(H3) -> 102.63158 | I7: =(J3*J7)/(I3) -> 105.40541 | ... O7: =(P3*P7)/(O3) -> 125.80645 | P7: 130 | Q7: =(P3*P7)/(Q3) -> 134.48276 | R7: =(Q3*Q7)/(R3) -> 139.28571 | S7: =(R3*R7)/(S3) -> 144.44444 | T7: =(S3*S7)/(T3) -> 150 | U7: =(T3*T7)/(U3) -> 156 | V7: =(U3*U7)/(V3) -> 162.5 | W7: =(V3*V7)/(W3) -> 169.56522 | X7: =(W3*W7)/(X3) -> 177.27273 | ... AJ7: =(AI3*AI7)/(AJ3) -> 390
A8: 41 cm | B8: =(C3*C8)/(B3) -> 40.5 | C8: =(D3*D8)/(C3) -> 50.625 | D8: =(E3*E8)/(D3) -> 67.5 | E8: =(F3*F8)/(E3) -> 81 | F8: =(G3*G8)/(F3) -> 101.25 | G8: =(H3*H8)/(G3) -> 103.84615 | H8: =(I3*I8)/(H3) -> 106.57895 | I8: =(J3*J8)/(I3) -> 109.45946 | ... O8: =(P3*P8)/(O3) -> 130.64516 | P8: 135 | Q8: =(P3*P8)/(Q3) -> 139.65517 | R8: =(Q3*Q8)/(R3) -> 144.64286 | S8: =(R3*R8)/(S3) -> 150 | T8: =(S3*S8)/(T3) -> 155.76923 | U8: =(T3*T8)/(U3) -> 162 | V8: =(U3*U8)/(V3) -> 168.75 | W8: =(V3*V8)/(W3) -> 176.08696 | X8: =(W3*W8)/(X3) -> 184.09091 | ... AJ8: =(AI3*AI8)/(AJ3) -> 405
A9: 40 cm | B9: =(C3*C9)/(B3) -> 42 | C9: =(D3*D9)/(C3) -> 52.5 | D9: =(E3*E9)/(D3) -> 70 | E9: =(F3*F9)/(E3) -> 84 | F9: =(G3*G9)/(F3) -> 105 | G9: =(H3*H9)/(G3) -> 107.69231 | H9: =(I3*I9)/(H3) -> 110.52632 | I9: =(J3*J9)/(I3) -> 113.51351 | ... O9: =(P3*P9)/(O3) -> 135.48387 | P9: 140 | Q9: =(P3*P9)/(Q3) -> 144.82759 | R9: =(Q3*Q9)/(R3) -> 150 | S9: =(R3*R9)/(S3) -> 155.55556 | T9: =(S3*S9)/(T3) -> 161.53846 | U9: =(T3*T9)/(U3) -> 168 | V9: =(U3*U9)/(V3) -> 175 | W9: =(V3*V9)/(W3) -> 182.6087 | X9: =(W3*W9)/(X3) -> 190.90909 | ... AJ9: =(AI3*AI9)/(AJ3) -> 420
A10: 39 cm | B10: =(C3*C10)/(B3) -> 43.5 | C10: =(D3*D10)/(C3) -> 54.375 | D10: =(E3*E10)/(D3) -> 72.5 | E10: =(F3*F10)/(E3) -> 87 | F10: =(G3*G10)/(F3) -> 108.75 | G10: =(H3*H10)/(G3) -> 111.53846 | H10: =(I3*I10)/(H3) -> 114.47368 | I10: =(J3*J10)/(I3) -> 117.56757 | ... O10: =(P3*P10)/(O3) -> 140.32258 | P10: 145 | Q10: =(P3*P10)/(Q3) -> 150 | R10: =(Q3*Q10)/(R3) -> 155.35714 | S10: =(R3*R10)/(S3) -> 161.11111 | T10: =(S3*S10)/(T3) -> 167.30769 | U10: =(T3*T10)/(U3) -> 174 | V10: =(U3*U10)/(V3) -> 181.25 | W10: =(V3*V10)/(W3) -> 189.13043 | X10: =(W3*W10)/(X3) -> 197.72727 | ... AJ10: =(AI3*AI10)/(AJ3) -> 435
A11: 38 cm | B11: =(C3*C11)/(B3) -> 45 | C11: =(D3*D11)/(C3) -> 56.25 | D11: =(E3*E11)/(D3) -> 75 | E11: =(F3*F11)/(E3) -> 90 | F11: =(G3*G11)/(F3) -> 112.5 | G11: =(H3*H11)/(G3) -> 115.38462 | H11: =(I3*I11)/(H3) -> 118.42105 | I11: =(J3*J11)/(I3) -> 121.62162 | ... O11: =(P3*P11)/(O3) -> 145.16129 | P11: 150 | Q11: =(P3*P11)/(Q3) -> 155.17241 | R11: =(Q3*Q11)/(R3) -> 160.71429 | S11: =(R3*R11)/(S3) -> 166.66667 | T11: =(S3*S11)/(T3) -> 173.07692 | U11: =(T3*T11)/(U3) -> 180 | V11: =(U3*U11)/(V3) -> 187.5 | W11: =(V3*V11)/(W3) -> 195.65217 | X11: =(W3*W11)/(X3) -> 204.54545 | ... AJ11: =(AI3*AI11)/(AJ3) -> 450
A12: 37 cm | B12: =(C3*C12)/(B3) -> 46.5 | C12: =(D3*D12)/(C3) -> 58.125 | D12: =(E3*E12)/(D3) -> 77.5 | E12: =(F3*F12)/(E3) -> 93 | F12: =(G3*G12)/(F3) -> 116.25 | G12: =(H3*H12)/(G3) -> 119.23077 | H12: =(I3*I12)/(H3) -> 122.36842 | I12: =(J3*J12)/(I3) -> 125.67568 | ... O12: =(P3*P12)/(O3) -> 150 | P12: 155 | Q12: =(P3*P12)/(Q3) -> 160.34483 | R12: =(Q3*Q12)/(R3) -> 166.07143 | S12: =(R3*R12)/(S3) -> 172.22222 | T12: =(S3*S12)/(T3) -> 178.84615 | U12: =(T3*T12)/(U3) -> 186 | V12: =(U3*U12)/(V3) -> 193.75 | W12: =(V3*V12)/(W3) -> 202.17391 | X12: =(W3*W12)/(X3) -> 211.36364 | ... AJ12: =(AI3*AI12)/(AJ3) -> 465
A13: 36 cm | B13: =(C3*C13)/(B3) -> 48 | C13: =(D3*D13)/(C3) -> 60 | D13: =(E3*E13)/(D3) -> 80 | E13: =(F3*F13)/(E3) -> 96 | F13: =(G3*G13)/(F3) -> 120 | G13: =(H3*H13)/(G3) -> 123.07692 | H13: =(I3*I13)/(H3) -> 126.31579 | I13: =(J3*J13)/(I3) -> 129.72973 | ... O13: =(P3*P13)/(O3) -> 154.83871 | P13: 160 | Q13: =(P3*P13)/(Q3) -> 165.51724 | R13: =(Q3*Q13)/(R3) -> 171.42857 | S13: =(R3*R13)/(S3) -> 177.77778 | T13: =(S3*S13)/(T3) -> 184.61538 | U13: =(T3*T13)/(U3) -> 192 | V13: =(U3*U13)/(V3) -> 200 | W13: =(V3*V13)/(W3) -> 208.69565 | X13: =(W3*W13)/(X3) -> 218.18182 | ... AJ13: =(AI3*AI13)/(AJ3) -> 480
A14: 35 cm | B14: =(C3*C14)/(B3) -> 49.5 | C14: =(D3*D14)/(C3) -> 61.875 | D14: =(E3*E14)/(D3) -> 82.5 | E14: =(F3*F14)/(E3) -> 99 | F14: =(G3*G14)/(F3) -> 123.75 | G14: =(H3*H14)/(G3) -> 126.92308 | H14: =(I3*I14)/(H3) -> 130.26316 | I14: =(J3*J14)/(I3) -> 133.78378 | ... O14: =(P3*P14)/(O3) -> 159.67742 | P14: 165 | Q14: =(P3*P14)/(Q3) -> 170.68966 | R14: =(Q3*Q14)/(R3) -> 176.78571 | S14: =(R3*R14)/(S3) -> 183.33333 | T14: =(S3*S14)/(T3) -> 190.38462 | U14: =(T3*T14)/(U3) -> 198 | V14: =(U3*U14)/(V3) -> 206.25 | W14: =(V3*V14)/(W3) -> 215.21739 | X14: =(W3*W14)/(X3) -> 225 | ... AJ14: =(AI3*AI14)/(AJ3) -> 495
A15: 34 cm | B15: =(C3*C15)/(B3) -> 51 | C15: =(D3*D15)/(C3) -> 63.75 | D15: =(E3*E15)/(D3) -> 85 | E15: =(F3*F15)/(E3) -> 102 | F15: =(G3*G15)/(F3) -> 127.5 | G15: =(H3*H15)/(G3) -> 130.76923 | H15: =(I3*I15)/(H3) -> 134.21053 | I15: =(J3*J15)/(I3) -> 137.83784 | ... O15: =(P3*P15)/(O3) -> 164.51613 | P15: 170 | Q15: =(P3*P15)/(Q3) -> 175.86207 | R15: =(Q3*Q15)/(R3) -> 182.14286 | S15: =(R3*R15)/(S3) -> 188.88889 | T15: =(S3*S15)/(T3) -> 196.15385 | U15: =(T3*T15)/(U3) -> 204 | V15: =(U3*U15)/(V3) -> 212.5 | W15: =(V3*V15)/(W3) -> 221.73913 | X15: =(W3*W15)/(X3) -> 231.81818 | ... AJ15: =(AI3*AI15)/(AJ3) -> 510
A16: 33 cm | B16: =(C3*C16)/(B3) -> 52.5 | C16: =(D3*D16)/(C3) -> 65.625 | D16: =(E3*E16)/(D3) -> 87.5 | E16: =(F3*F16)/(E3) -> 105 | F16: =(G3*G16)/(F3) -> 131.25 | G16: =(H3*H16)/(G3) -> 134.61538 | H16: =(I3*I16)/(H3) -> 138.15789 | I16: =(J3*J16)/(I3) -> 141.89189 | ... O16: =(P3*P16)/(O3) -> 169.35484 | P16: 175 | Q16: =(P3*P16)/(Q3) -> 181.03448 | R16: =(Q3*Q16)/(R3) -> 187.5 | S16: =(R3*R16)/(S3) -> 194.44444 | T16: =(S3*S16)/(T3) -> 201.92308 | U16: =(T3*T16)/(U3) -> 210 | V16: =(U3*U16)/(V3) -> 218.75 | W16: =(V3*V16)/(W3) -> 228.26087 | X16: =(W3*W16)/(X3) -> 238.63636 | ... AJ16: =(AI3*AI16)/(AJ3) -> 525
A17: 32 cm | B17: =(C3*C17)/(B3) -> 54 | C17: =(D3*D17)/(C3) -> 67.5 | D17: =(E3*E17)/(D3) -> 90 | E17: =(F3*F17)/(E3) -> 108 | F17: =(G3*G17)/(F3) -> 135 | G17: =(H3*H17)/(G3) -> 138.46154 | H17: =(I3*I17)/(H3) -> 142.10526 | I17: =(J3*J17)/(I3) -> 145.94595 | ... O17: =(P3*P17)/(O3) -> 174.19355 | P17: 180 | Q17: =(P3*P17)/(Q3) -> 186.2069 | R17: =(Q3*Q17)/(R3) -> 192.85714 | S17: =(R3*R17)/(S3) -> 200 | T17: =(S3*S17)/(T3) -> 207.69231 | U17: =(T3*T17)/(U3) -> 216 | V17: =(U3*U17)/(V3) -> 225 | W17: =(V3*V17)/(W3) -> 234.78261 | X17: =(W3*W17)/(X3) -> 245.45455 | ... AJ17: =(AI3*AI17)/(AJ3) -> 540
A18: 31 cm | B18: =(C3*C18)/(B3) -> 55.5 | C18: =(D3*D18)/(C3) -> 69.375 | D18: =(E3*E18)/(D3) -> 92.5 | E18: =(F3*F18)/(E3) -> 111 | F18: =(G3*G18)/(F3) -> 138.75 | G18: =(H3*H18)/(G3) -> 142.30769 | H18: =(I3*I18)/(H3) -> 146.05263 | I18: =(J3*J18)/(I3) -> 150 | ... O18: =(P3*P18)/(O3) -> 179.03226 | P18: 185 | Q18: =(P3*P18)/(Q3) -> 191.37931 | R18: =(Q3*Q18)/(R3) -> 198.21429 | S18: =(R3*R18)/(S3) -> 205.55556 | T18: =(S3*S18)/(T3) -> 213.46154 | U18: =(T3*T18)/(U3) -> 222 | V18: =(U3*U18)/(V3) -> 231.25 | W18: =(V3*V18)/(W3) -> 241.30435 | X18: =(W3*W18)/(X3) -> 252.27273 | ... AJ18: =(AI3*AI18)/(AJ3) -> 555
A19: 30 cm | B19: =(C3*C19)/(B3) -> 57 | C19: =(D3*D19)/(C3) -> 71.25 | D19: =(E3*E19)/(D3) -> 95 | E19: =(F3*F19)/(E3) -> 114 | F19: =(G3*G19)/(F3) -> 142.5 | G19: =(H3*H19)/(G3) -> 146.15385 | H19: =(I3*I19)/(H3) -> 150 | I19: =(J3*J19)/(I3) -> 154.05405 | ... O19: =(P3*P19)/(O3) -> 183.87097 | P19: 190 | Q19: =(P3*P19)/(Q3) -> 196.55172 | R19: =(Q3*Q19)/(R3) -> 203.57143 | S19: =(R3*R19)/(S3) -> 211.11111 | T19: =(S3*S19)/(T3) -> 219.23077 | U19: =(T3*T19)/(U3) -> 228 | V19: =(U3*U19)/(V3) -> 237.5 | W19: =(V3*V19)/(W3) -> 247.82609 | X19: =(W3*W19)/(X3) -> 259.09091 | ... AJ19: =(AI3*AI19)/(AJ3) -> 570
A20: 29 cm | B20: =(C3*C20)/(B3) -> 58.5 | C20: =(D3*D20)/(C3) -> 73.125 | D20: =(E3*E20)/(D3) -> 97.5 | E20: =(F3*F20)/(E3) -> 117 | F20: =(G3*G20)/(F3) -> 146.25 | G20: =(H3*H20)/(G3) -> 150 | H20: =(I3*I20)/(H3) -> 153.94737 | I20: =(J3*J20)/(I3) -> 158.10811 | ... O20: =(P3*P20)/(O3) -> 188.70968 | P20: 195 | Q20: =(P3*P20)/(Q3) -> 201.72414 | R20: =(Q3*Q20)/(R3) -> 208.92857 | S20: =(R3*R20)/(S3) -> 216.66667 | T20: =(S3*S20)/(T3) -> 225 | U20: =(T3*T20)/(U3) -> 234 | V20: =(U3*U20)/(V3) -> 243.75 | W20: =(V3*V20)/(W3) -> 254.34783 | X20: =(W3*W20)/(X3) -> 265.90909 | ... AJ20: =(AI3*AI20)/(AJ3) -> 585
A21: 28 cm | B21: =(C3*C21)/(B3) -> 60 | C21: =(D3*D21)/(C3) -> 75 | D21: =(E3*E21)/(D3) -> 100 | E21: =(F3*F21)/(E3) -> 120 | F21: =(G3*G21)/(F3) -> 150 | G21: =(H3*H21)/(G3) -> 153.84615 | H21: =(I3*I21)/(H3) -> 157.89474 | I21: =(J3*J21)/(I3) -> 162.16216 | ... O21: =(P3*P21)/(O3) -> 193.54839 | P21: 200 | Q21: =(P3*P21)/(Q3) -> 206.89655 | R21: =(Q3*Q21)/(R3) -> 214.28571 | S21: =(R3*R21)/(S3) -> 222.22222 | T21: =(S3*S21)/(T3) -> 230.76923 | U21: =(T3*T21)/(U3) -> 240 | V21: =(U3*U21)/(V3) -> 250 | W21: =(V3*V21)/(W3) -> 260.86957 | X21: =(W3*W21)/(X3) -> 272.72727 | ... AJ21: =(AI3*AI21)/(AJ3) -> 600
A22: 27 cm | B22: =(C3*C22)/(B3) -> 61.5 | C22: =(D3*D22)/(C3) -> 76.875 | D22: =(E3*E22)/(D3) -> 102.5 | E22: =(F3*F22)/(E3) -> 123 | F22: =(G3*G22)/(F3) -> 153.75 | G22: =(H3*H22)/(G3) -> 157.69231 | H22: =(I3*I22)/(H3) -> 161.84211 | I22: =(J3*J22)/(I3) -> 166.21622 | ... O22: =(P3*P22)/(O3) -> 198.3871 | P22: 205 | Q22: =(P3*P22)/(Q3) -> 212.06897 | R22: =(Q3*Q22)/(R3) -> 219.64286 | S22: =(R3*R22)/(S3) -> 227.77778 | T22: =(S3*S22)/(T3) -> 236.53846 | U22: =(T3*T22)/(U3) -> 246 | V22: =(U3*U22)/(V3) -> 256.25 | W22: =(V3*V22)/(W3) -> 267.3913 | X22: =(W3*W22)/(X3) -> 279.54545 | ... AJ22: =(AI3*AI22)/(AJ3) -> 615
A23: 26 cm | B23: =(C3*C23)/(B3) -> 63 | C23: =(D3*D23)/(C3) -> 78.75 | D23: =(E3*E23)/(D3) -> 105 | E23: =(F3*F23)/(E3) -> 126 | F23: =(G3*G23)/(F3) -> 157.5 | G23: =(H3*H23)/(G3) -> 161.53846 | H23: =(I3*I23)/(H3) -> 165.78947 | I23: =(J3*J23)/(I3) -> 170.27027 | ... O23: =(P3*P23)/(O3) -> 203.22581 | P23: 210 | Q23: =(P3*P23)/(Q3) -> 217.24138 | R23: =(Q3*Q23)/(R3) -> 225 | S23: =(R3*R23)/(S3) -> 233.33333 | T23: =(S3*S23)/(T3) -> 242.30769 | U23: =(T3*T23)/(U3) -> 252 | V23: =(U3*U23)/(V3) -> 262.5 | W23: =(V3*V23)/(W3) -> 273.91304 | X23: =(W3*W23)/(X3) -> 286.36364 | ... AJ23: =(AI3*AI23)/(AJ3) -> 630
A24: 25 cm | B24: =(C3*C24)/(B3) -> 64.5 | C24: =(D3*D24)/(C3) -> 80.625 | D24: =(E3*E24)/(D3) -> 107.5 | E24: =(F3*F24)/(E3) -> 129 | F24: =(G3*G24)/(F3) -> 161.25 | G24: =(H3*H24)/(G3) -> 165.38462 | H24: =(I3*I24)/(H3) -> 169.73684 | I24: =(J3*J24)/(I3) -> 174.32432 | ... O24: =(P3*P24)/(O3) -> 208.06452 | P24: 215 | Q24: =(P3*P24)/(Q3) -> 222.41379 | R24: =(Q3*Q24)/(R3) -> 230.35714 | S24: =(R3*R24)/(S3) -> 238.88889 | T24: =(S3*S24)/(T3) -> 248.07692 | U24: =(T3*T24)/(U3) -> 258 | V24: =(U3*U24)/(V3) -> 268.75 | W24: =(V3*V24)/(W3) -> 280.43478 | X24: =(W3*W24)/(X3) -> 293.18182 | ... AJ24: =(AI3*AI24)/(AJ3) -> 645
A25: 24 cm | B25: =(C3*C25)/(B3) -> 66 | C25: =(D3*D25)/(C3) -> 82.5 | D25: =(E3*E25)/(D3) -> 110 | E25: =(F3*F25)/(E3) -> 132 | F25: =(G3*G25)/(F3) -> 165 | G25: =(H3*H25)/(G3) -> 169.23077 | H25: =(I3*I25)/(H3) -> 173.68421 | I25: =(J3*J25)/(I3) -> 178.37838 | ... O25: =(P3*P25)/(O3) -> 212.90323 | P25: 220 | Q25: =(P3*P25)/(Q3) -> 227.58621 | R25: =(Q3*Q25)/(R3) -> 235.71429 | S25: =(R3*R25)/(S3) -> 244.44444 | T25: =(S3*S25)/(T3) -> 253.84615 | U25: =(T3*T25)/(U3) -> 264 | V25: =(U3*U25)/(V3) -> 275 | W25: =(V3*V25)/(W3) -> 286.95652 | X25: =(W3*W25)/(X3) -> 300 | ... AJ25: =(AI3*AI25)/(AJ3) -> 660
A26: 23 cm | B26: =(C3*C26)/(B3) -> 67.5 | C26: =(D3*D26)/(C3) -> 84.375 | D26: =(E3*E26)/(D3) -> 112.5 | E26: =(F3*F26)/(E3) -> 135 | F26: =(G3*G26)/(F3) -> 168.75 | G26: =(H3*H26)/(G3) -> 173.07692 | H26: =(I3*I26)/(H3) -> 177.63158 | I26: =(J3*J26)/(I3) -> 182.43243 | ... O26: =(P3*P26)/(O3) -> 217.74194 | P26: 225 | Q26: =(P3*P26)/(Q3) -> 232.75862 | R26: =(Q3*Q26)/(R3) -> 241.07143 | S26: =(R3*R26)/(S3) -> 250 | T26: =(S3*S26)/(T3) -> 259.61538 | U26: =(T3*T26)/(U3) -> 270 | V26: =(U3*U26)/(V3) -> 281.25 | W26: =(V3*V26)/(W3) -> 293.47826 | X26: =(W3*W26)/(X3) -> 306.81818 | ... AJ26: =(AI3*AI26)/(AJ3) -> 675
A27: 22 cm | B27: =(C3*C27)/(B3) -> 69 | C27: =(D3*D27)/(C3) -> 86.25 | D27: =(E3*E27)/(D3) -> 115 | E27: =(F3*F27)/(E3) -> 138 | F27: =(G3*G27)/(F3) -> 172.5 | G27: =(H3*H27)/(G3) -> 176.92308 | H27: =(I3*I27)/(H3) -> 181.57895 | I27: =(J3*J27)/(I3) -> 186.48649 | ... O27: =(P3*P27)/(O3) -> 222.58065 | P27: 230 | Q27: =(P3*P27)/(Q3) -> 237.93103 | R27: =(Q3*Q27)/(R3) -> 246.42857 | S27: =(R3*R27)/(S3) -> 255.55556 | T27: =(S3*S27)/(T3) -> 265.38462 | U27: =(T3*T27)/(U3) -> 276 | V27: =(U3*U27)/(V3) -> 287.5 | W27: =(V3*V27)/(W3) -> 300 | X27: =(W3*W27)/(X3) -> 313.63636 | ... AJ27: =(AI3*AI27)/(AJ3) -> 690
A28: 21 cm | B28: =(C3*C28)/(B3) -> 70.5 | C28: =(D3*D28)/(C3) -> 88.125 | D28: =(E3*E28)/(D3) -> 117.5 | E28: =(F3*F28)/(E3) -> 141 | F28: =(G3*G28)/(F3) -> 176.25 | G28: =(H3*H28)/(G3) -> 180.76923 | H28: =(I3*I28)/(H3) -> 185.52632 | I28: =(J3*J28)/(I3) -> 190.54054 | ... O28: =(P3*P28)/(O3) -> 227.41935 | P28: 235 | Q28: =(P3*P28)/(Q3) -> 243.10345 | R28: =(Q3*Q28)/(R3) -> 251.78571 | S28: =(R3*R28)/(S3) -> 261.11111 | T28: =(S3*S28)/(T3) -> 271.15385 | U28: =(T3*T28)/(U3) -> 282 | V28: =(U3*U28)/(V3) -> 293.75 | W28: =(V3*V28)/(W3) -> 306.52174 | X28: =(W3*W28)/(X3) -> 320.45455 | ... AJ28: =(AI3*AI28)/(AJ3) -> 705
A29: 20 cm | B29: =(C3*C29)/(B3) -> 72 | C29: =(D3*D29)/(C3) -> 90 | D29: =(E3*E29)/(D3) -> 120 | E29: =(F3*F29)/(E3) -> 144 | F29: =(G3*G29)/(F3) -> 180 | G29: =(H3*H29)/(G3) -> 184.61538 | H29: =(I3*I29)/(H3) -> 189.47368 | I29: =(J3*J29)/(I3) -> 194.59459 | ... O29: =(P3*P29)/(O3) -> 232.25806 | P29: 240 | Q29: =(P3*P29)/(Q3) -> 248.27586 | R29: =(Q3*Q29)/(R3) -> 257.14286 | S29: =(R3*R29)/(S3) -> 266.66667 | T29: =(S3*S29)/(T3) -> 276.92308 | U29: =(T3*T29)/(U3) -> 288 | V29: =(U3*U29)/(V3) -> 300 | W29: =(V3*V29)/(W3) -> 313.04348 | X29: =(W3*W29)/(X3) -> 327.27273 | ... AJ29: =(AI3*AI29)/(AJ3) -> 720
A30: 19 cm | B30: =(C3*C30)/(B3) -> 73.5 | C30: =(D3*D30)/(C3) -> 91.875 | D30: =(E3*E30)/(D3) -> 122.5 | E30: =(F3*F30)/(E3) -> 147 | F30: =(G3*G30)/(F3) -> 183.75 | G30: =(H3*H30)/(G3) -> 188.46154 | H30: =(I3*I30)/(H3) -> 193.42105 | I30: =(J3*J30)/(I3) -> 198.64865 | ... O30: =(P3*P30)/(O3) -> 237.09677 | P30: 245 | Q30: =(P3*P30)/(Q3) -> 253.44828 | R30: =(Q3*Q30)/(R3) -> 262.5 | S30: =(R3*R30)/(S3) -> 272.22222 | T30: =(S3*S30)/(T3) -> 282.69231 | U30: =(T3*T30)/(U3) -> 294 | V30: =(U3*U30)/(V3) -> 306.25 | W30: =(V3*V30)/(W3) -> 319.56522 | X30: =(W3*W30)/(X3) -> 334.09091 | ... AJ30: =(AI3*AI30)/(AJ3) -> 735
A31: 18 cm | B31: =(C3*C31)/(B3) -> 75 | C31: =(D3*D31)/(C3) -> 93.75 | D31: =(E3*E31)/(D3) -> 125 | E31: =(F3*F31)/(E3) -> 150 | F31: =(G3*G31)/(F3) -> 187.5 | G31: =(H3*H31)/(G3) -> 192.30769 | H31: =(I3*I31)/(H3) -> 197.36842 | I31: =(J3*J31)/(I3) -> 202.7027 | ... O31: =(P3*P31)/(O3) -> 241.93548 | P31: 250 | Q31: =(P3*P31)/(Q3) -> 258.62069 | R31: =(Q3*Q31)/(R3) -> 267.85714 | S31: =(R3*R31)/(S3) -> 277.77778 | T31: =(S3*S31)/(T3) -> 288.46154 | U31: =(T3*T31)/(U3) -> 300 | V31: =(U3*U31)/(V3) -> 312.5 | W31: =(V3*V31)/(W3) -> 326.08696 | X31: =(W3*W31)/(X3) -> 340.90909 | ... AJ31: =(AI3*AI31)/(AJ3) -> 750
A32: 17 cm | B32: =(C3*C32)/(B3) -> 76.5 | C32: =(D3*D32)/(C3) -> 95.625 | D32: =(E3*E32)/(D3) -> 127.5 | E32: =(F3*F32)/(E3) -> 153 | F32: =(G3*G32)/(F3) -> 191.25 | G32: =(H3*H32)/(G3) -> 196.15385 | H32: =(I3*I32)/(H3) -> 201.31579 | I32: =(J3*J32)/(I3) -> 206.75676 | ... O32: =(P3*P32)/(O3) -> 246.77419 | P32: 255 | Q32: =(P3*P32)/(Q3) -> 263.7931 | R32: =(Q3*Q32)/(R3) -> 273.21429 | S32: =(R3*R32)/(S3) -> 283.33333 | T32: =(S3*S32)/(T3) -> 294.23077 | U32: =(T3*T32)/(U3) -> 306 | V32: =(U3*U32)/(V3) -> 318.75 | W32: =(V3*V32)/(W3) -> 332.6087 | X32: =(W3*W32)/(X3) -> 347.72727 | ... AJ32: =(AI3*AI32)/(AJ3) -> 765
A33: 16 cm | B33: =(C3*C33)/(B3) -> 78 | C33: =(D3*D33)/(C3) -> 97.5 | D33: =(E3*E33)/(D3) -> 130 | E33: =(F3*F33)/(E3) -> 156 | F33: =(G3*G33)/(F3) -> 195 | G33: =(H3*H33)/(G3) -> 200 | H33: =(I3*I33)/(H3) -> 205.26316 | I33: =(J3*J33)/(I3) -> 210.81081 | ... O33: =(P3*P33)/(O3) -> 251.6129 | P33: 260 | Q33: =(P3*P33)/(Q3) -> 268.96552 | R33: =(Q3*Q33)/(R3) -> 278.57143 | S33: =(R3*R33)/(S3) -> 288.88889 | T33: =(S3*S33)/(T3) -> 300 | U33: =(T3*T33)/(U3) -> 312 | V33: =(U3*U33)/(V3) -> 325 | W33: =(V3*V33)/(W3) -> 339.13043 | X33: =(W3*W33)/(X3) -> 354.54545 | ... AJ33: =(AI3*AI33)/(AJ3) -> 780
A34: 15 cm | B34: =(C3*C34)/(B3) -> 79.5 | C34: =(D3*D34)/(C3) -> 99.375 | D34: =(E3*E34)/(D3) -> 132.5 | E34: =(F3*F34)/(E3) -> 159 | F34: =(G3*G34)/(F3) -> 198.75 | G34: =(H3*H34)/(G3) -> 203.84615 | H34: =(I3*I34)/(H3) -> 209.21053 | I34: =(J3*J34)/(I3) -> 214.86486 | ... O34: =(P3*P34)/(O3) -> 256.45161 | P34: 265 | Q34: =(P3*P34)/(Q3) -> 274.13793 | R34: =(Q3*Q34)/(R3) -> 283.92857 | S34: =(R3*R34)/(S3) -> 294.44444 | T34: =(S3*S34)/(T3) -> 305.76923 | U34: =(T3*T34)/(U3) -> 318 | V34: =(U3*U34)/(V3) -> 331.25 | W34: =(V3*V34)/(W3) -> 345.65217 | X34: =(W3*W34)/(X3) -> 361.36364 | ... AJ34: =(AI3*AI34)/(AJ3) -> 795
C35: NOT:Çizelgede belirtilen iplik uzunluklarına;Orta renklerde 2mm,Koyu renklerde 4mm daha ilave ekle (hesaplama 18 fayna göre yapılmıştır)
B37: DÜZ RİBANA; 100 MAYDAKİ İPLİK UZUNLUKLARINA GÖRE ORTALAMA MAMÜL GRAMAJLARI
A38: 17 | B38: İPLİK NUMARALARI
A39: FAYN | B39: 100 | C39: 80 | D39: 60 | E39: 50 | F39: 40 | G39: 39 | H39: 38 | I39: 37 | J39: 36 | K39: 35 | L39: 34 | M39: 33 | N39: 32 | O39: 31 | P39: 30 | Q39: 29 | R39: 28 | S39: 27 | T39: 26 | U39: 25 | V39: 24 | W39: 23 | X39: 22 | Y39: 21 | Z39: 20 | AA39: 19 | AB39: 18 | AC39: 17 | AD39: 16 | AE39: 15 | AF39: 14 | AG39: 13 | AH39: 12 | AI39: 11 | AJ39: 10
A40: 45 cm | B40: =(C39*C40)/(B39) -> 33.6 | C40: =(D39*D40)/(C39) -> 42 | D40: =(E39*E40)/(D39) -> 56 | E40: =(F39*F40)/(E39) -> 67.2 | F40: =(G39*G40)/(F39) -> 84 | G40: =(H39*H40)/(G39) -> 86.153846 | H40: =(I39*I40)/(H39) -> 88.421053 | I40: =(J39*J40)/(I39) -> 90.810811 | ... O40: =(P39*P40)/(O39) -> 108.3871 | P40: 112 | Q40: =(P39*P40)/(Q39) -> 115.86207 | R40: =(Q39*Q40)/(R39) -> 120 | S40: =(R39*R40)/(S39) -> 124.44444 | T40: =(S39*S40)/(T39) -> 129.23077 | U40: =(T39*T40)/(U39) -> 134.4 | V40: =(U39*U40)/(V39) -> 140 | W40: =(V39*V40)/(W39) -> 146.08696 | X40: =(W39*W40)/(X39) -> 152.72727 | ... AJ40: =(AI39*AI40)/(AJ39) -> 336
A41: 44 cm | B41: =(C39*C41)/(B39) -> 34.5 | C41: =(D39*D41)/(C39) -> 43.125 | D41: =(E39*E41)/(D39) -> 57.5 | E41: =(F39*F41)/(E39) -> 69 | F41: =(G39*G41)/(F39) -> 86.25 | G41: =(H39*H41)/(G39) -> 88.461538 | H41: =(I39*I41)/(H39) -> 90.789474 | I41: =(J39*J41)/(I39) -> 93.243243 | ... O41: =(P39*P41)/(O39) -> 111.29032 | P41: 115 | Q41: =(P39*P41)/(Q39) -> 118.96552 | R41: =(Q39*Q41)/(R39) -> 123.21429 | S41: =(R39*R41)/(S39) -> 127.77778 | T41: =(S39*S41)/(T39) -> 132.69231 | U41: =(T39*T41)/(U39) -> 138 | V41: =(U39*U41)/(V39) -> 143.75 | W41: =(V39*V41)/(W39) -> 150 | X41: =(W39*W41)/(X39) -> 156.81818 | ... AJ41: =(AI39*AI41)/(AJ39) -> 345
...

Sheet TAM_DOLU_İĞNELİ_DÜZ_RİB_ENLERİ
A1: DÜZ RİBANALAR , PUSS ve FAYNA GÖRE ORTALAMA MAMÜL TÜP ENLERİ
A2: 38 PUSS
B3: Mk. | C3: May | D3: 24 Fayn | F3: Mk. | G3: May | H3: 22 Fayn | J3: Mk. | K3: May | L3: 20 Fayn | N3: Mk. | O3: May | P3: 18 Fayn | R3: Mk. | S3: May | T3: 17 Fayn | V3: Mk. | W3: May | X3: 16 Fayn | Z3: Mk. | AA3: May | AB3: 15 Fayn
A4: KUMAŞ CİNSİ | B4: İğne | F4: İğne | J4: İğne | N4: İğne | R4: İğne | V4: İğne | Z4: İğne
B5: Sayısı | C5: Genişliği | F5: Sayısı | G5: Genişliği | J5: Sayısı | K5: Genişliği | N5: Sayısı | O5: Genişliği | R5: Sayısı | S5: Genişliği | V5: Sayısı | W5: Genişliği | Z5: Sayısı | AA5: Genişliği
A6: 60/1 DÜZ RİBANA | B6: 2862 | C6: 0.0587 | D6: =(B6*C6)/2 -> 83.9997 | F6: 2622 | G6: 0.0538 | H6: =(F6*G6)/2 -> 70.5318 | J6: 2382 | K6: 0.0489 | L6: =(J6*K6)/2 -> 58.2399 | N6: 2136 | O6: 0.044 | P6: =(N6*O6)/2 -> 46.992 | R6: 2016 | S6: 0.0416 | T6: =(R6*S6)/2 -> 41.9328 | V6: 1896 | W6: 0.0391 | X6: =(V6*W6)/2 -> 37.0668 | Z6: 1788 | AA6: 0.0367 | AB6: =(Z6*AA6)/2 -> 32.8098
A7: 50/1 DÜZ RİBANA | B7: 2862 | C7: 0.0705 | D7: =(B7*C7)/2 -> 100.8855 | F7: 2622 | G7: 0.0646 | H7: =(F7*G7)/2 -> 84.6906 | J7: 2382 | K7: 0.0587 | L7: =(J7*K7)/2 -> 69.9117 | N7: 2136 | O7: 0.0528 | P7: =(N7*O7)/2 -> 56.3904 | R7: 2016 | S7: 0.0498 | T7: =(R7*S7)/2 -> 50.1984 | V7: 1896 | W7: 0.047 | X7: =(V7*W7)/2 -> 44.556 | Z7: 1788 | AA7: 0.044 | AB7: =(Z7*AA7)/2 -> 39.336
A8: 40/1 DÜZ RİBANA | B8: 2862 | C8: 0.0881 | D8: =(B8*C8)/2 -> 126.0711 | F8: 2622 | G8: 0.0807 | H8: =(F8*G8)/2 -> 105.7977 | J8: 2382 | K8: 0.0734 | L8: =(J8*K8)/2 -> 87.4194 | N8: 2136 | O8: 0.066 | P8: =(N8*O8)/2 -> 70.488 | R8: 2016 | S8: 0.0623 | T8: =(R8*S8)/2 -> 62.7984 | V8: 1896 | W8: 0.0587 | X8: =(V8*W8)/2 -> 55.6476 | Z8: 1788 | AA8: 0.055 | AB8: =(Z8*AA8)/2 -> 49.17
A9: 36/1 DÜZ RİBANA | B9: 2862 | C9: 0.0978 | D9: =(B9*C9)/2 -> 139.9518 | F9: 2622 | G9: 0.0897 | H9: =(F9*G9)/2 -> 117.5967 | J9: 2382 | K9: 0.0815 | L9: =(J9*K9)/2 -> 97.0665 | N9: 2136 | O9: 0.0733 | P9: =(N9*O9)/2 -> 78.2844 | R9: 2016 | S9: 0.0693 | T9: =(R9*S9)/2 -> 69.8544 | V9: 1896 | W9: 0.0652 | X9: =(V9*W9)/2 -> 61.8096 | Z9: 1788 | AA9: 0.0611 | AB9: =(Z9*AA9)/2 -> 54.6234
A10: 34/1 DÜZ RİBANA | B10: 2862 | C10: 0.1036 | D10: =(B10*C10)/2 -> 148.2516 | F10: 2622 | G10: 0.0949 | H10: =(F10*G10)/2 -> 124.4139 | J10: 2382 | K10: 0.0863 | L10: =(J10*K10)/2 -> 102.7833 | N10: 2136 | O10: 0.0776 | P10: =(N10*O10)/2 -> 82.8768 | R10: 2016 | S10: 0.0733 | T10: =(R10*S10)/2 -> 73.8864 | V10: 1896 | W10: 0.069 | X10: =(V10*W10)/2 -> 65.412 | Z10: 1788 | AA10: 0.0647 | AB10: =(Z10*AA10)/2 -> 57.8418
A11: 32/1 DÜZ RİBANA | B11: 2862 | C11: 0.1101 | D11: =(B11*C11)/2 -> 157.5531 | F11: 2622 | G11: 0.1009 | H11: =(F11*G11)/2 -> 132.2799 | J11: 2382 | K11: 0.0917 | L11: =(J11*K11)/2 -> 109.2147 | N11: 2136 | O11: 0.0825 | P11: =(N11*O11)/2 -> 88.11 | R11: 2016 | S11: 0.0779 | T11: =(R11*S11)/2 -> 78.5232 | V11: 1896 | W11: 0.0733 | X11: =(V11*W11)/2 -> 69.4884 | Z11: 1788 | AA11: 0.0687 | AB11: =(Z11*AA11)/2 -> 61.4178
A12: 30/1 DÜZ RİBANA | B12: 2862 | C12: 0.1174 | D12: =(B12*C12)/2 -> 167.9994 | F12: 2622 | G12: 0.1076 | H12: =(F12*G12)/2 -> 141.0636 | J12: 2382 | K12: 0.0978 | L12: =(J12*K12)/2 -> 116.4798 | N12: 2136 | O12: 0.088 | P12: =(N12*O12)/2 -> 93.984 | R12: 2016 | S12: 0.0831 | T12: =(R12*S12)/2 -> 83.7648 | V12: 1896 | W12: 0.0782 | X12: =(V12*W12)/2 -> 74.1336 | Z12: 1788 | AA12: 0.0733 | AB12: =(Z12*AA12)/2 -> 65.5302
A13: 28/1 DÜZ RİBANA | B13: 2862 | C13: 0.1258 | D13: =(B13*C13)/2 -> 180.0198 | F13: 2622 | G13: 0.1153 | H13: =(F13*G13)/2 -> 151.1583 | J13: 2382 | K13: 0.1048 | L13: =(J13*K13)/2 -> 124.8168 | N13: 2136 | O13: 0.0943 | P13: =(N13*O13)/2 -> 100.7124 | R13: 2016 | S13: 0.089 | T13: =(R13*S13)/2 -> 89.712 | V13: 1896 | W13: 0.0834 | X13: =(V13*W13)/2 -> 79.0632 | Z13: 1788 | AA13: 0.0785 | AB13: =(Z13*AA13)/2 -> 70.179
A14: 26/1 DÜZ RİBANA | B14: 2862 | C14: 0.1355 | D14: =(B14*C14)/2 -> 193.9005 | F14: 2622 | G14: 0.1242 | H14: =(F14*G14)/2 -> 162.8262 | J14: 2382 | K14: 0.1128 | L14: =(J14*K14)/2 -> 134.3448 | N14: 2136 | O14: 0.1015 | P14: =(N14*O14)/2 -> 108.402 | R14: 2016 | S14: 0.0959 | T14: =(R14*S14)/2 -> 96.6672 | V14: 1896 | W14: 0.0902 | X14: =(V14*W14)/2 -> 85.5096 | Z14: 1788 | AA14: 0.0846 | AB14: =(Z14*AA14)/2 -> 75.6324
A15: 24/1 DÜZ RİBANA | B15: 2862 | C15: 0.1468 | D15: =(B15*C15)/2 -> 210.0708 | F15: 2622 | G15: 0.1345 | H15: =(F15*G15)/2 -> 176.3295 | J15: 2382 | K15: 0.1223 | L15: =(J15*K15)/2 -> 145.6593 | N15: 2136 | O15: 0.11 | P15: =(N15*O15)/2 -> 117.48 | R15: 2016 | S15: 0.1039 | T15: =(R15*S15)/2 -> 104.7312 | V15: 1896 | W15: 0.0978 | X15: =(V15*W15)/2 -> 92.7144 | Z15: 1788 | AA15: 0.0916 | AB15: =(Z15*AA15)/2 -> 81.8904
A16: 20/1 DÜZ RİBANA | B16: 2862 | C16: 0 | D16: =(B16*C16)/2 -> 0 | F16: 2622 | G16: 0.1614 | H16: =(F16*G16)/2 -> 211.5954 | J16: 2382 | K16: 0.1467 | L16: =(J16*K16)/2 -> 174.7197 | N16: 2136 | O16: 0.132 | P16: =(N16*O16)/2 -> 140.976 | R16: 2016 | S16: 0.1247 | T16: =(R16*S16)/2 -> 125.6976 | V16: 1896 | W16: 0.1173 | X16: =(V16*W16)/2 -> 111.2004 | Z16: 1788 | AA16: 0.11 | AB16: =(Z16*AA16)/2 -> 98.34
A17: 36 PUSS
B18: Mk. | C18: May | D18: 24 Fayn | F18: Mk. | G18: May | H18: 22 Fayn | J18: Mk. | K18: May | L18: 20 Fayn | N18: Mk. | O18: May | P18: 18 Fayn | R18: Mk. | S18: May | T18: 17 Fayn | V18: Mk. | W18: May | X18: 16 Fayn | Z18: Mk. | AA18: May | AB18: 15 Fayn
A19: KUMAŞ CİNSİ | B19: İğne | F19: İğne | J19: İğne | N19: İğne | R19: İğne | V19: İğne | Z19: İğne
B20: Sayısı | C20: Genişliği | F20: Sayısı | G20: Genişliği | J20: Sayısı | K20: Genişliği | N20: Sayısı | O20: Genişliği | R20: Sayısı | S20: Genişliği | V20: Sayısı | W20: Genişliği | Z20: Sayısı | AA20: Genişliği
A21: 60/1 DÜZ RİBANA | B21: 2712 | C21: 0.0587 | D21: =(B21*C21)/2 -> 79.5972 | F21: 2478 | G21: 0.0538 | H21: =(F21*G21)/2 -> 66.6582 | J21: 2256 | K21: 0.0489 | L21: =(J21*K21)/2 -> 55.1592 | N21: 2016 | O21: 0.044 | P21: =(N21*O21)/2 -> 44.352 | R21: 1920 | S21: 0.0416 | T21: =(R21*S21)/2 -> 39.936 | V21: 1800 | W21: 0.0391 | X21: =(V21*W21)/2 -> 35.19 | Z21: 1680 | AA21: 0.0367 | AB21: =(Z21*AA21)/2 -> 30.828
A22: 50/1 DÜZ RİBANA | B22: 2712 | C22: 0.0705 | D22: =(B22*C22)/2 -> 95.598 | F22: 2478 | G22: 0.0646 | H22: =(F22*G22)/2 -> 80.0394 | J22: 2256 | K22: 0.0587 | L22: =(J22*K22)/2 -> 66.2136 | N22: 2016 | O22: 0.0528 | P22: =(N22*O22)/2 -> 53.2224 | R22: 1920 | S22: 0.0498 | T22: =(R22*S22)/2 -> 47.808 | V22: 1800 | W22: 0.047 | X22: =(V22*W22)/2 -> 42.3 | Z22: 1680 | AA22: 0.044 | AB22: =(Z22*AA22)/2 -> 36.96
A23: 40/1 DÜZ RİBANA | B23: 2712 | C23: 0.0881 | D23: =(B23*C23)/2 -> 119.4636 | F23: 2478 | G23: 0.0807 | H23: =(F23*G23)/2 -> 99.9873 | J23: 2256 | K23: 0.0734 | L23: =(J23*K23)/2 -> 82.7952 | N23: 2016 | O23: 0.066 | P23: =(N23*O23)/2 -> 66.528 | R23: 1920 | S23: 0.0623 | T23: =(R23*S23)/2 -> 59.808 | V23: 1800 | W23: 0.0587 | X23: =(V23*W23)/2 -> 52.83 | Z23: 1680 | AA23: 0.055 | AB23: =(Z23*AA23)/2 -> 46.2
A24: 36/1 DÜZ RİBANA | B24: 2712 | C24: 0.0978 | D24: =(B24*C24)/2 -> 132.6168 | F24: 2478 | G24: 0.0897 | H24: =(F24*G24)/2 -> 111.1383 | J24: 2256 | K24: 0.0815 | L24: =(J24*K24)/2 -> 91.932 | N24: 2016 | O24: 0.0733 | P24: =(N24*O24)/2 -> 73.8864 | R24: 1920 | S24: 0.0693 | T24: =(R24*S24)/2 -> 66.528 | V24: 1800 | W24: 0.0652 | X24: =(V24*W24)/2 -> 58.68 | Z24: 1680 | AA24: 0.0611 | AB24: =(Z24*AA24)/2 -> 51.324
A25: 34/1 DÜZ RİBANA | B25: 2712 | C25: 0.1036 | D25: =(B25*C25)/2 -> 140.4816 | F25: 2478 | G25: 0.0949 | H25: =(F25*G25)/2 -> 117.5811 | J25: 2256 | K25: 0.0863 | L25: =(J25*K25)/2 -> 97.3464 | N25: 2016 | O25: 0.0776 | P25: =(N25*O25)/2 -> 78.2208 | R25: 1920 | S25: 0.0733 | T25: =(R25*S25)/2 -> 70.368 | V25: 1800 | W25: 0.069 | X25: =(V25*W25)/2 -> 62.1 | Z25: 1680 | AA25: 0.0647 | AB25: =(Z25*AA25)/2 -> 54.348
A26: 32/1 DÜZ RİBANA | B26: 2712 | C26: 0.1101 | D26: =(B26*C26)/2 -> 149.2956 | F26: 2478 | G26: 0.1009 | H26: =(F26*G26)/2 -> 125.0151 | J26: 2256 | K26: 0.0917 | L26: =(J26*K26)/2 -> 103.4376 | N26: 2016 | O26: 0.0825 | P26: =(N26*O26)/2 -> 83.16 | R26: 1920 | S26: 0.0779 | T26: =(R26*S26)/2 -> 74.784 | V26: 1800 | W26: 0.0733 | X26: =(V26*W26)/2 -> 65.97 | Z26: 1680 | AA26: 0.0687 | AB26: =(Z26*AA26)/2 -> 57.708
A27: 30/1 DÜZ RİBANA | B27: 2712 | C27: 0.1174 | D27: =(B27*C27)/2 -> 159.1944 | F27: 2478 | G27: 0.1076 | H27: =(F27*G27)/2 -> 133.3164 | J27: 2256 | K27: 0.0978 | L27: =(J27*K27)/2 -> 110.3184 | N27: 2016 | O27: 0.088 | P27: =(N27*O27)/2 -> 88.704 | R27: 1920 | S27: 0.0831 | T27: =(R27*S27)/2 -> 79.776 | V27: 1800 | W27: 0.0782 | X27: =(V27*W27)/2 -> 70.38 | Z27: 1680 | AA27: 0.0733 | AB27: =(Z27*AA27)/2 -> 61.572
A28: 28/1 DÜZ RİBANA | B28: 2712 | C28: 0.1258 | D28: =(B28*C28)/2 -> 170.5848 | F28: 2478 | G28: 0.1153 | H28: =(F28*G28)/2 -> 142.8567 | J28: 2256 | K28: 0.1048 | L28: =(J28*K28)/2 -> 118.2144 | N28: 2016 | O28: 0.0943 | P28: =(N28*O28)/2 -> 95.0544 | R28: 1920 | S28: 0.089 | T28: =(R28*S28)/2 -> 85.44 | V28: 1800 | W28: 0.0834 | X28: =(V28*W28)/2 -> 75.06 | Z28: 1680 | AA28: 0.0785 | AB28: =(Z28*AA28)/2 -> 65.94
A29: 26/1 DÜZ RİBANA | B29: 2712 | C29: 0.1355 | D29: =(B29*C29)/2 -> 183.738 | F29: 2478 | G29: 0.1242 | H29: =(F29*G29)/2 -> 153.8838 | J29: 2256 | K29: 0.1128 | L29: =(J29*K29)/2 -> 127.2384 | N29: 2016 | O29: 0.1015 | P29: =(N29*O29)/2 -> 102.312 | R29: 1920 | S29: 0.0959 | T29: =(R29*S29)/2 -> 92.064 | V29: 1800 | W29: 0.0902 | X29: =(V29*W29)/2 -> 81.18 | Z29: 1680 | AA29: 0.0846 | AB29: =(Z29*AA29)/2 -> 71.064
A30: 24/1 DÜZ RİBANA | B30: 2712 | C30: 0.1468 | D30: =(B30*C30)/2 -> 199.0608 | F30: 2478 | G30: 0.1345 | H30: =(F30*G30)/2 -> 166.6455 | J30: 2256 | K30: 0.1223 | L30: =(J30*K30)/2 -> 137.9544 | N30: 2016 | O30: 0.11 | P30: =(N30*O30)/2 -> 110.88 | R30: 1920 | S30: 0.1039 | T30: =(R30*S30)/2 -> 99.744 | V30: 1800 | W30: 0.0978 | X30: =(V30*W30)/2 -> 88.02 | Z30: 1680 | AA30: 0.0916 | AB30: =(Z30*AA30)/2 -> 76.944
A31: 20/1 DÜZ RİBANA | B31: 2712 | C31: 0 | D31: =(B31*C31)/2 -> 0 | F31: 2478 | G31: 0.1614 | H31: =(F31*G31)/2 -> 199.9746 | J31: 2256 | K31: 0.1467 | L31: =(J31*K31)/2 -> 165.4776 | N31: 2016 | O31: 0.132 | P31: =(N31*O31)/2 -> 133.056 | R31: 1920 | S31: 0.1247 | T31: =(R31*S31)/2 -> 119.712 | V31: 1800 | W31: 0.1173 | X31: =(V31*W31)/2 -> 105.57 | Z31: 1680 | AA31: 0.11 | AB31: =(Z31*AA31)/2 -> 92.4
A32: 34 PUSS
B33: Mk. | C33: May | D33: 24 Fayn | F33: Mk. | G33: May | H33: 22 Fayn | J33: Mk. | K33: May | L33: 20 Fayn | N33: Mk. | O33: May | P33: 18 Fayn | R33: Mk. | S33: May | T33: 17 Fayn | V33: Mk. | W33: May | X33: 16 Fayn | Z33: Mk. | AA33: May | AB33: 15 Fayn
A34: KUMAŞ CİNSİ | B34: İğne | F34: İğne | J34: İğne | N34: İğne | R34: İğne | V34: İğne | Z34: İğne
B35: Sayısı | C35: Genişliği | F35: Sayısı | G35: Genişliği | J35: Sayısı | K35: Genişliği | N35: Sayısı | O35: Genişliği | R35: Sayısı | S35: Genişliği | V35: Sayısı | W35: Genişliği | Z35: Sayısı | AA35: Genişliği
A36: 60/1 DÜZ RİBANA | B36: 2562 | C36: 0.0587 | D36: =(B36*C36)/2 -> 75.1947 | F36: 2346 | G36: 0.0538 | H36: =(F36*G36)/2 -> 63.1074 | J36: 2136 | K36: 0.0489 | L36: =(J36*K36)/2 -> 52.2252 | N36: 1920 | O36: 0.044 | P36: =(N36*O36)/2 -> 42.24 | R36: 1818 | S36: 0.0416 | T36: =(R36*S36)/2 -> 37.8144 | V36: 1704 | W36: 0.0391 | X36: =(V36*W36)/2 -> 33.3132 | Z36: 1596 | AA36: 0.0367 | AB36: =(Z36*AA36)/2 -> 29.2866
A37: 50/1 DÜZ RİBANA | B37: 2562 | C37: 0.0705 | D37: =(B37*C37)/2 -> 90.3105 | F37: 2346 | G37: 0.0646 | H37: =(F37*G37)/2 -> 75.7758 | J37: 2136 | K37: 0.0587 | L37: =(J37*K37)/2 -> 62.6916 | N37: 1920 | O37: 0.0528 | P37: =(N37*O37)/2 -> 50.688 | R37: 1818 | S37: 0.0498 | T37: =(R37*S37)/2 -> 45.2682 | V37: 1704 | W37: 0.047 | X37: =(V37*W37)/2 -> 40.044 | Z37: 1596 | AA37: 0.044 | AB37: =(Z37*AA37)/2 -> 35.112
A38: 40/1 DÜZ RİBANA | B38: 2562 | C38: 0.0881 | D38: =(B38*C38)/2 -> 112.8561 | F38: 2346 | G38: 0.0807 | H38: =(F38*G38)/2 -> 94.6611 | J38: 2136 | K38: 0.0734 | L38: =(J38*K38)/2 -> 78.3912 | N38: 1920 | O38: 0.066 | P38: =(N38*O38)/2 -> 63.36 | R38: 1818 | S38: 0.0623 | T38: =(R38*S38)/2 -> 56.6307 | V38: 1704 | W38: 0.0587 | X38: =(V38*W38)/2 -> 50.0124 | Z38: 1596 | AA38: 0.055 | AB38: =(Z38*AA38)/2 -> 43.89
A39: 36/1 DÜZ RİBANA | B39: 2562 | C39: 0.0978 | D39: =(B39*C39)/2 -> 125.2818 | F39: 2346 | G39: 0.0897 | H39: =(F39*G39)/2 -> 105.2181 | J39: 2136 | K39: 0.0815 | L39: =(J39*K39)/2 -> 87.042 | N39: 1920 | O39: 0.0733 | P39: =(N39*O39)/2 -> 70.368 | R39: 1818 | S39: 0.0693 | T39: =(R39*S39)/2 -> 62.9937 | V39: 1704 | W39: 0.0652 | X39: =(V39*W39)/2 -> 55.5504 | Z39: 1596 | AA39: 0.0611 | AB39: =(Z39*AA39)/2 -> 48.7578
A40: 34/1 DÜZ RİBANA | B40: 2562 | C40: 0.1036 | D40: =(B40*C40)/2 -> 132.7116 | F40: 2346 | G40: 0.0949 | H40: =(F40*G40)/2 -> 111.3177 | J40: 2136 | K40: 0.0863 | L40: =(J40*K40)/2 -> 92.1684 | N40: 1920 | O40: 0.0776 | P40: =(N40*O40)/2 -> 74.496 | R40: 1818 | S40: 0.0733 | T40: =(R40*S40)/2 -> 66.6297 | V40: 1704 | W40: 0.069 | X40: =(V40*W40)/2 -> 58.788 | Z40: 1596 | AA40: 0.0647 | AB40: =(Z40*AA40)/2 -> 51.6306
...

Sheet 1X1 ÇİFT KAT DÜZ RİBANA GRAMAJ
A1: 50 iğne | B1: 1x1 iğne boşaltmalı çift katlı DÜZ RİBANA; 100 MAYDAKİ İPLİK UZUNLUKLARINA GÖRE ORTALAMA MAMÜL GRAMAJLARI
A2: 18 | B2: İPLİK NUMARALARI
A3: FAYN | B3: 100 | C3: 80 | D3: 60 | E3: 50 | F3: 40 | G3: 39 | H3: 38 | I3: 37 | J3: 36 | K3: 35 | L3: 34 | M3: 33 | N3: 32 | O3: 31 | P3: 30 | Q3: 29 | R3: 28 | S3: 27 | T3: 26 | U3: 25 | V3: 24 | W3: 23 | X3: 22 | Y3: 21 | Z3: 20 | AA3: 19 | AB3: 18 | AC3: 17 | AD3: 16 | AE3: 15 | AF3: 14 | AG3: 13 | AH3: 12 | AI3: 11 | AJ3: 10
A4: 45 cm | B4: =(C3*C4)/(B3) -> 22.2 | C4: =(D3*D4)/(C3) -> 27.75 | D4: =(E3*E4)/(D3) -> 37 | E4: =(F3*F4)/(E3) -> 44.4 | F4: =(G3*G4)/(F3) -> 55.5 | G4: =(H3*H4)/(G3) -> 56.923077 | H4: =(I3*I4)/(H3) -> 58.421053 | I4: =(J3*J4)/(I3) -> 60 | ... O4: =(P3*P4)/(O3) -> 71.612903 | P4: 74 | Q4: =(P3*P4)/(Q3) -> 76.551724 | R4: =(Q3*Q4)/(R3) -> 79.285714 | S4: =(R3*R4)/(S3) -> 82.222222 | T4: =(S3*S4)/(T3) -> 85.384615 | U4: =(T3*T4)/(U3) -> 88.8 | V4: =(U3*U4)/(V3) -> 92.5 | W4: =(V3*V4)/(W3) -> 96.521739 | X4: =(W3*W4)/(X3) -> 100.90909 | ... AJ4: =(AI3*AI4)/(AJ3) -> 222
A5: 44 cm | B5: =(C3*C5)/(B3) -> 22.5 | C5: =(D3*D5)/(C3) -> 28.125 | D5: =(E3*E5)/(D3) -> 37.5 | E5: =(F3*F5)/(E3) -> 45 | F5: =(G3*G5)/(F3) -> 56.25 | G5: =(H3*H5)/(G3) -> 57.692308 | H5: =(I3*I5)/(H3) -> 59.210526 | I5: =(J3*J5)/(I3) -> 60.810811 | ... O5: =(P3*P5)/(O3) -> 72.580645 | P5: 75 | Q5: =(P3*P5)/(Q3) -> 77.586207 | R5: =(Q3*Q5)/(R3) -> 80.357143 | S5: =(R3*R5)/(S3) -> 83.333333 | T5: =(S3*S5)/(T3) -> 86.538462 | U5: =(T3*T5)/(U3) -> 90 | V5: =(U3*U5)/(V3) -> 93.75 | W5: =(V3*V5)/(W3) -> 97.826087 | X5: =(W3*W5)/(X3) -> 102.27273 | ... AJ5: =(AI3*AI5)/(AJ3) -> 225
A6: 43 cm | B6: =(C3*C6)/(B3) -> 23.1 | C6: =(D3*D6)/(C3) -> 28.875 | D6: =(E3*E6)/(D3) -> 38.5 | E6: =(F3*F6)/(E3) -> 46.2 | F6: =(G3*G6)/(F3) -> 57.75 | G6: =(H3*H6)/(G3) -> 59.230769 | H6: =(I3*I6)/(H3) -> 60.789474 | I6: =(J3*J6)/(I3) -> 62.432432 | ... O6: =(P3*P6)/(O3) -> 74.516129 | P6: 77 | Q6: =(P3*P6)/(Q3) -> 79.655172 | R6: =(Q3*Q6)/(R3) -> 82.5 | S6: =(R3*R6)/(S3) -> 85.555556 | T6: =(S3*S6)/(T3) -> 88.846154 | U6: =(T3*T6)/(U3) -> 92.4 | V6: =(U3*U6)/(V3) -> 96.25 | W6: =(V3*V6)/(W3) -> 100.43478 | X6: =(W3*W6)/(X3) -> 105 | ... AJ6: =(AI3*AI6)/(AJ3) -> 231
A7: 42 cm | B7: =(C3*C7)/(B3) -> 23.7 | C7: =(D3*D7)/(C3) -> 29.625 | D7: =(E3*E7)/(D3) -> 39.5 | E7: =(F3*F7)/(E3) -> 47.4 | F7: =(G3*G7)/(F3) -> 59.25 | G7: =(H3*H7)/(G3) -> 60.769231 | H7: =(I3*I7)/(H3) -> 62.368421 | I7: =(J3*J7)/(I3) -> 64.054054 | ... O7: =(P3*P7)/(O3) -> 76.451613 | P7: 79 | Q7: =(P3*P7)/(Q3) -> 81.724138 | R7: =(Q3*Q7)/(R3) -> 84.642857 | S7: =(R3*R7)/(S3) -> 87.777778 | T7: =(S3*S7)/(T3) -> 91.153846 | U7: =(T3*T7)/(U3) -> 94.8 | V7: =(U3*U7)/(V3) -> 98.75 | W7: =(V3*V7)/(W3) -> 103.04348 | X7: =(W3*W7)/(X3) -> 107.72727 | ... AJ7: =(AI3*AI7)/(AJ3) -> 237
A8: 41 cm | B8: =(C3*C8)/(B3) -> 24.3 | C8: =(D3*D8)/(C3) -> 30.375 | D8: =(E3*E8)/(D3) -> 40.5 | E8: =(F3*F8)/(E3) -> 48.6 | F8: =(G3*G8)/(F3) -> 60.75 | G8: =(H3*H8)/(G3) -> 62.307692 | H8: =(I3*I8)/(H3) -> 63.947368 | I8: =(J3*J8)/(I3) -> 65.675676 | ... O8: =(P3*P8)/(O3) -> 78.387097 | P8: 81 | Q8: =(P3*P8)/(Q3) -> 83.793103 | R8: =(Q3*Q8)/(R3) -> 86.785714 | S8: =(R3*R8)/(S3) -> 90 | T8: =(S3*S8)/(T3) -> 93.461538 | U8: =(T3*T8)/(U3) -> 97.2 | V8: =(U3*U8)/(V3) -> 101.25 | W8: =(V3*V8)/(W3) -> 105.65217 | X8: =(W3*W8)/(X3) -> 110.45455 | ... AJ8: =(AI3*AI8)/(AJ3) -> 243
A9: 40 cm | B9: =(C3*C9)/(B3) -> 24.9 | C9: =(D3*D9)/(C3) -> 31.125 | D9: =(E3*E9)/(D3) -> 41.5 | E9: =(F3*F9)/(E3) -> 49.8 | F9: =(G3*G9)/(F3) -> 62.25 | G9: =(H3*H9)/(G3) -> 63.846154 | H9: =(I3*I9)/(H3) -> 65.526316 | I9: =(J3*J9)/(I3) -> 67.297297 | ... O9: =(P3*P9)/(O3) -> 80.322581 | P9: 83 | Q9: =(P3*P9)/(Q3) -> 85.862069 | R9: =(Q3*Q9)/(R3) -> 88.928571 | S9: =(R3*R9)/(S3) -> 92.222222 | T9: =(S3*S9)/(T3) -> 95.769231 | U9: =(T3*T9)/(U3) -> 99.6 | V9: =(U3*U9)/(V3) -> 103.75 | W9: =(V3*V9)/(W3) -> 108.26087 | X9: =(W3*W9)/(X3) -> 113.18182 | ... AJ9: =(AI3*AI9)/(AJ3) -> 249
A10: 39 cm | B10: =(C3*C10)/(B3) -> 25.5 | C10: =(D3*D10)/(C3) -> 31.875 | D10: =(E3*E10)/(D3) -> 42.5 | E10: =(F3*F10)/(E3) -> 51 | F10: =(G3*G10)/(F3) -> 63.75 | G10: =(H3*H10)/(G3) -> 65.384615 | H10: =(I3*I10)/(H3) -> 67.105263 | I10: =(J3*J10)/(I3) -> 68.918919 | ... O10: =(P3*P10)/(O3) -> 82.258065 | P10: 85 | Q10: =(P3*P10)/(Q3) -> 87.931034 | R10: =(Q3*Q10)/(R3) -> 91.071429 | S10: =(R3*R10)/(S3) -> 94.444444 | T10: =(S3*S10)/(T3) -> 98.076923 | U10: =(T3*T10)/(U3) -> 102 | V10: =(U3*U10)/(V3) -> 106.25 | W10: =(V3*V10)/(W3) -> 110.86957 | X10: =(W3*W10)/(X3) -> 115.90909 | ... AJ10: =(AI3*AI10)/(AJ3) -> 255
A11: 38 cm | B11: =(C3*C11)/(B3) -> 26.1 | C11: =(D3*D11)/(C3) -> 32.625 | D11: =(E3*E11)/(D3) -> 43.5 | E11: =(F3*F11)/(E3) -> 52.2 | F11: =(G3*G11)/(F3) -> 65.25 | G11: =(H3*H11)/(G3) -> 66.923077 | H11: =(I3*I11)/(H3) -> 68.684211 | I11: =(J3*J11)/(I3) -> 70.540541 | ... O11: =(P3*P11)/(O3) -> 84.193548 | P11: 87 | Q11: =(P3*P11)/(Q3) -> 90 | R11: =(Q3*Q11)/(R3) -> 93.214286 | S11: =(R3*R11)/(S3) -> 96.666667 | T11: =(S3*S11)/(T3) -> 100.38462 | U11: =(T3*T11)/(U3) -> 104.4 | V11: =(U3*U11)/(V3) -> 108.75 | W11: =(V3*V11)/(W3) -> 113.47826 | X11: =(W3*W11)/(X3) -> 118.63636 | ... AJ11: =(AI3*AI11)/(AJ3) -> 261
A12: 37 cm | B12: =(C3*C12)/(B3) -> 27 | C12: =(D3*D12)/(C3) -> 33.75 | D12: =(E3*E12)/(D3) -> 45 | E12: =(F3*F12)/(E3) -> 54 | F12: =(G3*G12)/(F3) -> 67.5 | G12: =(H3*H12)/(G3) -> 69.230769 | H12: =(I3*I12)/(H3) -> 71.052632 | I12: =(J3*J12)/(I3) -> 72.972973 | ... O12: =(P3*P12)/(O3) -> 87.096774 | P12: 90 | Q12: =(P3*P12)/(Q3) -> 93.103448 | R12: =(Q3*Q12)/(R3) -> 96.428571 | S12: =(R3*R12)/(S3) -> 100 | T12: =(S3*S12)/(T3) -> 103.84615 | U12: =(T3*T12)/(U3) -> 108 | V12: =(U3*U12)/(V3) -> 112.5 | W12: =(V3*V12)/(W3) -> 117.3913 | X12: =(W3*W12)/(X3) -> 122.72727 | ... AJ12: =(AI3*AI12)/(AJ3) -> 270
A13: 36 cm | B13: =(C3*C13)/(B3) -> 27.6 | C13: =(D3*D13)/(C3) -> 34.5 | D13: =(E3*E13)/(D3) -> 46 | E13: =(F3*F13)/(E3) -> 55.2 | F13: =(G3*G13)/(F3) -> 69 | G13: =(H3*H13)/(G3) -> 70.769231 | H13: =(I3*I13)/(H3) -> 72.631579 | I13: =(J3*J13)/(I3) -> 74.594595 | ... O13: =(P3*P13)/(O3) -> 89.032258 | P13: 92 | Q13: =(P3*P13)/(Q3) -> 95.172414 | R13: =(Q3*Q13)/(R3) -> 98.571429 | S13: =(R3*R13)/(S3) -> 102.22222 | T13: =(S3*S13)/(T3) -> 106.15385 | U13: =(T3*T13)/(U3) -> 110.4 | V13: =(U3*U13)/(V3) -> 115 | W13: =(V3*V13)/(W3) -> 120 | X13: =(W3*W13)/(X3) -> 125.45455 | ... AJ13: =(AI3*AI13)/(AJ3) -> 276
A14: 35 cm | B14: =(C3*C14)/(B3) -> 28.5 | C14: =(D3*D14)/(C3) -> 35.625 | D14: =(E3*E14)/(D3) -> 47.5 | E14: =(F3*F14)/(E3) -> 57 | F14: =(G3*G14)/(F3) -> 71.25 | G14: =(H3*H14)/(G3) -> 73.076923 | H14: =(I3*I14)/(H3) -> 75 | I14: =(J3*J14)/(I3) -> 77.027027 | ... O14: =(P3*P14)/(O3) -> 91.935484 | P14: 95 | Q14: =(P3*P14)/(Q3) -> 98.275862 | R14: =(Q3*Q14)/(R3) -> 101.78571 | S14: =(R3*R14)/(S3) -> 105.55556 | T14: =(S3*S14)/(T3) -> 109.61538 | U14: =(T3*T14)/(U3) -> 114 | V14: =(U3*U14)/(V3) -> 118.75 | W14: =(V3*V14)/(W3) -> 123.91304 | X14: =(W3*W14)/(X3) -> 129.54545 | ... AJ14: =(AI3*AI14)/(AJ3) -> 285
A15: 34 cm | B15: =(C3*C15)/(B3) -> 29.1 | C15: =(D3*D15)/(C3) -> 36.375 | D15: =(E3*E15)/(D3) -> 48.5 | E15: =(F3*F15)/(E3) -> 58.2 | F15: =(G3*G15)/(F3) -> 72.75 | G15: =(H3*H15)/(G3) -> 74.615385 | H15: =(I3*I15)/(H3) -> 76.578947 | I15: =(J3*J15)/(I3) -> 78.648649 | ... O15: =(P3*P15)/(O3) -> 93.870968 | P15: 97 | Q15: =(P3*P15)/(Q3) -> 100.34483 | R15: =(Q3*Q15)/(R3) -> 103.92857 | S15: =(R3*R15)/(S3) -> 107.77778 | T15: =(S3*S15)/(T3) -> 111.92308 | U15: =(T3*T15)/(U3) -> 116.4 | V15: =(U3*U15)/(V3) -> 121.25 | W15: =(V3*V15)/(W3) -> 126.52174 | X15: =(W3*W15)/(X3) -> 132.27273 | ... AJ15: =(AI3*AI15)/(AJ3) -> 291
A16: 33 cm | B16: =(C3*C16)/(B3) -> 30 | C16: =(D3*D16)/(C3) -> 37.5 | D16: =(E3*E16)/(D3) -> 50 | E16: =(F3*F16)/(E3) -> 60 | F16: =(G3*G16)/(F3) -> 75 | G16: =(H3*H16)/(G3) -> 76.923077 | H16: =(I3*I16)/(H3) -> 78.947368 | I16: =(J3*J16)/(I3) -> 81.081081 | ... O16: =(P3*P16)/(O3) -> 96.774194 | P16: 100 | Q16: =(P3*P16)/(Q3) -> 103.44828 | R16: =(Q3*Q16)/(R3) -> 107.14286 | S16: =(R3*R16)/(S3) -> 111.11111 | T16: =(S3*S16)/(T3) -> 115.38462 | U16: =(T3*T16)/(U3) -> 120 | V16: =(U3*U16)/(V3) -> 125 | W16: =(V3*V16)/(W3) -> 130.43478 | X16: =(W3*W16)/(X3) -> 136.36364 | ... AJ16: =(AI3*AI16)/(AJ3) -> 300
A17: 32 cm | B17: =(C3*C17)/(B3) -> 31.2 | C17: =(D3*D17)/(C3) -> 39 | D17: =(E3*E17)/(D3) -> 52 | E17: =(F3*F17)/(E3) -> 62.4 | F17: =(G3*G17)/(F3) -> 78 | G17: =(H3*H17)/(G3) -> 80 | H17: =(I3*I17)/(H3) -> 82.105263 | I17: =(J3*J17)/(I3) -> 84.324324 | ... O17: =(P3*P17)/(O3) -> 100.64516 | P17: 104 | Q17: =(P3*P17)/(Q3) -> 107.58621 | R17: =(Q3*Q17)/(R3) -> 111.42857 | S17: =(R3*R17)/(S3) -> 115.55556 | T17: =(S3*S17)/(T3) -> 120 | U17: =(T3*T17)/(U3) -> 124.8 | V17: =(U3*U17)/(V3) -> 130 | W17: =(V3*V17)/(W3) -> 135.65217 | X17: =(W3*W17)/(X3) -> 141.81818 | ... AJ17: =(AI3*AI17)/(AJ3) -> 312
A18: 31 cm | B18: =(C3*C18)/(B3) -> 32.1 | C18: =(D3*D18)/(C3) -> 40.125 | D18: =(E3*E18)/(D3) -> 53.5 | E18: =(F3*F18)/(E3) -> 64.2 | F18: =(G3*G18)/(F3) -> 80.25 | G18: =(H3*H18)/(G3) -> 82.307692 | H18: =(I3*I18)/(H3) -> 84.473684 | I18: =(J3*J18)/(I3) -> 86.756757 | ... O18: =(P3*P18)/(O3) -> 103.54839 | P18: 107 | Q18: =(P3*P18)/(Q3) -> 110.68966 | R18: =(Q3*Q18)/(R3) -> 114.64286 | S18: =(R3*R18)/(S3) -> 118.88889 | T18: =(S3*S18)/(T3) -> 123.46154 | U18: =(T3*T18)/(U3) -> 128.4 | V18: =(U3*U18)/(V3) -> 133.75 | W18: =(V3*V18)/(W3) -> 139.56522 | X18: =(W3*W18)/(X3) -> 145.90909 | ... AJ18: =(AI3*AI18)/(AJ3) -> 321
A19: 30 cm | B19: =(C3*C19)/(B3) -> 33 | C19: =(D3*D19)/(C3) -> 41.25 | D19: =(E3*E19)/(D3) -> 55 | E19: =(F3*F19)/(E3) -> 66 | F19: =(G3*G19)/(F3) -> 82.5 | G19: =(H3*H19)/(G3) -> 84.615385 | H19: =(I3*I19)/(H3) -> 86.842105 | I19: =(J3*J19)/(I3) -> 89.189189 | ... O19: =(P3*P19)/(O3) -> 106.45161 | P19: 110 | Q19: =(P3*P19)/(Q3) -> 113.7931 | R19: =(Q3*Q19)/(R3) -> 117.85714 | S19: =(R3*R19)/(S3) -> 122.22222 | T19: =(S3*S19)/(T3) -> 126.92308 | U19: =(T3*T19)/(U3) -> 132 | V19: =(U3*U19)/(V3) -> 137.5 | W19: =(V3*V19)/(W3) -> 143.47826 | X19: =(W3*W19)/(X3) -> 150 | ... AJ19: =(AI3*AI19)/(AJ3) -> 330
A20: 29 cm | B20: =(C3*C20)/(B3) -> 34.2 | C20: =(D3*D20)/(C3) -> 42.75 | D20: =(E3*E20)/(D3) -> 57 | E20: =(F3*F20)/(E3) -> 68.4 | F20: =(G3*G20)/(F3) -> 85.5 | G20: =(H3*H20)/(G3) -> 87.692308 | H20: =(I3*I20)/(H3) -> 90 | I20: =(J3*J20)/(I3) -> 92.432432 | ... O20: =(P3*P20)/(O3) -> 110.32258 | P20: 114 | Q20: =(P3*P20)/(Q3) -> 117.93103 | R20: =(Q3*Q20)/(R3) -> 122.14286 | S20: =(R3*R20)/(S3) -> 126.66667 | T20: =(S3*S20)/(T3) -> 131.53846 | U20: =(T3*T20)/(U3) -> 136.8 | V20: =(U3*U20)/(V3) -> 142.5 | W20: =(V3*V20)/(W3) -> 148.69565 | X20: =(W3*W20)/(X3) -> 155.45455 | ... AJ20: =(AI3*AI20)/(AJ3) -> 342
A21: 28 cm | B21: =(C3*C21)/(B3) -> 35.4 | C21: =(D3*D21)/(C3) -> 44.25 | D21: =(E3*E21)/(D3) -> 59 | E21: =(F3*F21)/(E3) -> 70.8 | F21: =(G3*G21)/(F3) -> 88.5 | G21: =(H3*H21)/(G3) -> 90.769231 | H21: =(I3*I21)/(H3) -> 93.157895 | I21: =(J3*J21)/(I3) -> 95.675676 | ... O21: =(P3*P21)/(O3) -> 114.19355 | P21: 118 | Q21: =(P3*P21)/(Q3) -> 122.06897 | R21: =(Q3*Q21)/(R3) -> 126.42857 | S21: =(R3*R21)/(S3) -> 131.11111 | T21: =(S3*S21)/(T3) -> 136.15385 | U21: =(T3*T21)/(U3) -> 141.6 | V21: =(U3*U21)/(V3) -> 147.5 | W21: =(V3*V21)/(W3) -> 153.91304 | X21: =(W3*W21)/(X3) -> 160.90909 | ... AJ21: =(AI3*AI21)/(AJ3) -> 354
A22: 27 cm | B22: =(C3*C22)/(B3) -> 36.9 | C22: =(D3*D22)/(C3) -> 46.125 | D22: =(E3*E22)/(D3) -> 61.5 | E22: =(F3*F22)/(E3) -> 73.8 | F22: =(G3*G22)/(F3) -> 92.25 | G22: =(H3*H22)/(G3) -> 94.615385 | H22: =(I3*I22)/(H3) -> 97.105263 | I22: =(J3*J22)/(I3) -> 99.72973 | ... O22: =(P3*P22)/(O3) -> 119.03226 | P22: 123 | Q22: =(P3*P22)/(Q3) -> 127.24138 | R22: =(Q3*Q22)/(R3) -> 131.78571 | S22: =(R3*R22)/(S3) -> 136.66667 | T22: =(S3*S22)/(T3) -> 141.92308 | U22: =(T3*T22)/(U3) -> 147.6 | V22: =(U3*U22)/(V3) -> 153.75 | W22: =(V3*V22)/(W3) -> 160.43478 | X22: =(W3*W22)/(X3) -> 167.72727 | ... AJ22: =(AI3*AI22)/(AJ3) -> 369
A23: 26 cm | B23: =(C3*C23)/(B3) -> 38.1 | C23: =(D3*D23)/(C3) -> 47.625 | D23: =(E3*E23)/(D3) -> 63.5 | E23: =(F3*F23)/(E3) -> 76.2 | F23: =(G3*G23)/(F3) -> 95.25 | G23: =(H3*H23)/(G3) -> 97.692308 | H23: =(I3*I23)/(H3) -> 100.26316 | I23: =(J3*J23)/(I3) -> 102.97297 | ... O23: =(P3*P23)/(O3) -> 122.90323 | P23: 127 | Q23: =(P3*P23)/(Q3) -> 131.37931 | R23: =(Q3*Q23)/(R3) -> 136.07143 | S23: =(R3*R23)/(S3) -> 141.11111 | T23: =(S3*S23)/(T3) -> 146.53846 | U23: =(T3*T23)/(U3) -> 152.4 | V23: =(U3*U23)/(V3) -> 158.75 | W23: =(V3*V23)/(W3) -> 165.65217 | X23: =(W3*W23)/(X3) -> 173.18182 | ... AJ23: =(AI3*AI23)/(AJ3) -> 381
A24: 25 cm | B24: =(C3*C24)/(B3) -> 39.6 | C24: =(D3*D24)/(C3) -> 49.5 | D24: =(E3*E24)/(D3) -> 66 | E24: =(F3*F24)/(E3) -> 79.2 | F24: =(G3*G24)/(F3) -> 99 | G24: =(H3*H24)/(G3) -> 101.53846 | H24: =(I3*I24)/(H3) -> 104.21053 | I24: =(J3*J24)/(I3) -> 107.02703 | ... O24: =(P3*P24)/(O3) -> 127.74194 | P24: 132 | Q24: =(P3*P24)/(Q3) -> 136.55172 | R24: =(Q3*Q24)/(R3) -> 141.42857 | S24: =(R3*R24)/(S3) -> 146.66667 | T24: =(S3*S24)/(T3) -> 152.30769 | U24: =(T3*T24)/(U3) -> 158.4 | V24: =(U3*U24)/(V3) -> 165 | W24: =(V3*V24)/(W3) -> 172.17391 | X24: =(W3*W24)/(X3) -> 180 | ... AJ24: =(AI3*AI24)/(AJ3) -> 396
A25: 24 cm | B25: =(C3*C25)/(B3) -> 41.4 | C25: =(D3*D25)/(C3) -> 51.75 | D25: =(E3*E25)/(D3) -> 69 | E25: =(F3*F25)/(E3) -> 82.8 | F25: =(G3*G25)/(F3) -> 103.5 | G25: =(H3*H25)/(G3) -> 106.15385 | H25: =(I3*I25)/(H3) -> 108.94737 | I25: =(J3*J25)/(I3) -> 111.89189 | ... O25: =(P3*P25)/(O3) -> 133.54839 | P25: 138 | Q25: =(P3*P25)/(Q3) -> 142.75862 | R25: =(Q3*Q25)/(R3) -> 147.85714 | S25: =(R3*R25)/(S3) -> 153.33333 | T25: =(S3*S25)/(T3) -> 159.23077 | U25: =(T3*T25)/(U3) -> 165.6 | V25: =(U3*U25)/(V3) -> 172.5 | W25: =(V3*V25)/(W3) -> 180 | X25: =(W3*W25)/(X3) -> 188.18182 | ... AJ25: =(AI3*AI25)/(AJ3) -> 414
A26: 23 cm | B26: =(C3*C26)/(B3) -> 43.2 | C26: =(D3*D26)/(C3) -> 54 | D26: =(E3*E26)/(D3) -> 72 | E26: =(F3*F26)/(E3) -> 86.4 | F26: =(G3*G26)/(F3) -> 108 | G26: =(H3*H26)/(G3) -> 110.76923 | H26: =(I3*I26)/(H3) -> 113.68421 | I26: =(J3*J26)/(I3) -> 116.75676 | ... O26: =(P3*P26)/(O3) -> 139.35484 | P26: 144 | Q26: =(P3*P26)/(Q3) -> 148.96552 | R26: =(Q3*Q26)/(R3) -> 154.28571 | S26: =(R3*R26)/(S3) -> 160 | T26: =(S3*S26)/(T3) -> 166.15385 | U26: =(T3*T26)/(U3) -> 172.8 | V26: =(U3*U26)/(V3) -> 180 | W26: =(V3*V26)/(W3) -> 187.82609 | X26: =(W3*W26)/(X3) -> 196.36364 | ... AJ26: =(AI3*AI26)/(AJ3) -> 432
A27: 22 cm | B27: =(C3*C27)/(B3) -> 45.3 | C27: =(D3*D27)/(C3) -> 56.625 | D27: =(E3*E27)/(D3) -> 75.5 | E27: =(F3*F27)/(E3) -> 90.6 | F27: =(G3*G27)/(F3) -> 113.25 | G27: =(H3*H27)/(G3) -> 116.15385 | H27: =(I3*I27)/(H3) -> 119.21053 | I27: =(J3*J27)/(I3) -> 122.43243 | ... O27: =(P3*P27)/(O3) -> 146.12903 | P27: 151 | Q27: =(P3*P27)/(Q3) -> 156.2069 | R27: =(Q3*Q27)/(R3) -> 161.78571 | S27: =(R3*R27)/(S3) -> 167.77778 | T27: =(S3*S27)/(T3) -> 174.23077 | U27: =(T3*T27)/(U3) -> 181.2 | V27: =(U3*U27)/(V3) -> 188.75 | W27: =(V3*V27)/(W3) -> 196.95652 | X27: =(W3*W27)/(X3) -> 205.90909 | ... AJ27: =(AI3*AI27)/(AJ3) -> 453
A28: 21 cm | B28: =(C3*C28)/(B3) -> 47.4 | C28: =(D3*D28)/(C3) -> 59.25 | D28: =(E3*E28)/(D3) -> 79 | E28: =(F3*F28)/(E3) -> 94.8 | F28: =(G3*G28)/(F3) -> 118.5 | G28: =(H3*H28)/(G3) -> 121.53846 | H28: =(I3*I28)/(H3) -> 124.73684 | I28: =(J3*J28)/(I3) -> 128.10811 | ... O28: =(P3*P28)/(O3) -> 152.90323 | P28: 158 | Q28: =(P3*P28)/(Q3) -> 163.44828 | R28: =(Q3*Q28)/(R3) -> 169.28571 | S28: =(R3*R28)/(S3) -> 175.55556 | T28: =(S3*S28)/(T3) -> 182.30769 | U28: =(T3*T28)/(U3) -> 189.6 | V28: =(U3*U28)/(V3) -> 197.5 | W28: =(V3*V28)/(W3) -> 206.08696 | X28: =(W3*W28)/(X3) -> 215.45455 | ... AJ28: =(AI3*AI28)/(AJ3) -> 474
A29: 20 cm | B29: =(C3*C29)/(B3) -> 49.8 | C29: =(D3*D29)/(C3) -> 62.25 | D29: =(E3*E29)/(D3) -> 83 | E29: =(F3*F29)/(E3) -> 99.6 | F29: =(G3*G29)/(F3) -> 124.5 | G29: =(H3*H29)/(G3) -> 127.69231 | H29: =(I3*I29)/(H3) -> 131.05263 | I29: =(J3*J29)/(I3) -> 134.59459 | ... O29: =(P3*P29)/(O3) -> 160.64516 | P29: 166 | Q29: =(P3*P29)/(Q3) -> 171.72414 | R29: =(Q3*Q29)/(R3) -> 177.85714 | S29: =(R3*R29)/(S3) -> 184.44444 | T29: =(S3*S29)/(T3) -> 191.53846 | U29: =(T3*T29)/(U3) -> 199.2 | V29: =(U3*U29)/(V3) -> 207.5 | W29: =(V3*V29)/(W3) -> 216.52174 | X29: =(W3*W29)/(X3) -> 226.36364 | ... AJ29: =(AI3*AI29)/(AJ3) -> 498
A30: 19 cm | B30: =(C3*C30)/(B3) -> 52.2 | C30: =(D3*D30)/(C3) -> 65.25 | D30: =(E3*E30)/(D3) -> 87 | E30: =(F3*F30)/(E3) -> 104.4 | F30: =(G3*G30)/(F3) -> 130.5 | G30: =(H3*H30)/(G3) -> 133.84615 | H30: =(I3*I30)/(H3) -> 137.36842 | I30: =(J3*J30)/(I3) -> 141.08108 | ... O30: =(P3*P30)/(O3) -> 168.3871 | P30: 174 | Q30: =(P3*P30)/(Q3) -> 180 | R30: =(Q3*Q30)/(R3) -> 186.42857 | S30: =(R3*R30)/(S3) -> 193.33333 | T30: =(S3*S30)/(T3) -> 200.76923 | U30: =(T3*T30)/(U3) -> 208.8 | V30: =(U3*U30)/(V3) -> 217.5 | W30: =(V3*V30)/(W3) -> 226.95652 | X30: =(W3*W30)/(X3) -> 237.27273 | ... AJ30: =(AI3*AI30)/(AJ3) -> 522
A31: 18 cm | B31: =(C3*C31)/(B3) -> 55.2 | C31: =(D3*D31)/(C3) -> 69 | D31: =(E3*E31)/(D3) -> 92 | E31: =(F3*F31)/(E3) -> 110.4 | F31: =(G3*G31)/(F3) -> 138 | G31: =(H3*H31)/(G3) -> 141.53846 | H31: =(I3*I31)/(H3) -> 145.26316 | I31: =(J3*J31)/(I3) -> 149.18919 | ... O31: =(P3*P31)/(O3) -> 178.06452 | P31: 184 | Q31: =(P3*P31)/(Q3) -> 190.34483 | R31: =(Q3*Q31)/(R3) -> 197.14286 | S31: =(R3*R31)/(S3) -> 204.44444 | T31: =(S3*S31)/(T3) -> 212.30769 | U31: =(T3*T31)/(U3) -> 220.8 | V31: =(U3*U31)/(V3) -> 230 | W31: =(V3*V31)/(W3) -> 240 | X31: =(W3*W31)/(X3) -> 250.90909 | ... AJ31: =(AI3*AI31)/(AJ3) -> 552
A32: 17 cm | B32: =(C3*C32)/(B3) -> 58.5 | C32: =(D3*D32)/(C3) -> 73.125 | D32: =(E3*E32)/(D3) -> 97.5 | E32: =(F3*F32)/(E3) -> 117 | F32: =(G3*G32)/(F3) -> 146.25 | G32: =(H3*H32)/(G3) -> 150 | H32: =(I3*I32)/(H3) -> 153.94737 | I32: =(J3*J32)/(I3) -> 158.10811 | ... O32: =(P3*P32)/(O3) -> 188.70968 | P32: 195 | Q32: =(P3*P32)/(Q3) -> 201.72414 | R32: =(Q3*Q32)/(R3) -> 208.92857 | S32: =(R3*R32)/(S3) -> 216.66667 | T32: =(S3*S32)/(T3) -> 225 | U32: =(T3*T32)/(U3) -> 234 | V32: =(U3*U32)/(V3) -> 243.75 | W32: =(V3*V32)/(W3) -> 254.34783 | X32: =(W3*W32)/(X3) -> 265.90909 | ... AJ32: =(AI3*AI32)/(AJ3) -> 585
A33: 16 cm | B33: =(C3*C33)/(B3) -> 62.1 | C33: =(D3*D33)/(C3) -> 77.625 | D33: =(E3*E33)/(D3) -> 103.5 | E33: =(F3*F33)/(E3) -> 124.2 | F33: =(G3*G33)/(F3) -> 155.25 | G33: =(H3*H33)/(G3) -> 159.23077 | H33: =(I3*I33)/(H3) -> 163.42105 | I33: =(J3*J33)/(I3) -> 167.83784 | ... O33: =(P3*P33)/(O3) -> 200.32258 | P33: 207 | Q33: =(P3*P33)/(Q3) -> 214.13793 | R33: =(Q3*Q33)/(R3) -> 221.78571 | S33: =(R3*R33)/(S3) -> 230 | T33: =(S3*S33)/(T3) -> 238.84615 | U33: =(T3*T33)/(U3) -> 248.4 | V33: =(U3*U33)/(V3) -> 258.75 | W33: =(V3*V33)/(W3) -> 270 | X33: =(W3*W33)/(X3) -> 282.27273 | ... AJ33: =(AI3*AI33)/(AJ3) -> 621
A34: 15 cm | B34: =(C3*C34)/(B3) -> 66.3 | C34: =(D3*D34)/(C3) -> 82.875 | D34: =(E3*E34)/(D3) -> 110.5 | E34: =(F3*F34)/(E3) -> 132.6 | F34: =(G3*G34)/(F3) -> 165.75 | G34: =(H3*H34)/(G3) -> 170 | H34: =(I3*I34)/(H3) -> 174.47368 | I34: =(J3*J34)/(I3) -> 179.18919 | ... O34: =(P3*P34)/(O3) -> 213.87097 | P34: 221 | Q34: =(P3*P34)/(Q3) -> 228.62069 | R34: =(Q3*Q34)/(R3) -> 236.78571 | S34: =(R3*R34)/(S3) -> 245.55556 | T34: =(S3*S34)/(T3) -> 255 | U34: =(T3*T34)/(U3) -> 265.2 | V34: =(U3*U34)/(V3) -> 276.25 | W34: =(V3*V34)/(W3) -> 288.26087 | X34: =(W3*W34)/(X3) -> 301.36364 | ... AJ34: =(AI3*AI34)/(AJ3) -> 663
C35: NOT:Çizelgede belirtilen iplik uzunluklarına;Orta renklerde 2mm,Koyu renklerde 4mm daha ilave ekle (hesaplama 18 fayna göre yapılmıştır)
A37: 50 iğne | B37: 1x1 iğne boşaltmalı çift katlı DÜZ RİBANA; 100 MAYDAKİ İPLİK UZUNLUKLARINA GÖRE ORTALAMA MAMÜL GRAMAJLARI
A38: 17 | B38: İPLİK NUMARALARI
A39: FAYN | B39: 100 | C39: 80 | D39: 60 | E39: 50 | F39: 40 | G39: 39 | H39: 38 | I39: 37 | J39: 36 | K39: 35 | L39: 34 | M39: 33 | N39: 32 | O39: 31 | P39: 30 | Q39: 29 | R39: 28 | S39: 27 | T39: 26 | U39: 25 | V39: 24 | W39: 23 | X39: 22 | Y39: 21 | Z39: 20 | AA39: 19 | AB39: 18 | AC39: 17 | AD39: 16 | AE39: 15 | AF39: 14 | AG39: 13 | AH39: 12 | AI39: 11 | AJ39: 10
A40: 45 cm | B40: =(C39*C40)/(B39) -> 21.3 | C40: =(D39*D40)/(C39) -> 26.625 | D40: =(E39*E40)/(D39) -> 35.5 | E40: =(F39*F40)/(E39) -> 42.6 | F40: =(G39*G40)/(F39) -> 53.25 | G40: =(H39*H40)/(G39) -> 54.615385 | H40: =(I39*I40)/(H39) -> 56.052632 | I40: =(J39*J40)/(I39) -> 57.567568 | ... O40: =(P39*P40)/(O39) -> 68.709677 | P40: 71 | Q40: =(P39*P40)/(Q39) -> 73.448276 | R40: =(Q39*Q40)/(R39) -> 76.071429 | S40: =(R39*R40)/(S39) -> 78.888889 | T40: =(S39*S40)/(T39) -> 81.923077 | U40: =(T39*T40)/(U39) -> 85.2 | V40: =(U39*U40)/(V39) -> 88.75 | W40: =(V39*V40)/(W39) -> 92.608696 | X40: =(W39*W40)/(X39) -> 96.818182 | ... AJ40: =(AI39*AI40)/(AJ39) -> 213
A41: 44 cm | B41: =(C39*C41)/(B39) -> 21.9 | C41: =(D39*D41)/(C39) -> 27.375 | D41: =(E39*E41)/(D39) -> 36.5 | E41: =(F39*F41)/(E39) -> 43.8 | F41: =(G39*G41)/(F39) -> 54.75 | G41: =(H39*H41)/(G39) -> 56.153846 | H41: =(I39*I41)/(H39) -> 57.631579 | I41: =(J39*J41)/(I39) -> 59.189189 | ... O41: =(P39*P41)/(O39) -> 70.645161 | P41: 73 | Q41: =(P39*P41)/(Q39) -> 75.517241 | R41: =(Q39*Q41)/(R39) -> 78.214286 | S41: =(R39*R41)/(S39) -> 81.111111 | T41: =(S39*S41)/(T39) -> 84.230769 | U41: =(T39*T41)/(U39) -> 87.6 | V41: =(U39*U41)/(V39) -> 91.25 | W41: =(V39*V41)/(W39) -> 95.217391 | X41: =(W39*W41)/(X39) -> 99.545455 | ... AJ41: =(AI39*AI41)/(AJ39) -> 219
...

Sheet FULL LYC RİBANA GRAMAJLARI
B1: 20 DENYE FULL LYCRALI RİBANA; 100 MAYDAKİ İPLİK UZUNLUKLARINA GÖRE ORTALAMA MAMÜL GRAMAJLARI (tam dolu iğneli )
A2: 20 | B2: İPLİK NUMARALARI
A3: DENYELİ | B3: 100 | C3: 80 | D3: 60 | E3: 50 | F3: 40 | G3: 39 | H3: 38 | I3: 37 | J3: 36 | K3: 35 | L3: 34 | M3: 33 | N3: 32 | O3: 31 | P3: 30 | Q3: 29 | R3: 28 | S3: 27 | T3: 26 | U3: 25 | V3: 24 | W3: 23 | X3: 22 | Y3: 21 | Z3: 20 | AA3: 19 | AB3: 18 | AC3: 17 | AD3: 16 | AE3: 15 | AF3: 14 | AG3: 13 | AH3: 12 | AI3: 11 | AJ3: 10
A4: 45 cm | B4: =(C3*C4)/(B3) -> 54 | C4: =(D3*D4)/(C3) -> 67.5 | D4: =(E3*E4)/(D3) -> 90 | E4: =(F3*F4)/(E3) -> 108 | F4: =(G3*G4)/(F3) -> 135 | G4: =(H3*H4)/(G3) -> 138.46154 | H4: =(I3*I4)/(H3) -> 142.10526 | I4: =(J3*J4)/(I3) -> 145.94595 | ... O4: =(P3*P4)/(O3) -> 174.19355 | P4: 180 | Q4: =(P3*P4)/(Q3) -> 186.2069 | R4: =(Q3*Q4)/(R3) -> 192.85714 | S4: =(R3*R4)/(S3) -> 200 | T4: =(S3*S4)/(T3) -> 207.69231 | U4: =(T3*T4)/(U3) -> 216 | V4: =(U3*U4)/(V3) -> 225 | W4: =(V3*V4)/(W3) -> 234.78261 | X4: =(W3*W4)/(X3) -> 245.45455 | ... AJ4: =(AI3*AI4)/(AJ3) -> 540
A5: 44 cm | B5: =(C3*C5)/(B3) -> 55.5 | C5: =(D3*D5)/(C3) -> 69.375 | D5: =(E3*E5)/(D3) -> 92.5 | E5: =(F3*F5)/(E3) -> 111 | F5: =(G3*G5)/(F3) -> 138.75 | G5: =(H3*H5)/(G3) -> 142.30769 | H5: =(I3*I5)/(H3) -> 146.05263 | I5: =(J3*J5)/(I3) -> 150 | ... O5: =(P3*P5)/(O3) -> 179.03226 | P5: 185 | Q5: =(P3*P5)/(Q3) -> 191.37931 | R5: =(Q3*Q5)/(R3) -> 198.21429 | S5: =(R3*R5)/(S3) -> 205.55556 | T5: =(S3*S5)/(T3) -> 213.46154 | U5: =(T3*T5)/(U3) -> 222 | V5: =(U3*U5)/(V3) -> 231.25 | W5: =(V3*V5)/(W3) -> 241.30435 | X5: =(W3*W5)/(X3) -> 252.27273 | ... AJ5: =(AI3*AI5)/(AJ3) -> 555
A6: 43 cm | B6: =(C3*C6)/(B3) -> 56.7 | C6: =(D3*D6)/(C3) -> 70.875 | D6: =(E3*E6)/(D3) -> 94.5 | E6: =(F3*F6)/(E3) -> 113.4 | F6: =(G3*G6)/(F3) -> 141.75 | G6: =(H3*H6)/(G3) -> 145.38462 | H6: =(I3*I6)/(H3) -> 149.21053 | I6: =(J3*J6)/(I3) -> 153.24324 | ... O6: =(P3*P6)/(O3) -> 182.90323 | P6: 189 | Q6: =(P3*P6)/(Q3) -> 195.51724 | R6: =(Q3*Q6)/(R3) -> 202.5 | S6: =(R3*R6)/(S3) -> 210 | T6: =(S3*S6)/(T3) -> 218.07692 | U6: =(T3*T6)/(U3) -> 226.8 | V6: =(U3*U6)/(V3) -> 236.25 | W6: =(V3*V6)/(W3) -> 246.52174 | X6: =(W3*W6)/(X3) -> 257.72727 | ... AJ6: =(AI3*AI6)/(AJ3) -> 567
A7: 42 cm | B7: =(C3*C7)/(B3) -> 57.9 | C7: =(D3*D7)/(C3) -> 72.375 | D7: =(E3*E7)/(D3) -> 96.5 | E7: =(F3*F7)/(E3) -> 115.8 | F7: =(G3*G7)/(F3) -> 144.75 | G7: =(H3*H7)/(G3) -> 148.46154 | H7: =(I3*I7)/(H3) -> 152.36842 | I7: =(J3*J7)/(I3) -> 156.48649 | ... O7: =(P3*P7)/(O3) -> 186.77419 | P7: 193 | Q7: =(P3*P7)/(Q3) -> 199.65517 | R7: =(Q3*Q7)/(R3) -> 206.78571 | S7: =(R3*R7)/(S3) -> 214.44444 | T7: =(S3*S7)/(T3) -> 222.69231 | U7: =(T3*T7)/(U3) -> 231.6 | V7: =(U3*U7)/(V3) -> 241.25 | W7: =(V3*V7)/(W3) -> 251.73913 | X7: =(W3*W7)/(X3) -> 263.18182 | ... AJ7: =(AI3*AI7)/(AJ3) -> 579
A8: 41 cm | B8: =(C3*C8)/(B3) -> 59.4 | C8: =(D3*D8)/(C3) -> 74.25 | D8: =(E3*E8)/(D3) -> 99 | E8: =(F3*F8)/(E3) -> 118.8 | F8: =(G3*G8)/(F3) -> 148.5 | G8: =(H3*H8)/(G3) -> 152.30769 | H8: =(I3*I8)/(H3) -> 156.31579 | I8: =(J3*J8)/(I3) -> 160.54054 | ... O8: =(P3*P8)/(O3) -> 191.6129 | P8: 198 | Q8: =(P3*P8)/(Q3) -> 204.82759 | R8: =(Q3*Q8)/(R3) -> 212.14286 | S8: =(R3*R8)/(S3) -> 220 | T8: =(S3*S8)/(T3) -> 228.46154 | U8: =(T3*T8)/(U3) -> 237.6 | V8: =(U3*U8)/(V3) -> 247.5 | W8: =(V3*V8)/(W3) -> 258.26087 | X8: =(W3*W8)/(X3) -> 270 | ... AJ8: =(AI3*AI8)/(AJ3) -> 594
A9: 40 cm | B9: =(C3*C9)/(B3) -> 60.9 | C9: =(D3*D9)/(C3) -> 76.125 | D9: =(E3*E9)/(D3) -> 101.5 | E9: =(F3*F9)/(E3) -> 121.8 | F9: =(G3*G9)/(F3) -> 152.25 | G9: =(H3*H9)/(G3) -> 156.15385 | H9: =(I3*I9)/(H3) -> 160.26316 | I9: =(J3*J9)/(I3) -> 164.59459 | ... O9: =(P3*P9)/(O3) -> 196.45161 | P9: 203 | Q9: =(P3*P9)/(Q3) -> 210 | R9: =(Q3*Q9)/(R3) -> 217.5 | S9: =(R3*R9)/(S3) -> 225.55556 | T9: =(S3*S9)/(T3) -> 234.23077 | U9: =(T3*T9)/(U3) -> 243.6 | V9: =(U3*U9)/(V3) -> 253.75 | W9: =(V3*V9)/(W3) -> 264.78261 | X9: =(W3*W9)/(X3) -> 276.81818 | ... AJ9: =(AI3*AI9)/(AJ3) -> 609
