Workbook

Sheet 28 FAYN FULL LYC SÜPREM GRAMAJ
B1: 20 DENYE FULL LYCRALI SÜPREMLERİN GRAMAJLARINA GÖRE 100 MAYDAKİ ORTALAMA İPLİK UZUNLUKLARI
A2: 20 | B2: İPLİK NUMARALARI
A3: DENYELİ | B3: 100 | C3: 80 | D3: 60 | E3: 50 | F3: 40 | G3: 39 | H3: 38 | I3: 37 | J3: 36 | K3: 35 | L3: 34 | M3: 33 | N3: 32 | O3: 31 | P3: 30 | Q3: 29 | R3: 28 | S3: 27 | T3: 26 | U3: 25 | V3: 24 | W3: 23 | X3: 22 | Y3: 21 | Z3: 20 | AA3: 19 | AB3: 18 | AC3: 17 | AD3: 16 | AE3: 15 | AF3: 14 | AG3: 13 | AH3: 12 | AI3: 11 | AJ3: 10
A4: 45 cm | B4: =(C3*C4)/(B3) -> 43.8 | C4: =(D3*D4)/(C3) -> 54.75 | D4: =(E3*E4)/(D3) -> 73 | E4: =(F3*F4)/(E3) -> 87.6 | F4: =(G3*G4)/(F3) -> 109.5 | G4: =(H3*H4)/(G3) -> 112.30769 | H4: =(I3*I4)/(H3) -> 115.26316 | I4: =(J3*J4)/(I3) -> 118.37838 | ... O4: =(P3*P4)/(O3) -> 141.29032 | P4: 146 | Q4: =(P3*P4)/(Q3) -> 151.03448 | R4: =(Q3*Q4)/(R3) -> 156.42857 | S4: =(R3*R4)/(S3) -> 162.22222 | T4: =(S3*S4)/(T3) -> 168.46154 | U4: =(T3*T4)/(U3) -> 175.2 | V4: =(U3*U4)/(V3) -> 182.5 | W4: =(V3*V4)/(W3) -> 190.43478 | X4: =(W3*W4)/(X3) -> 199.09091 | ... AJ4: =(AI3*AI4)/(AJ3) -> 438
A5: 44 cm | B5: =(C3*C5)/(B3) -> 44.7 | C5: =(D3*D5)/(C3) -> 55.875 | D5: =(E3*E5)/(D3) -> 74.5 | E5: =(F3*F5)/(E3) -> 89.4 | F5: =(G3*G5)/(F3) -> 111.75 | G5: =(H3*H5)/(G3) -> 114.61538 | H5: =(I3*I5)/(H3) -> 117.63158 | I5: =(J3*J5)/(I3) -> 120.81081 | ... O5: =(P3*P5)/(O3) -> 144.19355 | P5: 149 | Q5: =(P3*P5)/(Q3) -> 154.13793 | R5: =(Q3*Q5)/(R3) -> 159.64286 | S5: =(R3*R5)/(S3) -> 165.55556 | T5: =(S3*S5)/(T3) -> 171.92308 | U5: =(T3*T5)/(U3) -> 178.8 | V5: =(U3*U5)/(V3) -> 186.25 | W5: =(V3*V5)/(W3) -> 194.34783 | X5: =(W3*W5)/(X3) -> 203.18182 | ... AJ5: =(AI3*AI5)/(AJ3) -> 447
A6: 43 cm | B6: =(C3*C6)/(B3) -> 45.9 | C6: =(D3*D6)/(C3) -> 57.375 | D6: =(E3*E6)/(D3) -> 76.5 | E6: =(F3*F6)/(E3) -> 91.8 | F6: =(G3*G6)/(F3) -> 114.75 | G6: =(H3*H6)/(G3) -> 117.69231 | H6: =(I3*I6)/(H3) -> 120.78947 | I6: =(J3*J6)/(I3) -> 124.05405 | ... O6: =(P3*P6)/(O3) -> 148.06452 | P6: 153 | Q6: =(P3*P6)/(Q3) -> 158.27586 | R6: =(Q3*Q6)/(R3) -> 163.92857 | S6: =(R3*R6)/(S3) -> 170 | T6: =(S3*S6)/(T3) -> 176.53846 | U6: =(T3*T6)/(U3) -> 183.6 | V6: =(U3*U6)/(V3) -> 191.25 | W6: =(V3*V6)/(W3) -> 199.56522 | X6: =(W3*W6)/(X3) -> 208.63636 | ... AJ6: =(AI3*AI6)/(AJ3) -> 459
A7: 42 cm | B7: =(C3*C7)/(B3) -> 47.7 | C7: =(D3*D7)/(C3) -> 59.625 | D7: =(E3*E7)/(D3) -> 79.5 | E7: =(F3*F7)/(E3) -> 95.4 | F7: =(G3*G7)/(F3) -> 119.25 | G7: =(H3*H7)/(G3) -> 122.30769 | H7: =(I3*I7)/(H3) -> 125.52632 | I7: =(J3*J7)/(I3) -> 128.91892 | ... O7: =(P3*P7)/(O3) -> 153.87097 | P7: 159 | Q7: =(P3*P7)/(Q3) -> 164.48276 | R7: =(Q3*Q7)/(R3) -> 170.35714 | S7: =(R3*R7)/(S3) -> 176.66667 | T7: =(S3*S7)/(T3) -> 183.46154 | U7: =(T3*T7)/(U3) -> 190.8 | V7: =(U3*U7)/(V3) -> 198.75 | W7: =(V3*V7)/(W3) -> 207.3913 | X7: =(W3*W7)/(X3) -> 216.81818 | ... AJ7: =(AI3*AI7)/(AJ3) -> 477
A8: 41 cm | B8: =(C3*C8)/(B3) -> 48 | C8: =(D3*D8)/(C3) -> 60 | D8: =(E3*E8)/(D3) -> 80 | E8: =(F3*F8)/(E3) -> 96 | F8: =(G3*G8)/(F3) -> 120 | G8: =(H3*H8)/(G3) -> 123.07692 | H8: =(I3*I8)/(H3) -> 126.31579 | I8: =(J3*J8)/(I3) -> 129.72973 | ... O8: =(P3*P8)/(O3) -> 154.83871 | P8: 160 | Q8: =(P3*P8)/(Q3) -> 165.51724 | R8: =(Q3*Q8)/(R3) -> 171.42857 | S8: =(R3*R8)/(S3) -> 177.77778 | T8: =(S3*S8)/(T3) -> 184.61538 | U8: =(T3*T8)/(U3) -> 192 | V8: =(U3*U8)/(V3) -> 200 | W8: =(V3*V8)/(W3) -> 208.69565 | X8: =(W3*W8)/(X3) -> 218.18182 | ... AJ8: =(AI3*AI8)/(AJ3) -> 480
A9: 40 cm | B9: =(C3*C9)/(B3) -> 49.2 | C9: =(D3*D9)/(C3) -> 61.5 | D9: =(E3*E9)/(D3) -> 82 | E9: =(F3*F9)/(E3) -> 98.4 | F9: =(G3*G9)/(F3) -> 123 | G9: =(H3*H9)/(G3) -> 126.15385 | H9: =(I3*I9)/(H3) -> 129.47368 | I9: =(J3*J9)/(I3) -> 132.97297 | ... O9: =(P3*P9)/(O3) -> 158.70968 | P9: 164 | Q9: =(P3*P9)/(Q3) -> 169.65517 | R9: =(Q3*Q9)/(R3) -> 175.71429 | S9: =(R3*R9)/(S3) -> 182.22222 | T9: =(S3*S9)/(T3) -> 189.23077 | U9: =(T3*T9)/(U3) -> 196.8 | V9: =(U3*U9)/(V3) -> 205 | W9: =(V3*V9)/(W3) -> 213.91304 | X9: =(W3*W9)/(X3) -> 223.63636 | ... AJ9: =(AI3*AI9)/(AJ3) -> 492
A10: 39 cm | B10: =(C3*C10)/(B3) -> 50.4 | C10: =(D3*D10)/(C3) -> 63 | D10: =(E3*E10)/(D3) -> 84 | E10: =(F3*F10)/(E3) -> 100.8 | F10: =(G3*G10)/(F3) -> 126 | G10: =(H3*H10)/(G3) -> 129.23077 | H10: =(I3*I10)/(H3) -> 132.63158 | I10: =(J3*J10)/(I3) -> 136.21622 | ... O10: =(P3*P10)/(O3) -> 162.58065 | P10: 168 | Q10: =(P3*P10)/(Q3) -> 173.7931 | R10: =(Q3*Q10)/(R3) -> 180 | S10: =(R3*R10)/(S3) -> 186.66667 | T10: =(S3*S10)/(T3) -> 193.84615 | U10: =(T3*T10)/(U3) -> 201.6 | V10: =(U3*U10)/(V3) -> 210 | W10: =(V3*V10)/(W3) -> 219.13043 | X10: =(W3*W10)/(X3) -> 229.09091 | ... AJ10: =(AI3*AI10)/(AJ3) -> 504
A11: 38 cm | B11: =(C3*C11)/(B3) -> 51.9 | C11: =(D3*D11)/(C3) -> 64.875 | D11: =(E3*E11)/(D3) -> 86.5 | E11: =(F3*F11)/(E3) -> 103.8 | F11: =(G3*G11)/(F3) -> 129.75 | G11: =(H3*H11)/(G3) -> 133.07692 | H11: =(I3*I11)/(H3) -> 136.57895 | I11: =(J3*J11)/(I3) -> 140.27027 | ... O11: =(P3*P11)/(O3) -> 167.41935 | P11: 173 | Q11: =(P3*P11)/(Q3) -> 178.96552 | R11: =(Q3*Q11)/(R3) -> 185.35714 | S11: =(R3*R11)/(S3) -> 192.22222 | T11: =(S3*S11)/(T3) -> 199.61538 | U11: =(T3*T11)/(U3) -> 207.6 | V11: =(U3*U11)/(V3) -> 216.25 | W11: =(V3*V11)/(W3) -> 225.65217 | X11: =(W3*W11)/(X3) -> 235.90909 | ... AJ11: =(AI3*AI11)/(AJ3) -> 519
A12: 37 cm | B12: =(C3*C12)/(B3) -> 53.1 | C12: =(D3*D12)/(C3) -> 66.375 | D12: =(E3*E12)/(D3) -> 88.5 | E12: =(F3*F12)/(E3) -> 106.2 | F12: =(G3*G12)/(F3) -> 132.75 | G12: =(H3*H12)/(G3) -> 136.15385 | H12: =(I3*I12)/(H3) -> 139.73684 | I12: =(J3*J12)/(I3) -> 143.51351 | ... O12: =(P3*P12)/(O3) -> 171.29032 | P12: 177 | Q12: =(P3*P12)/(Q3) -> 183.10345 | R12: =(Q3*Q12)/(R3) -> 189.64286 | S12: =(R3*R12)/(S3) -> 196.66667 | T12: =(S3*S12)/(T3) -> 204.23077 | U12: =(T3*T12)/(U3) -> 212.4 | V12: =(U3*U12)/(V3) -> 221.25 | W12: =(V3*V12)/(W3) -> 230.86957 | X12: =(W3*W12)/(X3) -> 241.36364 | ... AJ12: =(AI3*AI12)/(AJ3) -> 531
A13: 36 cm | B13: =(C3*C13)/(B3) -> 54.6 | C13: =(D3*D13)/(C3) -> 68.25 | D13: =(E3*E13)/(D3) -> 91 | E13: =(F3*F13)/(E3) -> 109.2 | F13: =(G3*G13)/(F3) -> 136.5 | G13: =(H3*H13)/(G3) -> 140 | H13: =(I3*I13)/(H3) -> 143.68421 | I13: =(J3*J13)/(I3) -> 147.56757 | ... O13: =(P3*P13)/(O3) -> 176.12903 | P13: 182 | Q13: =(P3*P13)/(Q3) -> 188.27586 | R13: =(Q3*Q13)/(R3) -> 195 | S13: =(R3*R13)/(S3) -> 202.22222 | T13: =(S3*S13)/(T3) -> 210 | U13: =(T3*T13)/(U3) -> 218.4 | V13: =(U3*U13)/(V3) -> 227.5 | W13: =(V3*V13)/(W3) -> 237.3913 | X13: =(W3*W13)/(X3) -> 248.18182 | ... AJ13: =(AI3*AI13)/(AJ3) -> 546
A14: 35 cm | B14: =(C3*C14)/(B3) -> 56.1 | C14: =(D3*D14)/(C3) -> 70.125 | D14: =(E3*E14)/(D3) -> 93.5 | E14: =(F3*F14)/(E3) -> 112.2 | F14: =(G3*G14)/(F3) -> 140.25 | G14: =(H3*H14)/(G3) -> 143.84615 | H14: =(I3*I14)/(H3) -> 147.63158 | I14: =(J3*J14)/(I3) -> 151.62162 | ... O14: =(P3*P14)/(O3) -> 180.96774 | P14: 187 | Q14: =(P3*P14)/(Q3) -> 193.44828 | R14: =(Q3*Q14)/(R3) -> 200.35714 | S14: =(R3*R14)/(S3) -> 207.77778 | T14: =(S3*S14)/(T3) -> 215.76923 | U14: =(T3*T14)/(U3) -> 224.4 | V14: =(U3*U14)/(V3) -> 233.75 | W14: =(V3*V14)/(W3) -> 243.91304 | X14: =(W3*W14)/(X3) -> 255 | ... AJ14: =(AI3*AI14)/(AJ3) -> 561
A15: 34 cm | B15: =(C3*C15)/(B3) -> 57.9 | C15: =(D3*D15)/(C3) -> 72.375 | D15: =(E3*E15)/(D3) -> 96.5 | E15: =(F3*F15)/(E3) -> 115.8 | F15: =(G3*G15)/(F3) -> 144.75 | G15: =(H3*H15)/(G3) -> 148.46154 | H15: =(I3*I15)/(H3) -> 152.36842 | I15: =(J3*J15)/(I3) -> 156.48649 | ... O15: =(P3*P15)/(O3) -> 186.77419 | P15: 193 | Q15: =(P3*P15)/(Q3) -> 199.65517 | R15: =(Q3*Q15)/(R3) -> 206.78571 | S15: =(R3*R15)/(S3) -> 214.44444 | T15: =(S3*S15)/(T3) -> 222.69231 | U15: =(T3*T15)/(U3) -> 231.6 | V15: =(U3*U15)/(V3) -> 241.25 | W15: =(V3*V15)/(W3) -> 251.73913 | X15: =(W3*W15)/(X3) -> 263.18182 | ... AJ15: =(AI3*AI15)/(AJ3) -> 579
A16: 33 cm | B16: =(C3*C16)/(B3) -> 59.7 | C16: =(D3*D16)/(C3) -> 74.625 | D16: =(E3*E16)/(D3) -> 99.5 | E16: =(F3*F16)/(E3) -> 119.4 | F16: =(G3*G16)/(F3) -> 149.25 | G16: =(H3*H16)/(G3) -> 153.07692 | H16: =(I3*I16)/(H3) -> 157.10526 | I16: =(J3*J16)/(I3) -> 161.35135 | ... O16: =(P3*P16)/(O3) -> 192.58065 | P16: 199 | Q16: =(P3*P16)/(Q3) -> 205.86207 | R16: =(Q3*Q16)/(R3) -> 213.21429 | S16: =(R3*R16)/(S3) -> 221.11111 | T16: =(S3*S16)/(T3) -> 229.61538 | U16: =(T3*T16)/(U3) -> 238.8 | V16: =(U3*U16)/(V3) -> 248.75 | W16: =(V3*V16)/(W3) -> 259.56522 | X16: =(W3*W16)/(X3) -> 271.36364 | ... AJ16: =(AI3*AI16)/(AJ3) -> 597
A17: 32 cm | B17: =(C3*C17)/(B3) -> 61.5 | C17: =(D3*D17)/(C3) -> 76.875 | D17: =(E3*E17)/(D3) -> 102.5 | E17: =(F3*F17)/(E3) -> 123 | F17: =(G3*G17)/(F3) -> 153.75 | G17: =(H3*H17)/(G3) -> 157.69231 | H17: =(I3*I17)/(H3) -> 161.84211 | I17: =(J3*J17)/(I3) -> 166.21622 | ... O17: =(P3*P17)/(O3) -> 198.3871 | P17: 205 | Q17: =(P3*P17)/(Q3) -> 212.06897 | R17: =(Q3*Q17)/(R3) -> 219.64286 | S17: =(R3*R17)/(S3) -> 227.77778 | T17: =(S3*S17)/(T3) -> 236.53846 | U17: =(T3*T17)/(U3) -> 246 | V17: =(U3*U17)/(V3) -> 256.25 | W17: =(V3*V17)/(W3) -> 267.3913 | X17: =(W3*W17)/(X3) -> 279.54545 | ... AJ17: =(AI3*AI17)/(AJ3) -> 615
A18: 31 cm | B18: =(C3*C18)/(B3) -> 63.6 | C18: =(D3*D18)/(C3) -> 79.5 | D18: =(E3*E18)/(D3) -> 106 | E18: =(F3*F18)/(E3) -> 127.2 | F18: =(G3*G18)/(F3) -> 159 | G18: =(H3*H18)/(G3) -> 163.07692 | H18: =(I3*I18)/(H3) -> 167.36842 | I18: =(J3*J18)/(I3) -> 171.89189 | ... O18: =(P3*P18)/(O3) -> 205.16129 | P18: 212 | Q18: =(P3*P18)/(Q3) -> 219.31034 | R18: =(Q3*Q18)/(R3) -> 227.14286 | S18: =(R3*R18)/(S3) -> 235.55556 | T18: =(S3*S18)/(T3) -> 244.61538 | U18: =(T3*T18)/(U3) -> 254.4 | V18: =(U3*U18)/(V3) -> 265 | W18: =(V3*V18)/(W3) -> 276.52174 | X18: =(W3*W18)/(X3) -> 289.09091 | ... AJ18: =(AI3*AI18)/(AJ3) -> 636
A19: 30 cm | B19: =(C3*C19)/(B3) -> 65.7 | C19: =(D3*D19)/(C3) -> 82.125 | D19: =(E3*E19)/(D3) -> 109.5 | E19: =(F3*F19)/(E3) -> 131.4 | F19: =(G3*G19)/(F3) -> 164.25 | G19: =(H3*H19)/(G3) -> 168.46154 | H19: =(I3*I19)/(H3) -> 172.89474 | I19: =(J3*J19)/(I3) -> 177.56757 | ... O19: =(P3*P19)/(O3) -> 211.93548 | P19: 219 | Q19: =(P3*P19)/(Q3) -> 226.55172 | R19: =(Q3*Q19)/(R3) -> 234.64286 | S19: =(R3*R19)/(S3) -> 243.33333 | T19: =(S3*S19)/(T3) -> 252.69231 | U19: =(T3*T19)/(U3) -> 262.8 | V19: =(U3*U19)/(V3) -> 273.75 | W19: =(V3*V19)/(W3) -> 285.65217 | X19: =(W3*W19)/(X3) -> 298.63636 | ... AJ19: =(AI3*AI19)/(AJ3) -> 657
A20: 29 cm | B20: =(C3*C20)/(B3) -> 67.8 | C20: =(D3*D20)/(C3) -> 84.75 | D20: =(E3*E20)/(D3) -> 113 | E20: =(F3*F20)/(E3) -> 135.6 | F20: =(G3*G20)/(F3) -> 169.5 | G20: =(H3*H20)/(G3) -> 173.84615 | H20: =(I3*I20)/(H3) -> 178.42105 | I20: =(J3*J20)/(I3) -> 183.24324 | ... O20: =(P3*P20)/(O3) -> 218.70968 | P20: 226 | Q20: =(P3*P20)/(Q3) -> 233.7931 | R20: =(Q3*Q20)/(R3) -> 242.14286 | S20: =(R3*R20)/(S3) -> 251.11111 | T20: =(S3*S20)/(T3) -> 260.76923 | U20: =(T3*T20)/(U3) -> 271.2 | V20: =(U3*U20)/(V3) -> 282.5 | W20: =(V3*V20)/(W3) -> 294.78261 | X20: =(W3*W20)/(X3) -> 308.18182 | ... AJ20: =(AI3*AI20)/(AJ3) -> 678
A21: 28 cm | B21: =(C3*C21)/(B3) -> 70.2 | C21: =(D3*D21)/(C3) -> 87.75 | D21: =(E3*E21)/(D3) -> 117 | E21: =(F3*F21)/(E3) -> 140.4 | F21: =(G3*G21)/(F3) -> 175.5 | G21: =(H3*H21)/(G3) -> 180 | H21: =(I3*I21)/(H3) -> 184.73684 | I21: =(J3*J21)/(I3) -> 189.72973 | ... O21: =(P3*P21)/(O3) -> 226.45161 | P21: 234 | Q21: =(P3*P21)/(Q3) -> 242.06897 | R21: =(Q3*Q21)/(R3) -> 250.71429 | S21: =(R3*R21)/(S3) -> 260 | T21: =(S3*S21)/(T3) -> 270 | U21: =(T3*T21)/(U3) -> 280.8 | V21: =(U3*U21)/(V3) -> 292.5 | W21: =(V3*V21)/(W3) -> 305.21739 | X21: =(W3*W21)/(X3) -> 319.09091 | ... AJ21: =(AI3*AI21)/(AJ3) -> 702
A22: 27 cm | B22: =(C3*C22)/(B3) -> 72.9 | C22: =(D3*D22)/(C3) -> 91.125 | D22: =(E3*E22)/(D3) -> 121.5 | E22: =(F3*F22)/(E3) -> 145.8 | F22: =(G3*G22)/(F3) -> 182.25 | G22: =(H3*H22)/(G3) -> 186.92308 | H22: =(I3*I22)/(H3) -> 191.84211 | I22: =(J3*J22)/(I3) -> 197.02703 | ... O22: =(P3*P22)/(O3) -> 235.16129 | P22: 243 | Q22: =(P3*P22)/(Q3) -> 251.37931 | R22: =(Q3*Q22)/(R3) -> 260.35714 | S22: =(R3*R22)/(S3) -> 270 | T22: =(S3*S22)/(T3) -> 280.38462 | U22: =(T3*T22)/(U3) -> 291.6 | V22: =(U3*U22)/(V3) -> 303.75 | W22: =(V3*V22)/(W3) -> 316.95652 | X22: =(W3*W22)/(X3) -> 331.36364 | ... AJ22: =(AI3*AI22)/(AJ3) -> 729
A23: 26 cm | B23: =(C3*C23)/(B3) -> 75.6 | C23: =(D3*D23)/(C3) -> 94.5 | D23: =(E3*E23)/(D3) -> 126 | E23: =(F3*F23)/(E3) -> 151.2 | F23: =(G3*G23)/(F3) -> 189 | G23: =(H3*H23)/(G3) -> 193.84615 | H23: =(I3*I23)/(H3) -> 198.94737 | I23: =(J3*J23)/(I3) -> 204.32432 | ... O23: =(P3*P23)/(O3) -> 243.87097 | P23: 252 | Q23: =(P3*P23)/(Q3) -> 260.68966 | R23: =(Q3*Q23)/(R3) -> 270 | S23: =(R3*R23)/(S3) -> 280 | T23: =(S3*S23)/(T3) -> 290.76923 | U23: =(T3*T23)/(U3) -> 302.4 | V23: =(U3*U23)/(V3) -> 315 | W23: =(V3*V23)/(W3) -> 328.69565 | X23: =(W3*W23)/(X3) -> 343.63636 | ... AJ23: =(AI3*AI23)/(AJ3) -> 756
A24: 25 cm | B24: =(C3*C24)/(B3) -> 78.6 | C24: =(D3*D24)/(C3) -> 98.25 | D24: =(E3*E24)/(D3) -> 131 | E24: =(F3*F24)/(E3) -> 157.2 | F24: =(G3*G24)/(F3) -> 196.5 | G24: =(H3*H24)/(G3) -> 201.53846 | H24: =(I3*I24)/(H3) -> 206.84211 | I24: =(J3*J24)/(I3) -> 212.43243 | ... O24: =(P3*P24)/(O3) -> 253.54839 | P24: 262 | Q24: =(P3*P24)/(Q3) -> 271.03448 | R24: =(Q3*Q24)/(R3) -> 280.71429 | S24: =(R3*R24)/(S3) -> 291.11111 | T24: =(S3*S24)/(T3) -> 302.30769 | U24: =(T3*T24)/(U3) -> 314.4 | V24: =(U3*U24)/(V3) -> 327.5 | W24: =(V3*V24)/(W3) -> 341.73913 | X24: =(W3*W24)/(X3) -> 357.27273 | ... AJ24: =(AI3*AI24)/(AJ3) -> 786
A25: 24 cm | B25: =(C3*C25)/(B3) -> 81.9 | C25: =(D3*D25)/(C3) -> 102.375 | D25: =(E3*E25)/(D3) -> 136.5 | E25: =(F3*F25)/(E3) -> 163.8 | F25: =(G3*G25)/(F3) -> 204.75 | G25: =(H3*H25)/(G3) -> 210 | H25: =(I3*I25)/(H3) -> 215.52632 | I25: =(J3*J25)/(I3) -> 221.35135 | ... O25: =(P3*P25)/(O3) -> 264.19355 | P25: 273 | Q25: =(P3*P25)/(Q3) -> 282.41379 | R25: =(Q3*Q25)/(R3) -> 292.5 | S25: =(R3*R25)/(S3) -> 303.33333 | T25: =(S3*S25)/(T3) -> 315 | U25: =(T3*T25)/(U3) -> 327.6 | V25: =(U3*U25)/(V3) -> 341.25 | W25: =(V3*V25)/(W3) -> 356.08696 | X25: =(W3*W25)/(X3) -> 372.27273 | ... AJ25: =(AI3*AI25)/(AJ3) -> 819
A26: 23 cm | B26: =(C3*C26)/(B3) -> 85.5 | C26: =(D3*D26)/(C3) -> 106.875 | D26: =(E3*E26)/(D3) -> 142.5 | E26: =(F3*F26)/(E3) -> 171 | F26: =(G3*G26)/(F3) -> 213.75 | G26: =(H3*H26)/(G3) -> 219.23077 | H26: =(I3*I26)/(H3) -> 225 | I26: =(J3*J26)/(I3) -> 231.08108 | ... O26: =(P3*P26)/(O3) -> 275.80645 | P26: 285 | Q26: =(P3*P26)/(Q3) -> 294.82759 | R26: =(Q3*Q26)/(R3) -> 305.35714 | S26: =(R3*R26)/(S3) -> 316.66667 | T26: =(S3*S26)/(T3) -> 328.84615 | U26: =(T3*T26)/(U3) -> 342 | V26: =(U3*U26)/(V3) -> 356.25 | W26: =(V3*V26)/(W3) -> 371.73913 | X26: =(W3*W26)/(X3) -> 388.63636 | ... AJ26: =(AI3*AI26)/(AJ3) -> 855
A27: 22 cm | B27: =(C3*C27)/(B3) -> 89.4 | C27: =(D3*D27)/(C3) -> 111.75 | D27: =(E3*E27)/(D3) -> 149 | E27: =(F3*F27)/(E3) -> 178.8 | F27: =(G3*G27)/(F3) -> 223.5 | G27: =(H3*H27)/(G3) -> 229.23077 | H27: =(I3*I27)/(H3) -> 235.26316 | I27: =(J3*J27)/(I3) -> 241.62162 | ... O27: =(P3*P27)/(O3) -> 288.3871 | P27: 298 | Q27: =(P3*P27)/(Q3) -> 308.27586 | R27: =(Q3*Q27)/(R3) -> 319.28571 | S27: =(R3*R27)/(S3) -> 331.11111 | T27: =(S3*S27)/(T3) -> 343.84615 | U27: =(T3*T27)/(U3) -> 357.6 | V27: =(U3*U27)/(V3) -> 372.5 | W27: =(V3*V27)/(W3) -> 388.69565 | X27: =(W3*W27)/(X3) -> 406.36364 | ... AJ27: =(AI3*AI27)/(AJ3) -> 894
A28: 21 cm | B28: =(C3*C28)/(B3) -> 93.6 | C28: =(D3*D28)/(C3) -> 117 | D28: =(E3*E28)/(D3) -> 156 | E28: =(F3*F28)/(E3) -> 187.2 | F28: =(G3*G28)/(F3) -> 234 | G28: =(H3*H28)/(G3) -> 240 | H28: =(I3*I28)/(H3) -> 246.31579 | I28: =(J3*J28)/(I3) -> 252.97297 | ... O28: =(P3*P28)/(O3) -> 301.93548 | P28: 312 | Q28: =(P3*P28)/(Q3) -> 322.75862 | R28: =(Q3*Q28)/(R3) -> 334.28571 | S28: =(R3*R28)/(S3) -> 346.66667 | T28: =(S3*S28)/(T3) -> 360 | U28: =(T3*T28)/(U3) -> 374.4 | V28: =(U3*U28)/(V3) -> 390 | W28: =(V3*V28)/(W3) -> 406.95652 | X28: =(W3*W28)/(X3) -> 425.45455 | ... AJ28: =(AI3*AI28)/(AJ3) -> 936
A29: 20 cm | B29: =(C3*C29)/(B3) -> 98.4 | C29: =(D3*D29)/(C3) -> 123 | D29: =(E3*E29)/(D3) -> 164 | E29: =(F3*F29)/(E3) -> 196.8 | F29: =(G3*G29)/(F3) -> 246 | G29: =(H3*H29)/(G3) -> 252.30769 | H29: =(I3*I29)/(H3) -> 258.94737 | I29: =(J3*J29)/(I3) -> 265.94595 | ... O29: =(P3*P29)/(O3) -> 317.41935 | P29: 328 | Q29: =(P3*P29)/(Q3) -> 339.31034 | R29: =(Q3*Q29)/(R3) -> 351.42857 | S29: =(R3*R29)/(S3) -> 364.44444 | T29: =(S3*S29)/(T3) -> 378.46154 | U29: =(T3*T29)/(U3) -> 393.6 | V29: =(U3*U29)/(V3) -> 410 | W29: =(V3*V29)/(W3) -> 427.82609 | X29: =(W3*W29)/(X3) -> 447.27273 | ... AJ29: =(AI3*AI29)/(AJ3) -> 984
A30: 19 cm | B30: =(C3*C30)/(B3) -> 103.5 | C30: =(D3*D30)/(C3) -> 129.375 | D30: =(E3*E30)/(D3) -> 172.5 | E30: =(F3*F30)/(E3) -> 207 | F30: =(G3*G30)/(F3) -> 258.75 | G30: =(H3*H30)/(G3) -> 265.38462 | H30: =(I3*I30)/(H3) -> 272.36842 | I30: =(J3*J30)/(I3) -> 279.72973 | ... O30: =(P3*P30)/(O3) -> 333.87097 | P30: 345 | Q30: =(P3*P30)/(Q3) -> 356.89655 | R30: =(Q3*Q30)/(R3) -> 369.64286 | S30: =(R3*R30)/(S3) -> 383.33333 | T30: =(S3*S30)/(T3) -> 398.07692 | U30: =(T3*T30)/(U3) -> 414 | V30: =(U3*U30)/(V3) -> 431.25 | W30: =(V3*V30)/(W3) -> 450 | X30: =(W3*W30)/(X3) -> 470.45455 | ... AJ30: =(AI3*AI30)/(AJ3) -> 1035
A31: 18 cm | B31: =(C3*C31)/(B3) -> 109.2 | C31: =(D3*D31)/(C3) -> 136.5 | D31: =(E3*E31)/(D3) -> 182 | E31: =(F3*F31)/(E3) -> 218.4 | F31: =(G3*G31)/(F3) -> 273 | G31: =(H3*H31)/(G3) -> 280 | H31: =(I3*I31)/(H3) -> 287.36842 | I31: =(J3*J31)/(I3) -> 295.13514 | ... O31: =(P3*P31)/(O3) -> 352.25806 | P31: 364 | Q31: =(P3*P31)/(Q3) -> 376.55172 | R31: =(Q3*Q31)/(R3) -> 390 | S31: =(R3*R31)/(S3) -> 404.44444 | T31: =(S3*S31)/(T3) -> 420 | U31: =(T3*T31)/(U3) -> 436.8 | V31: =(U3*U31)/(V3) -> 455 | W31: =(V3*V31)/(W3) -> 474.78261 | X31: =(W3*W31)/(X3) -> 496.36364 | ... AJ31: =(AI3*AI31)/(AJ3) -> 1092
A32: 17 cm | B32: =(C3*C32)/(B3) -> 115.8 | C32: =(D3*D32)/(C3) -> 144.75 | D32: =(E3*E32)/(D3) -> 193 | E32: =(F3*F32)/(E3) -> 231.6 | F32: =(G3*G32)/(F3) -> 289.5 | G32: =(H3*H32)/(G3) -> 296.92308 | H32: =(I3*I32)/(H3) -> 304.73684 | I32: =(J3*J32)/(I3) -> 312.97297 | ... O32: =(P3*P32)/(O3) -> 373.54839 | P32: 386 | Q32: =(P3*P32)/(Q3) -> 399.31034 | R32: =(Q3*Q32)/(R3) -> 413.57143 | S32: =(R3*R32)/(S3) -> 428.88889 | T32: =(S3*S32)/(T3) -> 445.38462 | U32: =(T3*T32)/(U3) -> 463.2 | V32: =(U3*U32)/(V3) -> 482.5 | W32: =(V3*V32)/(W3) -> 503.47826 | X32: =(W3*W32)/(X3) -> 526.36364 | ... AJ32: =(AI3*AI32)/(AJ3) -> 1158
A33: 16 cm | B33: =(C3*C33)/(B3) -> 123 | C33: =(D3*D33)/(C3) -> 153.75 | D33: =(E3*E33)/(D3) -> 205 | E33: =(F3*F33)/(E3) -> 246 | F33: =(G3*G33)/(F3) -> 307.5 | G33: =(H3*H33)/(G3) -> 315.38462 | H33: =(I3*I33)/(H3) -> 323.68421 | I33: =(J3*J33)/(I3) -> 332.43243 | ... O33: =(P3*P33)/(O3) -> 396.77419 | P33: 410 | Q33: =(P3*P33)/(Q3) -> 424.13793 | R33: =(Q3*Q33)/(R3) -> 439.28571 | S33: =(R3*R33)/(S3) -> 455.55556 | T33: =(S3*S33)/(T3) -> 473.07692 | U33: =(T3*T33)/(U3) -> 492 | V33: =(U3*U33)/(V3) -> 512.5 | W33: =(V3*V33)/(W3) -> 534.78261 | X33: =(W3*W33)/(X3) -> 559.09091 | ... AJ33: =(AI3*AI33)/(AJ3) -> 1230
A34: 15 cm | B34: =(C3*C34)/(B3) -> 131.1 | C34: =(D3*D34)/(C3) -> 163.875 | D34: =(E3*E34)/(D3) -> 218.5 | E34: =(F3*F34)/(E3) -> 262.2 | F34: =(G3*G34)/(F3) -> 327.75 | G34: =(H3*H34)/(G3) -> 336.15385 | H34: =(I3*I34)/(H3) -> 345 | I34: =(J3*J34)/(I3) -> 354.32432 | ... O34: =(P3*P34)/(O3) -> 422.90323 | P34: 437 | Q34: =(P3*P34)/(Q3) -> 452.06897 | R34: =(Q3*Q34)/(R3) -> 468.21429 | S34: =(R3*R34)/(S3) -> 485.55556 | T34: =(S3*S34)/(T3) -> 504.23077 | U34: =(T3*T34)/(U3) -> 524.4 | V34: =(U3*U34)/(V3) -> 546.25 | W34: =(V3*V34)/(W3) -> 570 | X34: =(W3*W34)/(X3) -> 595.90909 | ... AJ34: =(AI3*AI34)/(AJ3) -> 1311
C35: NOT:Çizelgede belirtilen iplik uzunluklarına;Orta renklerde 2mm,Koyu renklerde 4mm daha ilave ekle (hesaplama 28 fayna göre yapılmıştır)
B36: 30 DENYE FULL LYCRALI SÜPREMLERİN GRAMAJLARINA GÖRE 100 MAYDAKİ ORTALAMA İPLİK UZUNLUKLARI
A37: 30 | B37: İPLİK NUMARALARI
A38: DENYELİ | B38: 100 | C38: 80 | D38: 60 | E38: 50 | F38: 40 | G38: 39 | H38: 38 | I38: 37 | J38: 36 | K38: 35 | L38: 34 | M38: 33 | N38: 32 | O38: 31 | P38: 30 | Q38: 29 | R38: 28 | S38: 27 | T38: 26 | U38: 25 | V38: 24 | W38: 23 | X38: 22 | Y38: 21 | Z38: 20 | AA38: 19 | AB38: 18 | AC38: 17 | AD38: 16 | AE38: 15 | AF38: 14 | AG38: 13 | AH38: 12 | AI38: 11 | AJ38: 10
A39: 45 cm | B39: =(C38*C39)/(B38) -> 46.8 | C39: =(D38*D39)/(C38) -> 58.5 | D39: =(E38*E39)/(D38) -> 78 | E39: =(F38*F39)/(E38) -> 93.6 | F39: =(G38*G39)/(F38) -> 117 | G39: =(H38*H39)/(G38) -> 120 | H39: =(I38*I39)/(H38) -> 123.15789 | I39: =(J38*J39)/(I38) -> 126.48649 | ... O39: =(P38*P39)/(O38) -> 150.96774 | P39: 156 | Q39: =(P38*P39)/(Q38) -> 161.37931 | R39: =(Q38*Q39)/(R38) -> 167.14286 | S39: =(R38*R39)/(S38) -> 173.33333 | T39: =(S38*S39)/(T38) -> 180 | U39: =(T38*T39)/(U38) -> 187.2 | V39: =(U38*U39)/(V38) -> 195 | W39: =(V38*V39)/(W38) -> 203.47826 | X39: =(W38*W39)/(X38) -> 212.72727 | ... AJ39: =(AI38*AI39)/(AJ38) -> 468
A40: 44 cm | B40: =(C38*C40)/(B38) -> 48 | C40: =(D38*D40)/(C38) -> 60 | D40: =(E38*E40)/(D38) -> 80 | E40: =(F38*F40)/(E38) -> 96 | F40: =(G38*G40)/(F38) -> 120 | G40: =(H38*H40)/(G38) -> 123.07692 | H40: =(I38*I40)/(H38) -> 126.31579 | I40: =(J38*J40)/(I38) -> 129.72973 | ... O40: =(P38*P40)/(O38) -> 154.83871 | P40: 160 | Q40: =(P38*P40)/(Q38) -> 165.51724 | R40: =(Q38*Q40)/(R38) -> 171.42857 | S40: =(R38*R40)/(S38) -> 177.77778 | T40: =(S38*S40)/(T38) -> 184.61538 | U40: =(T38*T40)/(U38) -> 192 | V40: =(U38*U40)/(V38) -> 200 | W40: =(V38*V40)/(W38) -> 208.69565 | X40: =(W38*W40)/(X38) -> 218.18182 | ... AJ40: =(AI38*AI40)/(AJ38) -> 480
...

Sheet FULL LYC SÜPREM ENLERİ
A1: FULL LYCRALI SÜPREMLERİN; LYCRA , PUSS ve FAYNA GÖRE ORTALAMA MAMÜL AÇIK ENLERİ
A2: 36 PUSS
B3: Mk. | C3: 20 Dny | D3: 30 Dny | E3: 40 Dny | F3: 70 Dny | G3: 32 Fayn | L3: Mk. | M3: 20 Dny | N3: 30 Dny | O3: 40 Dny | P3: 70 Dny | Q3: 30 Fayn | V3: Mk. | W3: 20 Dny | X3: 30 Dny | Y3: 40 Dny | Z3: 70 Dny | AA3: 28 Fayn | AF3: Mk. | AG3: 20 Dny | AH3: 30 Dny | AI3: 40 Dny | AJ3: 70 Dny | AK3: 27 Fayn | AP3: Mk. | AQ3: 20 Dny | AR3: 30 Dny | AS3: 40 Dny | AT3: 70 Dny | AU3: 26 Fayn | AZ3: Mk. | BA3: 20 Dny | BB3: 30 Dny | BC3: 40 Dny | BD3: 70 Dny | BE3: 24 Fayn
A4: KUMAŞ CİNSİ | B4: İğne | C4: May | D4: May | E4: May | F4: May | G4: 20 | H4: 30 | I4: 40 | J4: 70 | L4: İğne | M4: May | N4: May | O4: May | P4: May | Q4: 20 | R4: 30 | S4: 40 | T4: 70 | V4: İğne | W4: May | X4: May | Y4: May | Z4: May | AA4: 20 | AB4: 30 | AC4: 40 | AD4: 70 | AF4: İğne | AG4: May | AH4: May | AI4: May | AJ4: May | AK4: 20 | AL4: 30 | AM4: 40 | AN4: 70 | AP4: İğne | AQ4: May | AR4: May | AS4: May | AT4: May | AU4: 20 | AV4: 30 | AW4: 40 | AX4: 70 | AZ4: İğne | BA4: May | BB4: May | BC4: May | BD4: May | BE4: 20 | BF4: 30 | BG4: 40 | BH4: 70
B5: Sayısı | C5: Genişliği | D5: Genişliği | E5: Genişliği | F5: Genişliği | G5: Dny | H5: Dny | I5: Dny | J5: Dny | L5: Sayısı | M5: Genişliği | N5: Genişliği | O5: Genişliği | P5: Genişliği | Q5: Dny | R5: Dny | S5: Dny | T5: Dny | V5: Sayısı | W5: Genişliği | X5: Genişliği | Y5: Genişliği | Z5: Genişliği | AA5: Dny | AB5: Dny | AC5: Dny | AD5: Dny | AF5: Sayısı | AG5: Genişliği | AH5: Genişliği | AI5: Genişliği | AJ5: Genişliği | AK5: Dny | AL5: Dny | AM5: Dny | AN5: Dny | AP5: Sayısı | AQ5: Genişliği | AR5: Genişliği | AS5: Genişliği | AT5: Genişliği | AU5: Dny | AV5: Dny | AW5: Dny | AX5: Dny | AZ5: Sayısı | BA5: Genişliği | BB5: Genişliği | BC5: Genişliği | BD5: Genişliği | BE5: Dny | BF5: Dny | BG5: Dny | BH5: Dny
A6: 80/1 FULL LYCRALI SÜPREM | B6: 3600 | C6: 0.0359 | D6: 0.035 | E6: 0.0338 | F6: 0.029 | G6: =(B6*C6) -> 129.24 | H6: =(B6*D6) -> 126 | I6: =(B6*E6) -> 121.68 | J6: =(B6*F6) -> 104.4 | L6: 3384 | M6: 0.0336 | N6: 0.0328 | O6: 0.0317 | P6: 0.0272 | Q6: =(L6*M6) -> 113.7024 | R6: =(L6*N6) -> 110.9952 | S6: =(L6*O6) -> 107.2728 | T6: =(L6*P6) -> 92.0448 | V6: 3168 | W6: 0.0314 | X6: 0.0306 | Y6: 0.0296 | Z6: 0.0254 | AA6: =(V6*W6) -> 99.4752 | AB6: =(V6*X6) -> 96.9408 | AC6: =(V6*Y6) -> 93.7728 | AD6: =(V6*Z6) -> 80.4672 | AF6: 3052 | AK6: =(AF6*AG6) -> 0 | AL6: =(AF6*AH6) -> 0 | AM6: =(AF6*AI6) -> 0 | AN6: =(AF6*AJ6) -> 0 | AP6: 2928 | AU6: =(AP6*AQ6) -> 0 | AV6: =(AP6*AR6) -> 0 | AW6: =(AP6*AS6) -> 0 | AX6: =(AP6*AT6) -> 0 | AZ6: 2712 | BE6: =(AZ6*BA6) -> 0 | BF6: =(AZ6*BB6) -> 0 | BG6: =(AZ6*BC6) -> 0 | BH6: =(AZ6*BD6) -> 0
A7: 60/1 FULL LYCRALI SÜPREM | B7: 3600 | C7: 0.0478 | D7: 0.0466 | E7: 0.045 | F7: 0.0387 | G7: =(B7*C7) -> 172.08 | H7: =(B7*D7) -> 167.76 | I7: =(B7*E7) -> 162 | J7: =(B7*F7) -> 139.32 | L7: 3384 | M7: 0.0448 | N7: 0.0437 | O7: 0.0422 | P7: 0.0363 | Q7: =(L7*M7) -> 151.6032 | R7: =(L7*N7) -> 147.8808 | S7: =(L7*O7) -> 142.8048 | T7: =(L7*P7) -> 122.8392 | V7: 3168 | W7: 0.0418 | X7: 0.0407 | Y7: 0.0394 | Z7: 0.0339 | AA7: =(V7*W7) -> 132.4224 | AB7: =(V7*X7) -> 128.9376 | AC7: =(V7*Y7) -> 124.8192 | AD7: =(V7*Z7) -> 107.3952 | AF7: 3052 | AK7: =(AF7*AG7) -> 0 | AL7: =(AF7*AH7) -> 0 | AM7: =(AF7*AI7) -> 0 | AN7: =(AF7*AJ7) -> 0 | AP7: 2928 | AU7: =(AP7*AQ7) -> 0 | AV7: =(AP7*AR7) -> 0 | AW7: =(AP7*AS7) -> 0 | AX7: =(AP7*AT7) -> 0 | AZ7: 2712 | BE7: =(AZ7*BA7) -> 0 | BF7: =(AZ7*BB7) -> 0 | BG7: =(AZ7*BC7) -> 0 | BH7: =(AZ7*BD7) -> 0
A8: 50/1 FULL LYCRALI SÜPREM | B8: 3600 | C8: 0.0574 | D8: 0.0559 | E8: 0.054 | F8: 0.0465 | G8: =(B8*C8) -> 206.64 | H8: =(B8*D8) -> 201.24 | I8: =(B8*E8) -> 194.4 | J8: =(B8*F8) -> 167.4 | L8: 3384 | M8: 0.0538 | N8: 0.0524 | O8: 0.0507 | P8: 0.0443 | Q8: =(L8*M8) -> 182.0592 | R8: =(L8*N8) -> 177.3216 | S8: =(L8*O8) -> 171.5688 | T8: =(L8*P8) -> 149.9112 | V8: 3168 | W8: 0.0502 | X8: 0.0489 | Y8: 0.0473 | Z8: 0.0414 | AA8: =(V8*W8) -> 159.0336 | AB8: =(V8*X8) -> 154.9152 | AC8: =(V8*Y8) -> 149.8464 | AD8: =(V8*Z8) -> 131.1552 | AF8: 3052 | AG8: 0.0484 | AH8: 0.0471 | AI8: 0.0456 | AJ8: 0.0399 | AK8: =(AF8*AG8) -> 147.7168 | AL8: =(AF8*AH8) -> 143.7492 | AM8: =(AF8*AI8) -> 139.1712 | AN8: =(AF8*AJ8) -> 121.7748 | AP8: 2928 | AU8: =(AP8*AQ8) -> 0 | AV8: =(AP8*AR8) -> 0 | AW8: =(AP8*AS8) -> 0 | AX8: =(AP8*AT8) -> 0 | AZ8: 2712 | BE8: =(AZ8*BA8) -> 0 | BF8: =(AZ8*BB8) -> 0 | BG8: =(AZ8*BC8) -> 0 | BH8: =(AZ8*BD8) -> 0
A9: 40/1 FULL LYCRALI SÜPREM | B9: 3600 | G9: =(B9*C9) -> 0 | H9: =(B9*D9) -> 0 | I9: =(B9*E9) -> 0 | J9: =(B9*F9) -> 0 | L9: 3384 | M9: 0.0672 | N9: 0.0655 | O9: 0.0633 | P9: 0.0554 | Q9: =(L9*M9) -> 227.4048 | R9: =(L9*N9) -> 221.652 | S9: =(L9*O9) -> 214.2072 | T9: =(L9*P9) -> 187.4736 | V9: 3168 | W9: 0.0627 | X9: 0.0611 | Y9: 0.0591 | Z9: 0.0517 | AA9: =(V9*W9) -> 198.6336 | AB9: =(V9*X9) -> 193.5648 | AC9: =(V9*Y9) -> 187.2288 | AD9: =(V9*Z9) -> 163.7856 | AF9: 3052 | AG9: 0.0605 | AH9: 0.0588 | AI9: 0.057 | AJ9: 0.0499 | AK9: =(AF9*AG9) -> 184.646 | AL9: =(AF9*AH9) -> 179.4576 | AM9: =(AF9*AI9) -> 173.964 | AN9: =(AF9*AJ9) -> 152.2948 | AP9: 2928 | AQ9: 0.0583 | AR9: 0.0566 | AS9: 0.0549 | AT9: 0.0481 | AU9: =(AP9*AQ9) -> 170.7024 | AV9: =(AP9*AR9) -> 165.7248 | AW9: =(AP9*AS9) -> 160.7472 | AX9: =(AP9*AT9) -> 140.8368 | AZ9: 2712 | BA9: 0.0538 | BB9: 0.0522 | BC9: 0.0507 | BD9: 0.0444 | BE9: =(AZ9*BA9) -> 145.9056 | BF9: =(AZ9*BB9) -> 141.5664 | BG9: =(AZ9*BC9) -> 137.4984 | BH9: =(AZ9*BD9) -> 120.4128
A10: 36/1 FULL LYCRALI SÜPREM | B10: 3600 | G10: =(B10*C10) -> 0 | H10: =(B10*D10) -> 0 | I10: =(B10*E10) -> 0 | J10: =(B10*F10) -> 0 | L10: 3384 | Q10: =(L10*M10) -> 0 | R10: =(L10*N10) -> 0 | S10: =(L10*O10) -> 0 | T10: =(L10*P10) -> 0 | V10: 3168 | W10: 0.0642 | X10: 0.0624 | Y10: 0.0606 | Z10: 0.0539 | AA10: =(V10*W10) -> 203.3856 | AB10: =(V10*X10) -> 197.6832 | AC10: =(V10*Y10) -> 191.9808 | AD10: =(V10*Z10) -> 170.7552 | AF10: 3052 | AG10: 0.0619 | AH10: 0.0602 | AI10: 0.0584 | AJ10: 0.052 | AK10: =(AF10*AG10) -> 188.9188 | AL10: =(AF10*AH10) -> 183.7304 | AM10: =(AF10*AI10) -> 178.2368 | AN10: =(AF10*AJ10) -> 158.704 | AP10: 2928 | AQ10: 0.0596 | AR10: 0.058 | AS10: 0.0562 | AT10: 0.0501 | AU10: =(AP10*AQ10) -> 174.5088 | AV10: =(AP10*AR10) -> 169.824 | AW10: =(AP10*AS10) -> 164.5536 | AX10: =(AP10*AT10) -> 146.6928 | AZ10: 2712 | BA10: 0.055 | BB10: 0.0535 | BC10: 0.0519 | BD10: 0.0462 | BE10: =(AZ10*BA10) -> 149.16 | BF10: =(AZ10*BB10) -> 145.092 | BG10: =(AZ10*BC10) -> 140.7528 | BH10: =(AZ10*BD10) -> 125.2944
A11: 34/1 FULL LYCRALI SÜPREM | B11: 3600 | G11: =(B11*C11) -> 0 | H11: =(B11*D11) -> 0 | I11: =(B11*E11) -> 0 | J11: =(B11*F11) -> 0 | L11: 3384 | Q11: =(L11*M11) -> 0 | R11: =(L11*N11) -> 0 | S11: =(L11*O11) -> 0 | T11: =(L11*P11) -> 0 | V11: 3168 | W11: 0.065 | X11: 0.0632 | Y11: 0.0613 | Z11: 0.0551 | AA11: =(V11*W11) -> 205.92 | AB11: =(V11*X11) -> 200.2176 | AC11: =(V11*Y11) -> 194.1984 | AD11: =(V11*Z11) -> 174.5568 | AF11: 3052 | AG11: 0.0627 | AH11: 0.0609 | AI11: 0.0591 | AJ11: 0.0531 | AK11: =(AF11*AG11) -> 191.3604 | AL11: =(AF11*AH11) -> 185.8668 | AM11: =(AF11*AI11) -> 180.3732 | AN11: =(AF11*AJ11) -> 162.0612 | AP11: 2928 | AQ11: 0.0604 | AR11: 0.0586 | AS11: 0.0569 | AT11: 0.0511 | AU11: =(AP11*AQ11) -> 176.8512 | AV11: =(AP11*AR11) -> 171.5808 | AW11: =(AP11*AS11) -> 166.6032 | AX11: =(AP11*AT11) -> 149.6208 | AZ11: 2712 | BA11: 0.0558 | BB11: 0.0541 | BC11: 0.0525 | BD11: 0.0472 | BE11: =(AZ11*BA11) -> 151.3296 | BF11: =(AZ11*BB11) -> 146.7192 | BG11: =(AZ11*BC11) -> 142.38 | BH11: =(AZ11*BD11) -> 128.0064
A12: 32/1 FULL LYCRALI SÜPREM | B12: 3600 | G12: =(B12*C12) -> 0 | H12: =(B12*D12) -> 0 | I12: =(B12*E12) -> 0 | J12: =(B12*F12) -> 0 | L12: 3384 | Q12: =(L12*M12) -> 0 | R12: =(L12*N12) -> 0 | S12: =(L12*O12) -> 0 | T12: =(L12*P12) -> 0 | V12: 3168 | W12: 0.0657 | X12: 0.0639 | Y12: 0.0624 | Z12: 0.0568 | AA12: =(V12*W12) -> 208.1376 | AB12: =(V12*X12) -> 202.4352 | AC12: =(V12*Y12) -> 197.6832 | AD12: =(V12*Z12) -> 179.9424 | AF12: 3052 | AG12: 0.0634 | AH12: 0.0616 | AI12: 0.0602 | AJ12: 0.0548 | AK12: =(AF12*AG12) -> 193.4968 | AL12: =(AF12*AH12) -> 188.0032 | AM12: =(AF12*AI12) -> 183.7304 | AN12: =(AF12*AJ12) -> 167.2496 | AP12: 2928 | AQ12: 0.0611 | AR12: 0.0593 | AS12: 0.058 | AT12: 0.0528 | AU12: =(AP12*AQ12) -> 178.9008 | AV12: =(AP12*AR12) -> 173.6304 | AW12: =(AP12*AS12) -> 169.824 | AX12: =(AP12*AT12) -> 154.5984 | AZ12: 2712 | BA12: 0.0564 | BB12: 0.0547 | BC12: 0.0535 | BD12: 0.0487 | BE12: =(AZ12*BA12) -> 152.9568 | BF12: =(AZ12*BB12) -> 148.3464 | BG12: =(AZ12*BC12) -> 145.092 | BH12: =(AZ12*BD12) -> 132.0744
A13: 30/1 FULL LYCRALI SÜPREM | B13: 3600 | G13: =(B13*C13) -> 0 | H13: =(B13*D13) -> 0 | I13: =(B13*E13) -> 0 | J13: =(B13*F13) -> 0 | L13: 3384 | Q13: =(L13*M13) -> 0 | R13: =(L13*N13) -> 0 | S13: =(L13*O13) -> 0 | T13: =(L13*P13) -> 0 | V13: 3168 | W13: 0.0665 | X13: 0.0646 | Y13: 0.0627 | Z13: 0.0572 | AA13: =(V13*W13) -> 210.672 | AB13: =(V13*X13) -> 204.6528 | AC13: =(V13*Y13) -> 198.6336 | AD13: =(V13*Z13) -> 181.2096 | AF13: 3052 | AG13: 0.0641 | AH13: 0.0623 | AI13: 0.0605 | AJ13: 0.0552 | AK13: =(AF13*AG13) -> 195.6332 | AL13: =(AF13*AH13) -> 190.1396 | AM13: =(AF13*AI13) -> 184.646 | AN13: =(AF13*AJ13) -> 168.4704 | AP13: 2928 | AQ13: 0.0617 | AR13: 0.06 | AS13: 0.0583 | AT13: 0.0532 | AU13: =(AP13*AQ13) -> 180.6576 | AV13: =(AP13*AR13) -> 175.68 | AW13: =(AP13*AS13) -> 170.7024 | AX13: =(AP13*AT13) -> 155.7696 | AZ13: 2712 | BA13: 0.057 | BB13: 0.0554 | BC13: 0.0538 | BD13: 0.0491 | BE13: =(AZ13*BA13) -> 154.584 | BF13: =(AZ13*BB13) -> 150.2448 | BG13: =(AZ13*BC13) -> 145.9056 | BH13: =(AZ13*BD13) -> 133.1592
A14: 28/1 FULL LYCRALI SÜPREM | B14: 3600 | G14: =(B14*C14) -> 0 | H14: =(B14*D14) -> 0 | I14: =(B14*E14) -> 0 | J14: =(B14*F14) -> 0 | L14: 3384 | Q14: =(L14*M14) -> 0 | R14: =(L14*N14) -> 0 | S14: =(L14*O14) -> 0 | T14: =(L14*P14) -> 0 | V14: 3168 | W14: 0.0713 | X14: 0.0693 | Y14: 0.0672 | Z14: 0.0613 | AA14: =(V14*W14) -> 225.8784 | AB14: =(V14*X14) -> 219.5424 | AC14: =(V14*Y14) -> 212.8896 | AD14: =(V14*Z14) -> 194.1984 | AF14: 3052 | AG14: 0.0688 | AH14: 0.0668 | AI14: 0.0648 | AJ14: 0.0591 | AK14: =(AF14*AG14) -> 209.9776 | AL14: =(AF14*AH14) -> 203.8736 | AM14: =(AF14*AI14) -> 197.7696 | AN14: =(AF14*AJ14) -> 180.3732 | AP14: 2928 | AQ14: 0.0663 | AR14: 0.0643 | AS14: 0.0624 | AT14: 0.0569 | AU14: =(AP14*AQ14) -> 194.1264 | AV14: =(AP14*AR14) -> 188.2704 | AW14: =(AP14*AS14) -> 182.7072 | AX14: =(AP14*AT14) -> 166.6032 | AZ14: 2712 | BA14: 0.0612 | BB14: 0.0594 | BC14: 0.0576 | BD14: 0.0525 | BE14: =(AZ14*BA14) -> 165.9744 | BF14: =(AZ14*BB14) -> 161.0928 | BG14: =(AZ14*BC14) -> 156.2112 | BH14: =(AZ14*BD14) -> 142.38
A15: 26/1 FULL LYCRALI SÜPREM | B15: 3600 | G15: =(B15*C15) -> 0 | H15: =(B15*D15) -> 0 | I15: =(B15*E15) -> 0 | J15: =(B15*F15) -> 0 | L15: 3384 | Q15: =(L15*M15) -> 0 | R15: =(L15*N15) -> 0 | S15: =(L15*O15) -> 0 | T15: =(L15*P15) -> 0 | V15: 3168 | W15: 0.0767 | X15: 0.0746 | Y15: 0.0724 | Z15: 0.0661 | AA15: =(V15*W15) -> 242.9856 | AB15: =(V15*X15) -> 236.3328 | AC15: =(V15*Y15) -> 229.3632 | AD15: =(V15*Z15) -> 209.4048 | AF15: 3052 | AG15: 0.074 | AH15: 0.0719 | AI15: 0.0698 | AJ15: 0.0637 | AK15: =(AF15*AG15) -> 225.848 | AL15: =(AF15*AH15) -> 219.4388 | AM15: =(AF15*AI15) -> 213.0296 | AN15: =(AF15*AJ15) -> 194.4124 | AP15: 2928 | AQ15: 0.0713 | AR15: 0.0692 | AS15: 0.0672 | AT15: 0.0613 | AU15: =(AP15*AQ15) -> 208.7664 | AV15: =(AP15*AR15) -> 202.6176 | AW15: =(AP15*AS15) -> 196.7616 | AX15: =(AP15*AT15) -> 179.4864 | AZ15: 2712 | BA15: 0.0658 | BB15: 0.0639 | BC15: 0.062 | BD15: 0.0566 | BE15: =(AZ15*BA15) -> 178.4496 | BF15: =(AZ15*BB15) -> 173.2968 | BG15: =(AZ15*BC15) -> 168.144 | BH15: =(AZ15*BD15) -> 153.4992
A16: 24/1 FULL LYCRALI SÜPREM | B16: 3600 | G16: =(B16*C16) -> 0 | H16: =(B16*D16) -> 0 | I16: =(B16*E16) -> 0 | J16: =(B16*F16) -> 0 | L16: 3384 | Q16: =(L16*M16) -> 0 | R16: =(L16*N16) -> 0 | S16: =(L16*O16) -> 0 | T16: =(L16*P16) -> 0 | V16: 3168 | W16: 0.0832 | X16: 0.0808 | Y16: 0.0784 | Z16: 0.0716 | AA16: =(V16*W16) -> 263.5776 | AB16: =(V16*X16) -> 255.9744 | AC16: =(V16*Y16) -> 248.3712 | AD16: =(V16*Z16) -> 226.8288 | AF16: 3052 | AG16: 0.0802 | AH16: 0.0779 | AI16: 0.0756 | AJ16: 0.069 | AK16: =(AF16*AG16) -> 244.7704 | AL16: =(AF16*AH16) -> 237.7508 | AM16: =(AF16*AI16) -> 230.7312 | AN16: =(AF16*AJ16) -> 210.588 | AP16: 2928 | AQ16: 0.0772 | AR16: 0.075 | AS16: 0.0728 | AT16: 0.0664 | AU16: =(AP16*AQ16) -> 226.0416 | AV16: =(AP16*AR16) -> 219.6 | AW16: =(AP16*AS16) -> 213.1584 | AX16: =(AP16*AT16) -> 194.4192 | AZ16: 2712 | BA16: 0.0713 | BB16: 0.0692 | BC16: 0.0672 | BD16: 0.0613 | BE16: =(AZ16*BA16) -> 193.3656 | BF16: =(AZ16*BB16) -> 187.6704 | BG16: =(AZ16*BC16) -> 182.2464 | BH16: =(AZ16*BD16) -> 166.2456
A17: 34 PUSS
B18: Mk. | C18: 20 Dny | D18: 30 Dny | E18: 40 Dny | F18: 70 Dny | G18: 32 Fayn | L18: Mk. | M18: 20 Dny | N18: 30 Dny | O18: 40 Dny | P18: 70 Dny | Q18: 30 Fayn | V18: Mk. | W18: 20 Dny | X18: 30 Dny | Y18: 40 Dny | Z18: 70 Dny | AA18: 28 Fayn | AF18: Mk. | AG18: 20 Dny | AH18: 30 Dny | AI18: 40 Dny | AJ18: 70 Dny | AK18: 27 Fayn | AP18: Mk. | AQ18: 20 Dny | AR18: 30 Dny | AS18: 40 Dny | AT18: 70 Dny | AU18: 26 Fayn | AZ18: Mk. | BA18: 20 Dny | BB18: 30 Dny | BC18: 40 Dny | BD18: 70 Dny | BE18: 24 Fayn
A19: KUMAŞ CİNSİ | B19: İğne | C19: May | D19: May | E19: May | F19: May | G19: 20 | H19: 30 | I19: 40 | J19: 70 | L19: İğne | M19: May | N19: May | O19: May | P19: May | Q19: 20 | R19: 30 | S19: 40 | T19: 70 | V19: İğne | W19: May | X19: May | Y19: May | Z19: May | AA19: 20 | AB19: 30 | AC19: 40 | AD19: 70 | AF19: İğne | AG19: May | AH19: May | AI19: May | AJ19: May | AK19: 20 | AL19: 30 | AM19: 40 | AN19: 70 | AP19: İğne | AQ19: May | AR19: May | AS19: May | AT19: May | AU19: 20 | AV19: 30 | AW19: 40 | AX19: 70 | AZ19: İğne | BA19: May | BB19: May | BC19: May | BD19: May | BE19: 20 | BF19: 30 | BG19: 40 | BH19: 70
B20: Sayısı | C20: Genişliği | D20: Genişliği | E20: Genişliği | F20: Genişliği | G20: Dny | H20: Dny | I20: Dny | J20: Dny | L20: Sayısı | M20: Genişliği | N20: Genişliği | O20: Genişliği | P20: Genişliği | Q20: Dny | R20: Dny | S20: Dny | T20: Dny | V20: Sayısı | W20: Genişliği | X20: Genişliği | Y20: Genişliği | Z20: Genişliği | AA20: Dny | AB20: Dny | AC20: Dny | AD20: Dny | AF20: Sayısı | AG20: Genişliği | AH20: Genişliği | AI20: Genişliği | AJ20: Genişliği | AK20: Dny | AL20: Dny | AM20: Dny | AN20: Dny | AP20: Sayısı | AQ20: Genişliği | AR20: Genişliği | AS20: Genişliği | AT20: Genişliği | AU20: Dny | AV20: Dny | AW20: Dny | AX20: Dny | AZ20: Sayısı | BA20: Genişliği | BB20: Genişliği | BC20: Genişliği | BD20: Genişliği | BE20: Dny | BF20: Dny | BG20: Dny | BH20: Dny
A21: 80/1 FULL LYCRALI SÜPREM | B21: 3408 | C21: 0.0359 | D21: 0.035 | E21: 0.0338 | F21: 0.029 | G21: =(B21*C21) -> 122.3472 | H21: =(B21*D21) -> 119.28 | I21: =(B21*E21) -> 115.1904 | J21: =(B21*F21) -> 98.832 | L21: 3192 | M21: 0.0336 | N21: 0.0328 | O21: 0.0317 | P21: 0.0272 | Q21: =(L21*M21) -> 107.2512 | R21: =(L21*N21) -> 104.6976 | S21: =(L21*O21) -> 101.1864 | T21: =(L21*P21) -> 86.8224 | V21: 2976 | W21: 0.0314 | X21: 0.0306 | Y21: 0.0296 | Z21: 0.0254 | AA21: =(V21*W21) -> 93.4464 | AB21: =(V21*X21) -> 91.0656 | AC21: =(V21*Y21) -> 88.0896 | AD21: =(V21*Z21) -> 75.5904 | AF21: 2880 | AK21: =(AF21*AG21) -> 0 | AL21: =(AF21*AH21) -> 0 | AM21: =(AF21*AI21) -> 0 | AN21: =(AF21*AJ21) -> 0 | AP21: 2760 | AU21: =(AP21*AQ21) -> 0 | AV21: =(AP21*AR21) -> 0 | AW21: =(AP21*AS21) -> 0 | AX21: =(AP21*AT21) -> 0 | AZ21: 2544 | BE21: =(AZ21*BA21) -> 0 | BF21: =(AZ21*BB21) -> 0 | BG21: =(AZ21*BC21) -> 0 | BH21: =(AZ21*BD21) -> 0
A22: 60/1 FULL LYCRALI SÜPREM | B22: 3408 | C22: 0.0478 | D22: 0.0466 | E22: 0.045 | F22: 0.0387 | G22: =(B22*C22) -> 162.9024 | H22: =(B22*D22) -> 158.8128 | I22: =(B22*E22) -> 153.36 | J22: =(B22*F22) -> 131.8896 | L22: 3192 | M22: 0.0448 | N22: 0.0437 | O22: 0.0422 | P22: 0.0363 | Q22: =(L22*M22) -> 143.0016 | R22: =(L22*N22) -> 139.4904 | S22: =(L22*O22) -> 134.7024 | T22: =(L22*P22) -> 115.8696 | V22: 2976 | W22: 0.0418 | X22: 0.0407 | Y22: 0.0394 | Z22: 0.0339 | AA22: =(V22*W22) -> 124.3968 | AB22: =(V22*X22) -> 121.1232 | AC22: =(V22*Y22) -> 117.2544 | AD22: =(V22*Z22) -> 100.8864 | AF22: 2880 | AK22: =(AF22*AG22) -> 0 | AL22: =(AF22*AH22) -> 0 | AM22: =(AF22*AI22) -> 0 | AN22: =(AF22*AJ22) -> 0 | AP22: 2760 | AU22: =(AP22*AQ22) -> 0 | AV22: =(AP22*AR22) -> 0 | AW22: =(AP22*AS22) -> 0 | AX22: =(AP22*AT22) -> 0 | AZ22: 2544 | BE22: =(AZ22*BA22) -> 0 | BF22: =(AZ22*BB22) -> 0 | BG22: =(AZ22*BC22) -> 0 | BH22: =(AZ22*BD22) -> 0
A23: 50/1 FULL LYCRALI SÜPREM | B23: 3408 | C23: 0.0574 | D23: 0.0559 | E23: 0.054 | F23: 0.0465 | G23: =(B23*C23) -> 195.6192 | H23: =(B23*D23) -> 190.5072 | I23: =(B23*E23) -> 184.032 | J23: =(B23*F23) -> 158.472 | L23: 3192 | M23: 0.0538 | N23: 0.0524 | O23: 0.0507 | P23: 0.0443 | Q23: =(L23*M23) -> 171.7296 | R23: =(L23*N23) -> 167.2608 | S23: =(L23*O23) -> 161.8344 | T23: =(L23*P23) -> 141.4056 | V23: 2976 | W23: 0.0502 | X23: 0.0489 | Y23: 0.0473 | Z23: 0.0414 | AA23: =(V23*W23) -> 149.3952 | AB23: =(V23*X23) -> 145.5264 | AC23: =(V23*Y23) -> 140.7648 | AD23: =(V23*Z23) -> 123.2064 | AF23: 2880 | AG23: 0.0484 | AH23: 0.0471 | AI23: 0.0456 | AJ23: 0.0399 | AK23: =(AF23*AG23) -> 139.392 | AL23: =(AF23*AH23) -> 135.648 | AM23: =(AF23*AI23) -> 131.328 | AN23: =(AF23*AJ23) -> 114.912 | AP23: 2760 | AU23: =(AP23*AQ23) -> 0 | AV23: =(AP23*AR23) -> 0 | AW23: =(AP23*AS23) -> 0 | AX23: =(AP23*AT23) -> 0 | AZ23: 2544 | BE23: =(AZ23*BA23) -> 0 | BF23: =(AZ23*BB23) -> 0 | BG23: =(AZ23*BC23) -> 0 | BH23: =(AZ23*BD23) -> 0
A24: 40/1 FULL LYCRALI SÜPREM | B24: 3408 | G24: =(B24*C24) -> 0 | H24: =(B24*D24) -> 0 | I24: =(B24*E24) -> 0 | J24: =(B24*F24) -> 0 | L24: 3192 | M24: 0.0672 | N24: 0.0655 | O24: 0.0633 | P24: 0.0554 | Q24: =(L24*M24) -> 214.5024 | R24: =(L24*N24) -> 209.076 | S24: =(L24*O24) -> 202.0536 | T24: =(L24*P24) -> 176.8368 | V24: 2976 | W24: 0.0627 | X24: 0.0611 | Y24: 0.0591 | Z24: 0.0517 | AA24: =(V24*W24) -> 186.5952 | AB24: =(V24*X24) -> 181.8336 | AC24: =(V24*Y24) -> 175.8816 | AD24: =(V24*Z24) -> 153.8592 | AF24: 2880 | AG24: 0.0605 | AH24: 0.0588 | AI24: 0.057 | AJ24: 0.0499 | AK24: =(AF24*AG24) -> 174.24 | AL24: =(AF24*AH24) -> 169.344 | AM24: =(AF24*AI24) -> 164.16 | AN24: =(AF24*AJ24) -> 143.712 | AP24: 2760 | AQ24: 0.0583 | AR24: 0.0566 | AS24: 0.0549 | AT24: 0.0481 | AU24: =(AP24*AQ24) -> 160.908 | AV24: =(AP24*AR24) -> 156.216 | AW24: =(AP24*AS24) -> 151.524 | AX24: =(AP24*AT24) -> 132.756 | AZ24: 2544 | BA24: 0.0538 | BB24: 0.0522 | BC24: 0.0507 | BD24: 0.0444 | BE24: =(AZ24*BA24) -> 136.8672 | BF24: =(AZ24*BB24) -> 132.7968 | BG24: =(AZ24*BC24) -> 128.9808 | BH24: =(AZ24*BD24) -> 112.9536
A25: 36/1 FULL LYCRALI SÜPREM | B25: 3408 | G25: =(B25*C25) -> 0 | H25: =(B25*D25) -> 0 | I25: =(B25*E25) -> 0 | J25: =(B25*F25) -> 0 | L25: 3192 | Q25: =(L25*M25) -> 0 | R25: =(L25*N25) -> 0 | S25: =(L25*O25) -> 0 | T25: =(L25*P25) -> 0 | V25: 2976 | W25: 0.0642 | X25: 0.0624 | Y25: 0.0606 | Z25: 0.0539 | AA25: =(V25*W25) -> 191.0592 | AB25: =(V25*X25) -> 185.7024 | AC25: =(V25*Y25) -> 180.3456 | AD25: =(V25*Z25) -> 160.4064 | AF25: 2880 | AG25: 0.0619 | AH25: 0.0602 | AI25: 0.0584 | AJ25: 0.052 | AK25: =(AF25*AG25) -> 178.272 | AL25: =(AF25*AH25) -> 173.376 | AM25: =(AF25*AI25) -> 168.192 | AN25: =(AF25*AJ25) -> 149.76 | AP25: 2760 | AQ25: 0.0596 | AR25: 0.058 | AS25: 0.0562 | AT25: 0.0501 | AU25: =(AP25*AQ25) -> 164.496 | AV25: =(AP25*AR25) -> 160.08 | AW25: =(AP25*AS25) -> 155.112 | AX25: =(AP25*AT25) -> 138.276 | AZ25: 2544 | BA25: 0.055 | BB25: 0.0535 | BC25: 0.0519 | BD25: 0.0462 | BE25: =(AZ25*BA25) -> 139.92 | BF25: =(AZ25*BB25) -> 136.104 | BG25: =(AZ25*BC25) -> 132.0336 | BH25: =(AZ25*BD25) -> 117.5328
A26: 34/1 FULL LYCRALI SÜPREM | B26: 3408 | G26: =(B26*C26) -> 0 | H26: =(B26*D26) -> 0 | I26: =(B26*E26) -> 0 | J26: =(B26*F26) -> 0 | L26: 3192 | Q26: =(L26*M26) -> 0 | R26: =(L26*N26) -> 0 | S26: =(L26*O26) -> 0 | T26: =(L26*P26) -> 0 | V26: 2976 | W26: 0.065 | X26: 0.0632 | Y26: 0.0613 | Z26: 0.0551 | AA26: =(V26*W26) -> 193.44 | AB26: =(V26*X26) -> 188.0832 | AC26: =(V26*Y26) -> 182.4288 | AD26: =(V26*Z26) -> 163.9776 | AF26: 2880 | AG26: 0.0627 | AH26: 0.0609 | AI26: 0.0591 | AJ26: 0.0531 | AK26: =(AF26*AG26) -> 180.576 | AL26: =(AF26*AH26) -> 175.392 | AM26: =(AF26*AI26) -> 170.208 | AN26: =(AF26*AJ26) -> 152.928 | AP26: 2760 | AQ26: 0.0604 | AR26: 0.0586 | AS26: 0.0569 | AT26: 0.0511 | AU26: =(AP26*AQ26) -> 166.704 | AV26: =(AP26*AR26) -> 161.736 | AW26: =(AP26*AS26) -> 157.044 | AX26: =(AP26*AT26) -> 141.036 | AZ26: 2544 | BA26: 0.0558 | BB26: 0.0541 | BC26: 0.0525 | BD26: 0.0472 | BE26: =(AZ26*BA26) -> 141.9552 | BF26: =(AZ26*BB26) -> 137.6304 | BG26: =(AZ26*BC26) -> 133.56 | BH26: =(AZ26*BD26) -> 120.0768
A27: 32/1 FULL LYCRALI SÜPREM | B27: 3408 | G27: =(B27*C27) -> 0 | H27: =(B27*D27) -> 0 | I27: =(B27*E27) -> 0 | J27: =(B27*F27) -> 0 | L27: 3192 | Q27: =(L27*M27) -> 0 | R27: =(L27*N27) -> 0 | S27: =(L27*O27) -> 0 | T27: =(L27*P27) -> 0 | V27: 2976 | W27: 0.0657 | X27: 0.0639 | Y27: 0.0624 | Z27: 0.0568 | AA27: =(V27*W27) -> 195.5232 | AB27: =(V27*X27) -> 190.1664 | AC27: =(V27*Y27) -> 185.7024 | AD27: =(V27*Z27) -> 169.0368 | AF27: 2880 | AG27: 0.0634 | AH27: 0.0616 | AI27: 0.0602 | AJ27: 0.0548 | AK27: =(AF27*AG27) -> 182.592 | AL27: =(AF27*AH27) -> 177.408 | AM27: =(AF27*AI27) -> 173.376 | AN27: =(AF27*AJ27) -> 157.824 | AP27: 2760 | AQ27: 0.0611 | AR27: 0.0593 | AS27: 0.058 | AT27: 0.0528 | AU27: =(AP27*AQ27) -> 168.636 | AV27: =(AP27*AR27) -> 163.668 | AW27: =(AP27*AS27) -> 160.08 | AX27: =(AP27*AT27) -> 145.728 | AZ27: 2544 | BA27: 0.0564 | BB27: 0.0547 | BC27: 0.0535 | BD27: 0.0487 | BE27: =(AZ27*BA27) -> 143.4816 | BF27: =(AZ27*BB27) -> 139.1568 | BG27: =(AZ27*BC27) -> 136.104 | BH27: =(AZ27*BD27) -> 123.8928
A28: 30/1 FULL LYCRALI SÜPREM | B28: 3408 | G28: =(B28*C28) -> 0 | H28: =(B28*D28) -> 0 | I28: =(B28*E28) -> 0 | J28: =(B28*F28) -> 0 | L28: 3192 | Q28: =(L28*M28) -> 0 | R28: =(L28*N28) -> 0 | S28: =(L28*O28) -> 0 | T28: =(L28*P28) -> 0 | V28: 2976 | W28: 0.0665 | X28: 0.0646 | Y28: 0.0627 | Z28: 0.0572 | AA28: =(V28*W28) -> 197.904 | AB28: =(V28*X28) -> 192.2496 | AC28: =(V28*Y28) -> 186.5952 | AD28: =(V28*Z28) -> 170.2272 | AF28: 2880 | AG28: 0.0641 | AH28: 0.0623 | AI28: 0.0605 | AJ28: 0.0552 | AK28: =(AF28*AG28) -> 184.608 | AL28: =(AF28*AH28) -> 179.424 | AM28: =(AF28*AI28) -> 174.24 | AN28: =(AF28*AJ28) -> 158.976 | AP28: 2760 | AQ28: 0.0617 | AR28: 0.06 | AS28: 0.0583 | AT28: 0.0532 | AU28: =(AP28*AQ28) -> 170.292 | AV28: =(AP28*AR28) -> 165.6 | AW28: =(AP28*AS28) -> 160.908 | AX28: =(AP28*AT28) -> 146.832 | AZ28: 2544 | BA28: 0.057 | BB28: 0.0554 | BC28: 0.0538 | BD28: 0.0491 | BE28: =(AZ28*BA28) -> 145.008 | BF28: =(AZ28*BB28) -> 140.9376 | BG28: =(AZ28*BC28) -> 136.8672 | BH28: =(AZ28*BD28) -> 124.9104
A29: 28/1 FULL LYCRALI SÜPREM | B29: 3408 | G29: =(B29*C29) -> 0 | H29: =(B29*D29) -> 0 | I29: =(B29*E29) -> 0 | J29: =(B29*F29) -> 0 | L29: 3192 | Q29: =(L29*M29) -> 0 | R29: =(L29*N29) -> 0 | S29: =(L29*O29) -> 0 | T29: =(L29*P29) -> 0 | V29: 2976 | W29: 0.0713 | X29: 0.0693 | Y29: 0.0672 | Z29: 0.0613 | AA29: =(V29*W29) -> 212.1888 | AB29: =(V29*X29) -> 206.2368 | AC29: =(V29*Y29) -> 199.9872 | AD29: =(V29*Z29) -> 182.4288 | AF29: 2880 | AG29: 0.0688 | AH29: 0.0668 | AI29: 0.0648 | AJ29: 0.0591 | AK29: =(AF29*AG29) -> 198.144 | AL29: =(AF29*AH29) -> 192.384 | AM29: =(AF29*AI29) -> 186.624 | AN29: =(AF29*AJ29) -> 170.208 | AP29: 2760 | AQ29: 0.0663 | AR29: 0.0643 | AS29: 0.0624 | AT29: 0.0569 | AU29: =(AP29*AQ29) -> 182.988 | AV29: =(AP29*AR29) -> 177.468 | AW29: =(AP29*AS29) -> 172.224 | AX29: =(AP29*AT29) -> 157.044 | AZ29: 2522 | BA29: 0.0612 | BB29: 0.0594 | BC29: 0.0576 | BD29: 0.0525 | BE29: =(AZ29*BA29) -> 154.3464 | BF29: =(AZ29*BB29) -> 149.8068 | BG29: =(AZ29*BC29) -> 145.2672 | BH29: =(AZ29*BD29) -> 132.405
A30: 26/1 FULL LYCRALI SÜPREM | B30: 3408 | G30: =(B30*C30) -> 0 | H30: =(B30*D30) -> 0 | I30: =(B30*E30) -> 0 | J30: =(B30*F30) -> 0 | L30: 3192 | Q30: =(L30*M30) -> 0 | R30: =(L30*N30) -> 0 | S30: =(L30*O30) -> 0 | T30: =(L30*P30) -> 0 | V30: 2976 | W30: 0.0767 | X30: 0.0746 | Y30: 0.0724 | Z30: 0.0661 | AA30: =(V30*W30) -> 228.2592 | AB30: =(V30*X30) -> 222.0096 | AC30: =(V30*Y30) -> 215.4624 | AD30: =(V30*Z30) -> 196.7136 | AF30: 2880 | AG30: 0.074 | AH30: 0.0719 | AI30: 0.0698 | AJ30: 0.0637 | AK30: =(AF30*AG30) -> 213.12 | AL30: =(AF30*AH30) -> 207.072 | AM30: =(AF30*AI30) -> 201.024 | AN30: =(AF30*AJ30) -> 183.456 | AP30: 2760 | AQ30: 0.0713 | AR30: 0.0692 | AS30: 0.0672 | AT30: 0.0613 | AU30: =(AP30*AQ30) -> 196.788 | AV30: =(AP30*AR30) -> 190.992 | AW30: =(AP30*AS30) -> 185.472 | AX30: =(AP30*AT30) -> 169.188 | AZ30: 2544 | BA30: 0.0658 | BB30: 0.0639 | BC30: 0.062 | BD30: 0.0566 | BE30: =(AZ30*BA30) -> 167.3952 | BF30: =(AZ30*BB30) -> 162.5616 | BG30: =(AZ30*BC30) -> 157.728 | BH30: =(AZ30*BD30) -> 143.9904
A31: 24/1 FULL LYCRALI SÜPREM | B31: 3408 | G31: =(B31*C31) -> 0 | H31: =(B31*D31) -> 0 | I31: =(B31*E31) -> 0 | J31: =(B31*F31) -> 0 | L31: 3192 | Q31: =(L31*M31) -> 0 | R31: =(L31*N31) -> 0 | S31: =(L31*O31) -> 0 | T31: =(L31*P31) -> 0 | V31: 2976 | W31: 0.0832 | X31: 0.0808 | Y31: 0.0784 | Z31: 0.0716 | AA31: =(V31*W31) -> 247.6032 | AB31: =(V31*X31) -> 240.4608 | AC31: =(V31*Y31) -> 233.3184 | AD31: =(V31*Z31) -> 213.0816 | AF31: 2880 | AG31: 0.0802 | AH31: 0.0779 | AI31: 0.0756 | AJ31: 0.069 | AK31: =(AF31*AG31) -> 230.976 | AL31: =(AF31*AH31) -> 224.352 | AM31: =(AF31*AI31) -> 217.728 | AN31: =(AF31*AJ31) -> 198.72 | AP31: 2760 | AQ31: 0.0772 | AR31: 0.075 | AS31: 0.0728 | AT31: 0.0664 | AU31: =(AP31*AQ31) -> 213.072 | AV31: =(AP31*AR31) -> 207 | AW31: =(AP31*AS31) -> 200.928 | AX31: =(AP31*AT31) -> 183.264 | AZ31: 2544 | BA31: 0.0713 | BB31: 0.0692 | BC31: 0.0672 | BD31: 0.0613 | BE31: =(AZ31*BA31) -> 181.3872 | BF31: =(AZ31*BB31) -> 176.0448 | BG31: =(AZ31*BC31) -> 170.9568 | BH31: =(AZ31*BD31) -> 155.9472
A32: 32 PUSS
B33: Mk. | C33: 20 Dny | D33: 30 Dny | E33: 40 Dny | F33: 70 Dny | G33: 32 Fayn | L33: Mk. | M33: 20 Dny | N33: 30 Dny | O33: 40 Dny | P33: 70 Dny | Q33: 30 Fayn | V33: Mk. | W33: 20 Dny | X33: 30 Dny | Y33: 40 Dny | Z33: 70 Dny | AA33: 28 Fayn | AF33: Mk. | AG33: 20 Dny | AH33: 30 Dny | AI33: 40 Dny | AJ33: 70 Dny | AK33: 27 Fayn | AP33: Mk. | AQ33: 20 Dny | AR33: 30 Dny | AS33: 40 Dny | AT33: 70 Dny | AU33: 26 Fayn | AZ33: Mk. | BA33: 20 Dny | BB33: 30 Dny | BC33: 40 Dny | BD33: 70 Dny | BE33: 24 Fayn
A34: KUMAŞ CİNSİ | B34: İğne | C34: May | D34: May | E34: May | F34: May | G34: 20 | H34: 30 | I34: 40 | J34: 70 | L34: İğne | M34: May | N34: May | O34: May | P34: May | Q34: 20 | R34: 30 | S34: 40 | T34: 70 | V34: İğne | W34: May | X34: May | Y34: May | Z34: May | AA34: 20 | AB34: 30 | AC34: 40 | AD34: 70 | AF34: İğne | AG34: May | AH34: May | AI34: May | AJ34: May | AK34: 20 | AL34: 30 | AM34: 40 | AN34: 70 | AP34: İğne | AQ34: May | AR34: May | AS34: May | AT34: May | AU34: 20 | AV34: 30 | AW34: 40 | AX34: 70 | AZ34: İğne | BA34: May | BB34: May | BC34: May | BD34: May | BE34: 20 | BF34: 30 | BG34: 40 | BH34: 70
B35: Sayısı | C35: Genişliği | D35: Genişliği | E35: Genişliği | F35: Genişliği | G35: Dny | H35: Dny | I35: Dny | J35: Dny | L35: Sayısı | M35: Genişliği | N35: Genişliği | O35: Genişliği | P35: Genişliği | Q35: Dny | R35: Dny | S35: Dny | T35: Dny | V35: Sayısı | W35: Genişliği | X35: Genişliği | Y35: Genişliği | Z35: Genişliği | AA35: Dny | AB35: Dny | AC35: Dny | AD35: Dny | AF35: Sayısı | AG35: Genişliği | AH35: Genişliği | AI35: Genişliği | AJ35: Genişliği | AK35: Dny | AL35: Dny | AM35: Dny | AN35: Dny | AP35: Sayısı | AQ35: Genişliği | AR35: Genişliği | AS35: Genişliği | AT35: Genişliği | AU35: Dny | AV35: Dny | AW35: Dny | AX35: Dny | AZ35: Sayısı | BA35: Genişliği | BB35: Genişliği | BC35: Genişliği | BD35: Genişliği | BE35: Dny | BF35: Dny | BG35: Dny | BH35: Dny
A36: 80/1 FULL LYCRALI SÜPREM | B36: 3216 | C36: 0.0359 | D36: 0.035 | E36: 0.0338 | F36: 0.029 | G36: =(B36*C36) -> 115.4544 | H36: =(B36*D36) -> 112.56 | I36: =(B36*E36) -> 108.7008 | J36: =(B36*F36) -> 93.264 | L36: 3000 | M36: 0.0336 | N36: 0.0328 | O36: 0.0317 | P36: 0.0272 | Q36: =(L36*M36) -> 100.8 | R36: =(L36*N36) -> 98.4 | S36: =(L36*O36) -> 95.1 | T36: =(L36*P36) -> 81.6 | V36: 2808 | W36: 0.0314 | X36: 0.0306 | Y36: 0.0296 | Z36: 0.0254 | AA36: =(V36*W36) -> 88.1712 | AB36: =(V36*X36) -> 85.9248 | AC36: =(V36*Y36) -> 83.1168 | AD36: =(V36*Z36) -> 71.3232 | AF36: 2760 | AK36: =(AF36*AG36) -> 0 | AL36: =(AF36*AH36) -> 0 | AM36: =(AF36*AI36) -> 0 | AN36: =(AF36*AJ36) -> 0 | AP36: 2616 | AU36: =(AP36*AQ36) -> 0 | AV36: =(AP36*AR36) -> 0 | AW36: =(AP36*AS36) -> 0 | AX36: =(AP36*AT36) -> 0 | AZ36: 2400 | BE36: =(AZ36*BA36) -> 0 | BF36: =(AZ36*BB36) -> 0 | BG36: =(AZ36*BC36) -> 0 | BH36: =(AZ36*BD36) -> 0
A37: 60/1 FULL LYCRALI SÜPREM | B37: 3216 | C37: 0.0478 | D37: 0.0466 | E37: 0.045 | F37: 0.0387 | G37: =(B37*C37) -> 153.7248 | H37: =(B37*D37) -> 149.8656 | I37: =(B37*E37) -> 144.72 | J37: =(B37*F37) -> 124.4592 | L37: 3000 | M37: 0.0448 | N37: 0.0437 | O37: 0.0422 | P37: 0.0363 | Q37: =(L37*M37) -> 134.4 | R37: =(L37*N37) -> 131.1 | S37: =(L37*O37) -> 126.6 | T37: =(L37*P37) -> 108.9 | V37: 2808 | W37: 0.0418 | X37: 0.0407 | Y37: 0.0394 | Z37: 0.0339 | AA37: =(V37*W37) -> 117.3744 | AB37: =(V37*X37) -> 114.2856 | AC37: =(V37*Y37) -> 110.6352 | AD37: =(V37*Z37) -> 95.1912 | AF37: 2760 | AK37: =(AF37*AG37) -> 0 | AL37: =(AF37*AH37) -> 0 | AM37: =(AF37*AI37) -> 0 | AN37: =(AF37*AJ37) -> 0 | AP37: 2616 | AU37: =(AP37*AQ37) -> 0 | AV37: =(AP37*AR37) -> 0 | AW37: =(AP37*AS37) -> 0 | AX37: =(AP37*AT37) -> 0 | AZ37: 2400 | BE37: =(AZ37*BA37) -> 0 | BF37: =(AZ37*BB37) -> 0 | BG37: =(AZ37*BC37) -> 0 | BH37: =(AZ37*BD37) -> 0
A38: 50/1 FULL LYCRALI SÜPREM | B38: 3216 | C38: 0.0574 | D38: 0.0559 | E38: 0.054 | F38: 0.0465 | G38: =(B38*C38) -> 184.5984 | H38: =(B38*D38) -> 179.7744 | I38: =(B38*E38) -> 173.664 | J38: =(B38*F38) -> 149.544 | L38: 3000 | M38: 0.0538 | N38: 0.0524 | O38: 0.0507 | P38: 0.0443 | Q38: =(L38*M38) -> 161.4 | R38: =(L38*N38) -> 157.2 | S38: =(L38*O38) -> 152.1 | T38: =(L38*P38) -> 132.9 | V38: 2808 | W38: 0.0502 | X38: 0.0489 | Y38: 0.0473 | Z38: 0.0414 | AA38: =(V38*W38) -> 140.9616 | AB38: =(V38*X38) -> 137.3112 | AC38: =(V38*Y38) -> 132.8184 | AD38: =(V38*Z38) -> 116.2512 | AF38: 2760 | AG38: 0.0484 | AH38: 0.0471 | AI38: 0.0456 | AJ38: 0.0399 | AK38: =(AF38*AG38) -> 133.584 | AL38: =(AF38*AH38) -> 129.996 | AM38: =(AF38*AI38) -> 125.856 | AN38: =(AF38*AJ38) -> 110.124 | AP38: 2616 | AU38: =(AP38*AQ38) -> 0 | AV38: =(AP38*AR38) -> 0 | AW38: =(AP38*AS38) -> 0 | AX38: =(AP38*AT38) -> 0 | AZ38: 2400 | BE38: =(AZ38*BA38) -> 0 | BF38: =(AZ38*BB38) -> 0 | BG38: =(AZ38*BC38) -> 0 | BH38: =(AZ38*BD38) -> 0
A39: 40/1 FULL LYCRALI SÜPREM | B39: 3216 | G39: =(B39*C39) -> 0 | H39: =(B39*D39) -> 0 | I39: =(B39*E39) -> 0 | J39: =(B39*F39) -> 0 | L39: 3000 | M39: 0.0672 | N39: 0.0655 | O39: 0.0633 | P39: 0.0554 | Q39: =(L39*M39) -> 201.6 | R39: =(L39*N39) -> 196.5 | S39: =(L39*O39) -> 189.9 | T39: =(L39*P39) -> 166.2 | V39: 2808 | W39: 0.0627 | X39: 0.0611 | Y39: 0.0591 | Z39: 0.0517 | AA39: =(V39*W39) -> 176.0616 | AB39: =(V39*X39) -> 171.5688 | AC39: =(V39*Y39) -> 165.9528 | AD39: =(V39*Z39) -> 145.1736 | AF39: 2760 | AG39: 0.0605 | AH39: 0.0588 | AI39: 0.057 | AJ39: 0.0499 | AK39: =(AF39*AG39) -> 166.98 | AL39: =(AF39*AH39) -> 162.288 | AM39: =(AF39*AI39) -> 157.32 | AN39: =(AF39*AJ39) -> 137.724 | AP39: 2616 | AQ39: 0.0583 | AR39: 0.0566 | AS39: 0.0549 | AT39: 0.0481 | AU39: =(AP39*AQ39) -> 152.5128 | AV39: =(AP39*AR39) -> 148.0656 | AW39: =(AP39*AS39) -> 143.6184 | AX39: =(AP39*AT39) -> 125.8296 | AZ39: 2400 | BA39: 0.0538 | BB39: 0.0522 | BC39: 0.0507 | BD39: 0.0444 | BE39: =(AZ39*BA39) -> 129.12 | BF39: =(AZ39*BB39) -> 125.28 | BG39: =(AZ39*BC39) -> 121.68 | BH39: =(AZ39*BD39) -> 106.56
A40: 36/1 FULL LYCRALI SÜPREM | B40: 3216 | G40: =(B40*C40) -> 0 | H40: =(B40*D40) -> 0 | I40: =(B40*E40) -> 0 | J40: =(B40*F40) -> 0 | L40: 3000 | Q40: =(L40*M40) -> 0 | R40: =(L40*N40) -> 0 | S40: =(L40*O40) -> 0 | T40: =(L40*P40) -> 0 | V40: 2808 | W40: 0.0642 | X40: 0.0624 | Y40: 0.0606 | Z40: 0.0539 | AA40: =(V40*W40) -> 180.2736 | AB40: =(V40*X40) -> 175.2192 | AC40: =(V40*Y40) -> 170.1648 | AD40: =(V40*Z40) -> 151.3512 | AF40: 2760 | AG40: 0.0619 | AH40: 0.0602 | AI40: 0.0584 | AJ40: 0.052 | AK40: =(AF40*AG40) -> 170.844 | AL40: =(AF40*AH40) -> 166.152 | AM40: =(AF40*AI40) -> 161.184 | AN40: =(AF40*AJ40) -> 143.52 | AP40: 2616 | AQ40: 0.0596 | AR40: 0.058 | AS40: 0.0562 | AT40: 0.0501 | AU40: =(AP40*AQ40) -> 155.9136 | AV40: =(AP40*AR40) -> 151.728 | AW40: =(AP40*AS40) -> 147.0192 | AX40: =(AP40*AT40) -> 131.0616 | AZ40: 2400 | BA40: 0.055 | BB40: 0.0535 | BC40: 0.0519 | BD40: 0.0462 | BE40: =(AZ40*BA40) -> 132 | BF40: =(AZ40*BB40) -> 128.4 | BG40: =(AZ40*BC40) -> 124.56 | BH40: =(AZ40*BD40) -> 110.88
...

Sheet 28 FAYN %5 LYC SÜPREM GRAMAJLAR
B1: 20 DENYE %5 LYCRALI SÜPREMLERİN GRAMAJLARINA GÖRE 100 MAYDAKİ ORTALAMA İPLİK UZUNLUKLARI
A2: 20 | B2: İPLİK NUMARALARI
A3: DENYELİ | B3: 100 | C3: 80 | D3: 60 | E3: 50 | F3: 40 | G3: 39 | H3: 38 | I3: 37 | J3: 36 | K3: 35 | L3: 34 | M3: 33 | N3: 32 | O3: 31 | P3: 30 | Q3: 29 | R3: 28 | S3: 27 | T3: 26 | U3: 25 | V3: 24 | W3: 23 | X3: 22 | Y3: 21 | Z3: 20 | AA3: 19 | AB3: 18 | AC3: 17 | AD3: 16 | AE3: 15 | AF3: 14 | AG3: 13 | AH3: 12 | AI3: 11 | AJ3: 10
A4: 45 cm | B4: =(C3*C4)/(B3) -> 33.3 | C4: =(D3*D4)/(C3) -> 41.625 | D4: =(E3*E4)/(D3) -> 55.5 | E4: =(F3*F4)/(E3) -> 66.6 | F4: =(G3*G4)/(F3) -> 83.25 | G4: =(H3*H4)/(G3) -> 85.384615 | H4: =(I3*I4)/(H3) -> 87.631579 | I4: =(J3*J4)/(I3) -> 90 | ... O4: =(P3*P4)/(O3) -> 107.41935 | P4: 111 | Q4: =(P3*P4)/(Q3) -> 114.82759 | R4: =(Q3*Q4)/(R3) -> 118.92857 | S4: =(R3*R4)/(S3) -> 123.33333 | T4: =(S3*S4)/(T3) -> 128.07692 | U4: =(T3*T4)/(U3) -> 133.2 | V4: =(U3*U4)/(V3) -> 138.75 | W4: =(V3*V4)/(W3) -> 144.78261 | X4: =(W3*W4)/(X3) -> 151.36364 | ... AJ4: =(AI3*AI4)/(AJ3) -> 333
A5: 44 cm | B5: =(C3*C5)/(B3) -> 34.2 | C5: =(D3*D5)/(C3) -> 42.75 | D5: =(E3*E5)/(D3) -> 57 | E5: =(F3*F5)/(E3) -> 68.4 | F5: =(G3*G5)/(F3) -> 85.5 | G5: =(H3*H5)/(G3) -> 87.692308 | H5: =(I3*I5)/(H3) -> 90 | I5: =(J3*J5)/(I3) -> 92.432432 | ... O5: =(P3*P5)/(O3) -> 110.32258 | P5: 114 | Q5: =(P3*P5)/(Q3) -> 117.93103 | R5: =(Q3*Q5)/(R3) -> 122.14286 | S5: =(R3*R5)/(S3) -> 126.66667 | T5: =(S3*S5)/(T3) -> 131.53846 | U5: =(T3*T5)/(U3) -> 136.8 | V5: =(U3*U5)/(V3) -> 142.5 | W5: =(V3*V5)/(W3) -> 148.69565 | X5: =(W3*W5)/(X3) -> 155.45455 | ... AJ5: =(AI3*AI5)/(AJ3) -> 342
A6: 43 cm | B6: =(C3*C6)/(B3) -> 35.1 | C6: =(D3*D6)/(C3) -> 43.875 | D6: =(E3*E6)/(D3) -> 58.5 | E6: =(F3*F6)/(E3) -> 70.2 | F6: =(G3*G6)/(F3) -> 87.75 | G6: =(H3*H6)/(G3) -> 90 | H6: =(I3*I6)/(H3) -> 92.368421 | I6: =(J3*J6)/(I3) -> 94.864865 | ... O6: =(P3*P6)/(O3) -> 113.22581 | P6: 117 | Q6: =(P3*P6)/(Q3) -> 121.03448 | R6: =(Q3*Q6)/(R3) -> 125.35714 | S6: =(R3*R6)/(S3) -> 130 | T6: =(S3*S6)/(T3) -> 135 | U6: =(T3*T6)/(U3) -> 140.4 | V6: =(U3*U6)/(V3) -> 146.25 | W6: =(V3*V6)/(W3) -> 152.6087 | X6: =(W3*W6)/(X3) -> 159.54545 | ... AJ6: =(AI3*AI6)/(AJ3) -> 351
A7: 42 cm | B7: =(C3*C7)/(B3) -> 0 | C7: =(D3*D7)/(C3) -> 0 | D7: =(E3*E7)/(D3) -> 0 | E7: =(F3*F7)/(E3) -> 0 | F7: =(G3*G7)/(F3) -> 0 | G7: =(H3*H7)/(G3) -> 0 | H7: =(I3*I7)/(H3) -> 0 | I7: =(J3*J7)/(I3) -> 0 | ... O7: =(P3*P7)/(O3) -> 0 | Q7: =(P3*P7)/(Q3) -> 0 | R7: 119 | S7: =(R3*R7)/(S3) -> 123.40741 | T7: =(S3*S7)/(T3) -> 128.15385 | U7: =(T3*T7)/(U3) -> 133.28 | V7: =(U3*U7)/(V3) -> 138.83333 | W7: =(V3*V7)/(W3) -> 144.86957 | X7: =(W3*W7)/(X3) -> 151.45455 | Y7: =(X3*X7)/(Y3) -> 158.66667 | Z7: =(Y3*Y7)/(Z3) -> 166.6 | ... AJ7: =(AI3*AI7)/(AJ3) -> 333.2
A8: 41 cm | B8: =(C3*C8)/(B3) -> 0 | C8: =(D3*D8)/(C3) -> 0 | D8: =(E3*E8)/(D3) -> 0 | E8: =(F3*F8)/(E3) -> 0 | F8: =(G3*G8)/(F3) -> 0 | G8: =(H3*H8)/(G3) -> 0 | H8: =(I3*I8)/(H3) -> 0 | I8: =(J3*J8)/(I3) -> 0 | ... O8: =(P3*P8)/(O3) -> 0 | Q8: 122 | R8: =(Q3*Q8)/(R3) -> 126.35714 | S8: =(R3*R8)/(S3) -> 131.03704 | T8: =(S3*S8)/(T3) -> 136.07692 | U8: =(T3*T8)/(U3) -> 141.52 | V8: =(U3*U8)/(V3) -> 147.41667 | W8: =(V3*V8)/(W3) -> 153.82609 | X8: =(W3*W8)/(X3) -> 160.81818 | Y8: =(X3*X8)/(Y3) -> 168.47619 | ... AJ8: =(AI3*AI8)/(AJ3) -> 353.8
A9: 40 cm | B9: =(C3*C9)/(B3) -> 36.6 | C9: =(D3*D9)/(C3) -> 45.75 | D9: =(E3*E9)/(D3) -> 61 | E9: =(F3*F9)/(E3) -> 73.2 | F9: =(G3*G9)/(F3) -> 91.5 | G9: =(H3*H9)/(G3) -> 93.846154 | H9: =(I3*I9)/(H3) -> 96.315789 | I9: =(J3*J9)/(I3) -> 98.918919 | ... O9: =(P3*P9)/(O3) -> 118.06452 | P9: 122 | Q9: 125 | R9: =(Q3*Q9)/(R3) -> 129.46429 | S9: =(R3*R9)/(S3) -> 134.25926 | T9: =(S3*S9)/(T3) -> 139.42308 | U9: =(T3*T9)/(U3) -> 145 | V9: =(U3*U9)/(V3) -> 151.04167 | W9: =(V3*V9)/(W3) -> 157.6087 | X9: =(W3*W9)/(X3) -> 164.77273 | Y9: =(X3*X9)/(Y3) -> 172.61905 | ... AJ9: =(AI3*AI9)/(AJ3) -> 362.5
A10: 39 cm | B10: =(C3*C10)/(B3) -> 37.5 | C10: =(D3*D10)/(C3) -> 46.875 | D10: =(E3*E10)/(D3) -> 62.5 | E10: =(F3*F10)/(E3) -> 75 | F10: =(G3*G10)/(F3) -> 93.75 | G10: =(H3*H10)/(G3) -> 96.153846 | H10: =(I3*I10)/(H3) -> 98.684211 | I10: =(J3*J10)/(I3) -> 101.35135 | ... O10: =(P3*P10)/(O3) -> 120.96774 | P10: 125 | Q10: =(P3*P10)/(Q3) -> 129.31034 | R10: =(Q3*Q10)/(R3) -> 133.92857 | S10: =(R3*R10)/(S3) -> 138.88889 | T10: =(S3*S10)/(T3) -> 144.23077 | U10: =(T3*T10)/(U3) -> 150 | V10: =(U3*U10)/(V3) -> 156.25 | W10: =(V3*V10)/(W3) -> 163.04348 | X10: =(W3*W10)/(X3) -> 170.45455 | ... AJ10: =(AI3*AI10)/(AJ3) -> 375
A11: 38 cm | B11: =(C3*C11)/(B3) -> 38.4 | C11: =(D3*D11)/(C3) -> 48 | D11: =(E3*E11)/(D3) -> 64 | E11: =(F3*F11)/(E3) -> 76.8 | F11: =(G3*G11)/(F3) -> 96 | G11: =(H3*H11)/(G3) -> 98.461538 | H11: =(I3*I11)/(H3) -> 101.05263 | I11: =(J3*J11)/(I3) -> 103.78378 | ... O11: =(P3*P11)/(O3) -> 123.87097 | P11: 128 | Q11: =(P3*P11)/(Q3) -> 132.41379 | R11: =(Q3*Q11)/(R3) -> 137.14286 | S11: =(R3*R11)/(S3) -> 142.22222 | T11: =(S3*S11)/(T3) -> 147.69231 | U11: =(T3*T11)/(U3) -> 153.6 | V11: =(U3*U11)/(V3) -> 160 | W11: =(V3*V11)/(W3) -> 166.95652 | X11: =(W3*W11)/(X3) -> 174.54545 | ... AJ11: =(AI3*AI11)/(AJ3) -> 384
